nohup: ignoring input
Watching for file changes with StatReloader
Performing system checks...

System check identified some issues:

WARNINGS:
?: (staticfiles.W004) The directory '/home/ramachandra/movies/static' in the STATICFILES_DIRS setting does not exist.

System check identified 1 issue (0 silenced).
May 24, 2024 - 00:37:10
Django version 4.2.13, using settings 'movies.settings'
Starting development server at http://0.0.0.0:3000/
Quit the server with CONTROL-C.

[24/May/2024 00:37:16] "GET /app1/profile HTTP/1.1" 200 2943
[24/May/2024 00:37:16] "GET /static/app1/css/styles.css HTTP/1.1" 404 1820
Not Found: /app1/avatar.jpg
[24/May/2024 00:37:16] "GET /app1/avatar.jpg HTTP/1.1" 404 3909
Not Found: /app1/scripts.js
[24/May/2024 00:37:17] "GET /app1/scripts.js HTTP/1.1" 404 3909
[24/May/2024 00:38:11] "GET /app1/profile HTTP/1.1" 200 2942
[24/May/2024 00:38:11] "GET /static/app1/css/style.css HTTP/1.1" 200 2237
Not Found: /app1/avatar.jpg
[24/May/2024 00:38:11] "GET /app1/avatar.jpg HTTP/1.1" 404 3909
Not Found: /app1/scripts.js
[24/May/2024 00:38:11] "GET /app1/scripts.js HTTP/1.1" 404 3909
[24/May/2024 00:38:20] "GET /app1/profile HTTP/1.1" 200 2942
Not Found: /app1/avatar.jpg
[24/May/2024 00:38:20] "GET /app1/avatar.jpg HTTP/1.1" 404 3909
Not Found: /app1/scripts.js
[24/May/2024 00:38:20] "GET /app1/scripts.js HTTP/1.1" 404 3909
[24/May/2024 00:38:41] "GET /app1/profile HTTP/1.1" 200 2952
Not Found: /app1/avatar.jpg
[24/May/2024 00:38:41] "GET /app1/avatar.jpg HTTP/1.1" 404 3909
Not Found: /app1/static/js/scripts.js
[24/May/2024 00:38:41] "GET /app1/static/js/scripts.js HTTP/1.1" 404 3939
[24/May/2024 00:39:42] "GET /app1/profile HTTP/1.1" 200 2957
Not Found: /app1/avatar.jpg
[24/May/2024 00:39:42] "GET /app1/avatar.jpg HTTP/1.1" 404 3909
[24/May/2024 00:39:42] "GET /static/app1/css/style.css HTTP/1.1" 304 0
[24/May/2024 00:39:42] "GET /static/app1/js/script.js HTTP/1.1" 200 684
[24/May/2024 00:40:14] "GET /app1/profile HTTP/1.1" 200 2956
Not Found: /app1/avatar.jpg
[24/May/2024 00:40:14] "GET /app1/avatar.jpg HTTP/1.1" 404 3909
[24/May/2024 00:40:22] "GET /app1/profile HTTP/1.1" 200 2956
Not Found: /app1/avatar.jpg
[24/May/2024 00:40:22] "GET /app1/avatar.jpg HTTP/1.1" 404 3909
[24/May/2024 00:40:43] "GET /app1/profile HTTP/1.1" 200 2956
[24/May/2024 00:40:43] "GET /static/app1/css/style.css HTTP/1.1" 304 0
Not Found: /app1/avatar.jpg
[24/May/2024 00:40:43] "GET /app1/avatar.jpg HTTP/1.1" 404 3909
[24/May/2024 00:40:53] "GET /app1/profile HTTP/1.1" 200 2956
Not Found: /app1/avatar.jpg
[24/May/2024 00:40:53] "GET /app1/avatar.jpg HTTP/1.1" 404 3909
[24/May/2024 00:44:43] "GET /app1/profile HTTP/1.1" 200 1358
Not Found: /app1/user.jpg
[24/May/2024 00:44:43] "GET /app1/user.jpg HTTP/1.1" 404 3903
[24/May/2024 00:44:43] "GET /static/app1/css/style.css HTTP/1.1" 200 1409
[24/May/2024 00:45:10] "GET /app1/profile HTTP/1.1" 200 1358
Not Found: /app1/user.jpg
[24/May/2024 00:45:10] "GET /app1/user.jpg HTTP/1.1" 404 3903
[24/May/2024 00:45:10] "GET /static/app1/css/style.css HTTP/1.1" 304 0
[24/May/2024 00:45:19] "GET /app1/profile HTTP/1.1" 200 1358
Not Found: /app1/user.jpg
[24/May/2024 00:45:19] "GET /app1/user.jpg HTTP/1.1" 404 3903
[24/May/2024 00:45:19] "GET /static/app1/css/style.css HTTP/1.1" 304 0
[24/May/2024 00:46:21] "GET /app1/profile HTTP/1.1" 200 1358
[24/May/2024 00:46:21] "GET /static/app1/css/style.css HTTP/1.1" 304 0
Not Found: /app1/user.jpg
[24/May/2024 00:46:21] "GET /app1/user.jpg HTTP/1.1" 404 3903
[24/May/2024 00:46:58] "GET /app1/profile HTTP/1.1" 200 1358
[24/May/2024 00:46:59] "GET /static/app1/css/style.css HTTP/1.1" 304 0
Not Found: /app1/user.jpg
[24/May/2024 00:46:59] "GET /app1/user.jpg HTTP/1.1" 404 3903
[24/May/2024 00:47:14] "GET /app1/profile HTTP/1.1" 200 1358
[24/May/2024 00:47:14] "GET /static/app1/css/style.css HTTP/1.1" 304 0
Not Found: /app1/user.jpg
[24/May/2024 00:47:14] "GET /app1/user.jpg HTTP/1.1" 404 3903
/home/ramachandra/movies/movies/settings.py changed, reloading.
Watching for file changes with StatReloader
Performing system checks...

System check identified no issues (0 silenced).
May 24, 2024 - 00:48:11
Django version 4.2.13, using settings 'movies.settings'
Starting development server at http://0.0.0.0:3000/
Quit the server with CONTROL-C.

[24/May/2024 00:49:00] "GET /app1/profile HTTP/1.1" 200 1358
[24/May/2024 00:49:00] "GET /static/app1/css/style.css HTTP/1.1" 304 0
Not Found: /app1/user.jpg
[24/May/2024 00:49:00] "GET /app1/user.jpg HTTP/1.1" 404 3903
[24/May/2024 00:49:02] "GET /app1/profile HTTP/1.1" 200 1358
Not Found: /app1/user.jpg
[24/May/2024 00:49:02] "GET /app1/user.jpg HTTP/1.1" 404 3903
[24/May/2024 00:49:05] "GET /app1/profile HTTP/1.1" 200 1358
Not Found: /app1/user.jpg
[24/May/2024 00:49:05] "GET /app1/user.jpg HTTP/1.1" 404 3903
[24/May/2024 00:49:28] "GET /app1/profile HTTP/1.1" 200 4179
[24/May/2024 00:49:28] "GET /static/app1/css/style.css HTTP/1.1" 304 0
Not Found: /app1/user.jpg
[24/May/2024 00:49:28] "GET /app1/user.jpg HTTP/1.1" 404 3903
[24/May/2024 00:49:41] "GET /app1/profile HTTP/1.1" 200 4147
Not Found: /app1/user.jpg
[24/May/2024 00:49:41] "GET /app1/user.jpg HTTP/1.1" 404 3903
Not Found: /app1/inception.jpg
[24/May/2024 00:49:41] "GET /app1/inception.jpg HTTP/1.1" 404 3918
Not Found: /app1/dark_knight.jpg
[24/May/2024 00:49:41] "GET /app1/dark_knight.jpg HTTP/1.1" 404 3924
Not Found: /app1/interstellar.jpg
[24/May/2024 00:49:41] "GET /app1/interstellar.jpg HTTP/1.1" 404 3927
Not Found: /app1/pulp_fiction.jpg
[24/May/2024 00:49:41] "GET /app1/pulp_fiction.jpg HTTP/1.1" 404 3927
[24/May/2024 00:52:03] "GET /app1/profile HTTP/1.1" 200 8977
Not Found: /app1/avatar.jpg
[24/May/2024 00:52:03] "GET /app1/avatar.jpg HTTP/1.1" 404 3909
Not Found: /app1/movie1.jpg
[24/May/2024 00:52:03] "GET /app1/movie1.jpg HTTP/1.1" 404 3909
Not Found: /app1/movie2.jpg
[24/May/2024 00:52:03] "GET /app1/movie2.jpg HTTP/1.1" 404 3909
[24/May/2024 00:56:34] "GET /app1/profile HTTP/1.1" 200 3074
[24/May/2024 00:56:58] "GET /app1/profile HTTP/1.1" 200 8350
[24/May/2024 00:58:18] "GET /app1/profile HTTP/1.1" 200 4323
[24/May/2024 01:00:10] "GET /app1/profile HTTP/1.1" 200 4617
[24/May/2024 01:01:15] "GET /app1/profile HTTP/1.1" 200 4400
[24/May/2024 01:01:16] "GET /app1/profile HTTP/1.1" 200 4400
[24/May/2024 01:03:20] "GET /app1/profile HTTP/1.1" 200 3768
[24/May/2024 01:04:13] "GET /app1/profile HTTP/1.1" 200 5440
[24/May/2024 01:06:07] "GET /app1/profile HTTP/1.1" 200 5380
[24/May/2024 01:07:17] "GET /app1/profile HTTP/1.1" 200 5351
[24/May/2024 01:07:42] "GET /app1/profile HTTP/1.1" 200 5351
[24/May/2024 01:07:59] "GET /app1/profile HTTP/1.1" 200 5351
[24/May/2024 01:08:55] "GET /app1/profile HTTP/1.1" 200 5325
[24/May/2024 01:10:37] "GET /app1/profile HTTP/1.1" 200 5648
[24/May/2024 01:11:26] "GET /app1/profile HTTP/1.1" 200 4838
/home/ramachandra/movies/app1/models.py changed, reloading.
Watching for file changes with StatReloader
Exception in thread django-main-thread:
Traceback (most recent call last):
  File "/usr/lib/python3.8/threading.py", line 932, in _bootstrap_inner
    self.run()
  File "/usr/lib/python3.8/threading.py", line 870, in run
    self._target(*self._args, **self._kwargs)
  File "/home/ramachandra/.local/lib/python3.8/site-packages/django/utils/autoreload.py", line 64, in wrapper
    fn(*args, **kwargs)
  File "/home/ramachandra/.local/lib/python3.8/site-packages/django/core/management/commands/runserver.py", line 125, in inner_run
    autoreload.raise_last_exception()
  File "/home/ramachandra/.local/lib/python3.8/site-packages/django/utils/autoreload.py", line 87, in raise_last_exception
    raise _exception[1]
  File "/home/ramachandra/.local/lib/python3.8/site-packages/django/core/management/__init__.py", line 394, in execute
    autoreload.check_errors(django.setup)()
  File "/home/ramachandra/.local/lib/python3.8/site-packages/django/utils/autoreload.py", line 64, in wrapper
    fn(*args, **kwargs)
  File "/home/ramachandra/.local/lib/python3.8/site-packages/django/__init__.py", line 24, in setup
    apps.populate(settings.INSTALLED_APPS)
  File "/home/ramachandra/.local/lib/python3.8/site-packages/django/apps/registry.py", line 116, in populate
    app_config.import_models()
  File "/home/ramachandra/.local/lib/python3.8/site-packages/django/apps/config.py", line 269, in import_models
    self.models_module = import_module(models_module_name)
  File "/usr/lib/python3.8/importlib/__init__.py", line 127, in import_module
    return _bootstrap._gcd_import(name[level:], package, level)
  File "<frozen importlib._bootstrap>", line 1014, in _gcd_import
  File "<frozen importlib._bootstrap>", line 991, in _find_and_load
  File "<frozen importlib._bootstrap>", line 975, in _find_and_load_unlocked
  File "<frozen importlib._bootstrap>", line 671, in _load_unlocked
  File "<frozen importlib._bootstrap_external>", line 844, in exec_module
  File "<frozen importlib._bootstrap_external>", line 981, in get_code
  File "<frozen importlib._bootstrap_external>", line 911, in source_to_code
  File "<frozen importlib._bootstrap>", line 219, in _call_with_frames_removed
  File "/home/ramachandra/movies/app1/models.py", line 13
    class 
         ^
SyntaxError: invalid syntax
/home/ramachandra/movies/app1/models.py changed, reloading.
Watching for file changes with StatReloader
Exception in thread django-main-thread:
Traceback (most recent call last):
  File "/usr/lib/python3.8/threading.py", line 932, in _bootstrap_inner
    self.run()
  File "/usr/lib/python3.8/threading.py", line 870, in run
    self._target(*self._args, **self._kwargs)
  File "/home/ramachandra/.local/lib/python3.8/site-packages/django/utils/autoreload.py", line 64, in wrapper
    fn(*args, **kwargs)
  File "/home/ramachandra/.local/lib/python3.8/site-packages/django/core/management/commands/runserver.py", line 125, in inner_run
    autoreload.raise_last_exception()
  File "/home/ramachandra/.local/lib/python3.8/site-packages/django/utils/autoreload.py", line 87, in raise_last_exception
    raise _exception[1]
  File "/home/ramachandra/.local/lib/python3.8/site-packages/django/core/management/__init__.py", line 394, in execute
    autoreload.check_errors(django.setup)()
  File "/home/ramachandra/.local/lib/python3.8/site-packages/django/utils/autoreload.py", line 64, in wrapper
    fn(*args, **kwargs)
  File "/home/ramachandra/.local/lib/python3.8/site-packages/django/__init__.py", line 24, in setup
    apps.populate(settings.INSTALLED_APPS)
  File "/home/ramachandra/.local/lib/python3.8/site-packages/django/apps/registry.py", line 116, in populate
    app_config.import_models()
  File "/home/ramachandra/.local/lib/python3.8/site-packages/django/apps/config.py", line 269, in import_models
    self.models_module = import_module(models_module_name)
  File "/usr/lib/python3.8/importlib/__init__.py", line 127, in import_module
    return _bootstrap._gcd_import(name[level:], package, level)
  File "<frozen importlib._bootstrap>", line 1014, in _gcd_import
  File "<frozen importlib._bootstrap>", line 991, in _find_and_load
  File "<frozen importlib._bootstrap>", line 975, in _find_and_load_unlocked
  File "<frozen importlib._bootstrap>", line 671, in _load_unlocked
  File "<frozen importlib._bootstrap_external>", line 844, in exec_module
  File "<frozen importlib._bootstrap_external>", line 981, in get_code
  File "<frozen importlib._bootstrap_external>", line 911, in source_to_code
  File "<frozen importlib._bootstrap>", line 219, in _call_with_frames_removed
  File "/home/ramachandra/movies/app1/models.py", line 13
    class Favo
             ^
SyntaxError: invalid syntax
/home/ramachandra/movies/app1/models.py changed, reloading.
Watching for file changes with StatReloader
Exception in thread django-main-thread:
Traceback (most recent call last):
  File "/usr/lib/python3.8/threading.py", line 932, in _bootstrap_inner
    self.run()
  File "/usr/lib/python3.8/threading.py", line 870, in run
    self._target(*self._args, **self._kwargs)
  File "/home/ramachandra/.local/lib/python3.8/site-packages/django/utils/autoreload.py", line 64, in wrapper
    fn(*args, **kwargs)
  File "/home/ramachandra/.local/lib/python3.8/site-packages/django/core/management/commands/runserver.py", line 125, in inner_run
    autoreload.raise_last_exception()
  File "/home/ramachandra/.local/lib/python3.8/site-packages/django/utils/autoreload.py", line 87, in raise_last_exception
    raise _exception[1]
  File "/home/ramachandra/.local/lib/python3.8/site-packages/django/core/management/__init__.py", line 394, in execute
    autoreload.check_errors(django.setup)()
  File "/home/ramachandra/.local/lib/python3.8/site-packages/django/utils/autoreload.py", line 64, in wrapper
    fn(*args, **kwargs)
  File "/home/ramachandra/.local/lib/python3.8/site-packages/django/__init__.py", line 24, in setup
    apps.populate(settings.INSTALLED_APPS)
  File "/home/ramachandra/.local/lib/python3.8/site-packages/django/apps/registry.py", line 116, in populate
    app_config.import_models()
  File "/home/ramachandra/.local/lib/python3.8/site-packages/django/apps/config.py", line 269, in import_models
    self.models_module = import_module(models_module_name)
  File "/usr/lib/python3.8/importlib/__init__.py", line 127, in import_module
    return _bootstrap._gcd_import(name[level:], package, level)
  File "<frozen importlib._bootstrap>", line 1014, in _gcd_import
  File "<frozen importlib._bootstrap>", line 991, in _find_and_load
  File "<frozen importlib._bootstrap>", line 975, in _find_and_load_unlocked
  File "<frozen importlib._bootstrap>", line 671, in _load_unlocked
  File "<frozen importlib._bootstrap_external>", line 844, in exec_module
  File "<frozen importlib._bootstrap_external>", line 981, in get_code
  File "<frozen importlib._bootstrap_external>", line 911, in source_to_code
  File "<frozen importlib._bootstrap>", line 219, in _call_with_frames_removed
  File "/home/ramachandra/movies/app1/models.py", line 13
    class Favorite
                 ^
SyntaxError: invalid syntax
/home/ramachandra/movies/app1/models.py changed, reloading.
Watching for file changes with StatReloader
Exception in thread django-main-thread:
Traceback (most recent call last):
  File "/usr/lib/python3.8/threading.py", line 932, in _bootstrap_inner
    self.run()
  File "/usr/lib/python3.8/threading.py", line 870, in run
    self._target(*self._args, **self._kwargs)
  File "/home/ramachandra/.local/lib/python3.8/site-packages/django/utils/autoreload.py", line 64, in wrapper
    fn(*args, **kwargs)
  File "/home/ramachandra/.local/lib/python3.8/site-packages/django/core/management/commands/runserver.py", line 125, in inner_run
    autoreload.raise_last_exception()
  File "/home/ramachandra/.local/lib/python3.8/site-packages/django/utils/autoreload.py", line 87, in raise_last_exception
    raise _exception[1]
  File "/home/ramachandra/.local/lib/python3.8/site-packages/django/core/management/__init__.py", line 394, in execute
    autoreload.check_errors(django.setup)()
  File "/home/ramachandra/.local/lib/python3.8/site-packages/django/utils/autoreload.py", line 64, in wrapper
    fn(*args, **kwargs)
  File "/home/ramachandra/.local/lib/python3.8/site-packages/django/__init__.py", line 24, in setup
    apps.populate(settings.INSTALLED_APPS)
  File "/home/ramachandra/.local/lib/python3.8/site-packages/django/apps/registry.py", line 116, in populate
    app_config.import_models()
  File "/home/ramachandra/.local/lib/python3.8/site-packages/django/apps/config.py", line 269, in import_models
    self.models_module = import_module(models_module_name)
  File "/usr/lib/python3.8/importlib/__init__.py", line 127, in import_module
    return _bootstrap._gcd_import(name[level:], package, level)
  File "<frozen importlib._bootstrap>", line 1014, in _gcd_import
  File "<frozen importlib._bootstrap>", line 991, in _find_and_load
  File "<frozen importlib._bootstrap>", line 975, in _find_and_load_unlocked
  File "<frozen importlib._bootstrap>", line 671, in _load_unlocked
  File "<frozen importlib._bootstrap_external>", line 844, in exec_module
  File "<frozen importlib._bootstrap_external>", line 981, in get_code
  File "<frozen importlib._bootstrap_external>", line 911, in source_to_code
  File "<frozen importlib._bootstrap>", line 219, in _call_with_frames_removed
  File "/home/ramachandra/movies/app1/models.py", line 13
    class Favorites()
                    ^
SyntaxError: invalid syntax
/home/ramachandra/movies/app1/models.py changed, reloading.
Watching for file changes with StatReloader
Exception in thread django-main-thread:
Traceback (most recent call last):
  File "/usr/lib/python3.8/threading.py", line 932, in _bootstrap_inner
    self.run()
  File "/usr/lib/python3.8/threading.py", line 870, in run
    self._target(*self._args, **self._kwargs)
  File "/home/ramachandra/.local/lib/python3.8/site-packages/django/utils/autoreload.py", line 64, in wrapper
    fn(*args, **kwargs)
  File "/home/ramachandra/.local/lib/python3.8/site-packages/django/core/management/commands/runserver.py", line 125, in inner_run
    autoreload.raise_last_exception()
  File "/home/ramachandra/.local/lib/python3.8/site-packages/django/utils/autoreload.py", line 87, in raise_last_exception
    raise _exception[1]
  File "/home/ramachandra/.local/lib/python3.8/site-packages/django/core/management/__init__.py", line 394, in execute
    autoreload.check_errors(django.setup)()
  File "/home/ramachandra/.local/lib/python3.8/site-packages/django/utils/autoreload.py", line 64, in wrapper
    fn(*args, **kwargs)
  File "/home/ramachandra/.local/lib/python3.8/site-packages/django/__init__.py", line 24, in setup
    apps.populate(settings.INSTALLED_APPS)
  File "/home/ramachandra/.local/lib/python3.8/site-packages/django/apps/registry.py", line 116, in populate
    app_config.import_models()
  File "/home/ramachandra/.local/lib/python3.8/site-packages/django/apps/config.py", line 269, in import_models
    self.models_module = import_module(models_module_name)
  File "/usr/lib/python3.8/importlib/__init__.py", line 127, in import_module
    return _bootstrap._gcd_import(name[level:], package, level)
  File "<frozen importlib._bootstrap>", line 1014, in _gcd_import
  File "<frozen importlib._bootstrap>", line 991, in _find_and_load
  File "<frozen importlib._bootstrap>", line 975, in _find_and_load_unlocked
  File "<frozen importlib._bootstrap>", line 671, in _load_unlocked
  File "<frozen importlib._bootstrap_external>", line 844, in exec_module
  File "<frozen importlib._bootstrap_external>", line 981, in get_code
  File "<frozen importlib._bootstrap_external>", line 911, in source_to_code
  File "<frozen importlib._bootstrap>", line 219, in _call_with_frames_removed
  File "/home/ramachandra/movies/app1/models.py", line 13
    class Favorites(models.M)
                            ^
SyntaxError: invalid syntax
/home/ramachandra/movies/app1/models.py changed, reloading.
Watching for file changes with StatReloader
Exception in thread django-main-thread:
Traceback (most recent call last):
  File "/usr/lib/python3.8/threading.py", line 932, in _bootstrap_inner
    self.run()
  File "/usr/lib/python3.8/threading.py", line 870, in run
    self._target(*self._args, **self._kwargs)
  File "/home/ramachandra/.local/lib/python3.8/site-packages/django/utils/autoreload.py", line 64, in wrapper
    fn(*args, **kwargs)
  File "/home/ramachandra/.local/lib/python3.8/site-packages/django/core/management/commands/runserver.py", line 125, in inner_run
    autoreload.raise_last_exception()
  File "/home/ramachandra/.local/lib/python3.8/site-packages/django/utils/autoreload.py", line 87, in raise_last_exception
    raise _exception[1]
  File "/home/ramachandra/.local/lib/python3.8/site-packages/django/core/management/__init__.py", line 394, in execute
    autoreload.check_errors(django.setup)()
  File "/home/ramachandra/.local/lib/python3.8/site-packages/django/utils/autoreload.py", line 64, in wrapper
    fn(*args, **kwargs)
  File "/home/ramachandra/.local/lib/python3.8/site-packages/django/__init__.py", line 24, in setup
    apps.populate(settings.INSTALLED_APPS)
  File "/home/ramachandra/.local/lib/python3.8/site-packages/django/apps/registry.py", line 116, in populate
    app_config.import_models()
  File "/home/ramachandra/.local/lib/python3.8/site-packages/django/apps/config.py", line 269, in import_models
    self.models_module = import_module(models_module_name)
  File "/usr/lib/python3.8/importlib/__init__.py", line 127, in import_module
    return _bootstrap._gcd_import(name[level:], package, level)
  File "<frozen importlib._bootstrap>", line 1014, in _gcd_import
  File "<frozen importlib._bootstrap>", line 991, in _find_and_load
  File "<frozen importlib._bootstrap>", line 975, in _find_and_load_unlocked
  File "<frozen importlib._bootstrap>", line 671, in _load_unlocked
  File "<frozen importlib._bootstrap_external>", line 844, in exec_module
  File "<frozen importlib._bootstrap_external>", line 981, in get_code
  File "<frozen importlib._bootstrap_external>", line 911, in source_to_code
  File "<frozen importlib._bootstrap>", line 219, in _call_with_frames_removed
  File "/home/ramachandra/movies/app1/models.py", line 13
    class Favorites(models.Model)
                                ^
SyntaxError: invalid syntax
/home/ramachandra/movies/app1/models.py changed, reloading.
Watching for file changes with StatReloader
Exception in thread django-main-thread:
Traceback (most recent call last):
  File "/usr/lib/python3.8/threading.py", line 932, in _bootstrap_inner
    self.run()
  File "/usr/lib/python3.8/threading.py", line 870, in run
    self._target(*self._args, **self._kwargs)
  File "/home/ramachandra/.local/lib/python3.8/site-packages/django/utils/autoreload.py", line 64, in wrapper
    fn(*args, **kwargs)
  File "/home/ramachandra/.local/lib/python3.8/site-packages/django/core/management/commands/runserver.py", line 125, in inner_run
    autoreload.raise_last_exception()
  File "/home/ramachandra/.local/lib/python3.8/site-packages/django/utils/autoreload.py", line 87, in raise_last_exception
    raise _exception[1]
  File "/home/ramachandra/.local/lib/python3.8/site-packages/django/core/management/__init__.py", line 394, in execute
    autoreload.check_errors(django.setup)()
  File "/home/ramachandra/.local/lib/python3.8/site-packages/django/utils/autoreload.py", line 64, in wrapper
    fn(*args, **kwargs)
  File "/home/ramachandra/.local/lib/python3.8/site-packages/django/__init__.py", line 24, in setup
    apps.populate(settings.INSTALLED_APPS)
  File "/home/ramachandra/.local/lib/python3.8/site-packages/django/apps/registry.py", line 116, in populate
    app_config.import_models()
  File "/home/ramachandra/.local/lib/python3.8/site-packages/django/apps/config.py", line 269, in import_models
    self.models_module = import_module(models_module_name)
  File "/usr/lib/python3.8/importlib/__init__.py", line 127, in import_module
    return _bootstrap._gcd_import(name[level:], package, level)
  File "<frozen importlib._bootstrap>", line 1014, in _gcd_import
  File "<frozen importlib._bootstrap>", line 991, in _find_and_load
  File "<frozen importlib._bootstrap>", line 975, in _find_and_load_unlocked
  File "<frozen importlib._bootstrap>", line 671, in _load_unlocked
  File "<frozen importlib._bootstrap_external>", line 844, in exec_module
  File "<frozen importlib._bootstrap_external>", line 981, in get_code
  File "<frozen importlib._bootstrap_external>", line 911, in source_to_code
  File "<frozen importlib._bootstrap>", line 219, in _call_with_frames_removed
  File "/home/ramachandra/movies/app1/models.py", line 14
    
    ^
SyntaxError: unexpected EOF while parsing
/home/ramachandra/movies/app1/models.py changed, reloading.
Watching for file changes with StatReloader
Exception in thread django-main-thread:
Traceback (most recent call last):
  File "/usr/lib/python3.8/threading.py", line 932, in _bootstrap_inner
    self.run()
  File "/usr/lib/python3.8/threading.py", line 870, in run
    self._target(*self._args, **self._kwargs)
  File "/home/ramachandra/.local/lib/python3.8/site-packages/django/utils/autoreload.py", line 64, in wrapper
    fn(*args, **kwargs)
  File "/home/ramachandra/.local/lib/python3.8/site-packages/django/core/management/commands/runserver.py", line 125, in inner_run
    autoreload.raise_last_exception()
  File "/home/ramachandra/.local/lib/python3.8/site-packages/django/utils/autoreload.py", line 87, in raise_last_exception
    raise _exception[1]
  File "/home/ramachandra/.local/lib/python3.8/site-packages/django/core/management/__init__.py", line 394, in execute
    autoreload.check_errors(django.setup)()
  File "/home/ramachandra/.local/lib/python3.8/site-packages/django/utils/autoreload.py", line 64, in wrapper
    fn(*args, **kwargs)
  File "/home/ramachandra/.local/lib/python3.8/site-packages/django/__init__.py", line 24, in setup
    apps.populate(settings.INSTALLED_APPS)
  File "/home/ramachandra/.local/lib/python3.8/site-packages/django/apps/registry.py", line 116, in populate
    app_config.import_models()
  File "/home/ramachandra/.local/lib/python3.8/site-packages/django/apps/config.py", line 269, in import_models
    self.models_module = import_module(models_module_name)
  File "/usr/lib/python3.8/importlib/__init__.py", line 127, in import_module
    return _bootstrap._gcd_import(name[level:], package, level)
  File "<frozen importlib._bootstrap>", line 1014, in _gcd_import
  File "<frozen importlib._bootstrap>", line 991, in _find_and_load
  File "<frozen importlib._bootstrap>", line 975, in _find_and_load_unlocked
  File "<frozen importlib._bootstrap>", line 671, in _load_unlocked
  File "<frozen importlib._bootstrap_external>", line 848, in exec_module
  File "<frozen importlib._bootstrap>", line 219, in _call_with_frames_removed
  File "/home/ramachandra/movies/app1/models.py", line 13, in <module>
    class Favorites(models.Model):
  File "/home/ramachandra/movies/app1/models.py", line 14, in Favorites
    user
NameError: name 'user' is not defined
/home/ramachandra/movies/app1/models.py changed, reloading.
Watching for file changes with StatReloader
Exception in thread django-main-thread:
Traceback (most recent call last):
  File "/usr/lib/python3.8/threading.py", line 932, in _bootstrap_inner
    self.run()
  File "/usr/lib/python3.8/threading.py", line 870, in run
    self._target(*self._args, **self._kwargs)
  File "/home/ramachandra/.local/lib/python3.8/site-packages/django/utils/autoreload.py", line 64, in wrapper
    fn(*args, **kwargs)
  File "/home/ramachandra/.local/lib/python3.8/site-packages/django/core/management/commands/runserver.py", line 125, in inner_run
    autoreload.raise_last_exception()
  File "/home/ramachandra/.local/lib/python3.8/site-packages/django/utils/autoreload.py", line 87, in raise_last_exception
    raise _exception[1]
  File "/home/ramachandra/.local/lib/python3.8/site-packages/django/core/management/__init__.py", line 394, in execute
    autoreload.check_errors(django.setup)()
  File "/home/ramachandra/.local/lib/python3.8/site-packages/django/utils/autoreload.py", line 64, in wrapper
    fn(*args, **kwargs)
  File "/home/ramachandra/.local/lib/python3.8/site-packages/django/__init__.py", line 24, in setup
    apps.populate(settings.INSTALLED_APPS)
  File "/home/ramachandra/.local/lib/python3.8/site-packages/django/apps/registry.py", line 116, in populate
    app_config.import_models()
  File "/home/ramachandra/.local/lib/python3.8/site-packages/django/apps/config.py", line 269, in import_models
    self.models_module = import_module(models_module_name)
  File "/usr/lib/python3.8/importlib/__init__.py", line 127, in import_module
    return _bootstrap._gcd_import(name[level:], package, level)
  File "<frozen importlib._bootstrap>", line 1014, in _gcd_import
  File "<frozen importlib._bootstrap>", line 991, in _find_and_load
  File "<frozen importlib._bootstrap>", line 975, in _find_and_load_unlocked
  File "<frozen importlib._bootstrap>", line 671, in _load_unlocked
  File "<frozen importlib._bootstrap_external>", line 848, in exec_module
  File "<frozen importlib._bootstrap>", line 219, in _call_with_frames_removed
  File "/home/ramachandra/movies/app1/models.py", line 13, in <module>
    class Favorites(models.Model):
  File "/home/ramachandra/movies/app1/models.py", line 14, in Favorites
    user=mo
NameError: name 'mo' is not defined
/home/ramachandra/movies/app1/models.py changed, reloading.
Watching for file changes with StatReloader
Exception in thread django-main-thread:
Traceback (most recent call last):
  File "/usr/lib/python3.8/threading.py", line 932, in _bootstrap_inner
    self.run()
  File "/usr/lib/python3.8/threading.py", line 870, in run
    self._target(*self._args, **self._kwargs)
  File "/home/ramachandra/.local/lib/python3.8/site-packages/django/utils/autoreload.py", line 64, in wrapper
    fn(*args, **kwargs)
  File "/home/ramachandra/.local/lib/python3.8/site-packages/django/core/management/commands/runserver.py", line 125, in inner_run
    autoreload.raise_last_exception()
  File "/home/ramachandra/.local/lib/python3.8/site-packages/django/utils/autoreload.py", line 87, in raise_last_exception
    raise _exception[1]
  File "/home/ramachandra/.local/lib/python3.8/site-packages/django/core/management/__init__.py", line 394, in execute
    autoreload.check_errors(django.setup)()
  File "/home/ramachandra/.local/lib/python3.8/site-packages/django/utils/autoreload.py", line 64, in wrapper
    fn(*args, **kwargs)
  File "/home/ramachandra/.local/lib/python3.8/site-packages/django/__init__.py", line 24, in setup
    apps.populate(settings.INSTALLED_APPS)
  File "/home/ramachandra/.local/lib/python3.8/site-packages/django/apps/registry.py", line 116, in populate
    app_config.import_models()
  File "/home/ramachandra/.local/lib/python3.8/site-packages/django/apps/config.py", line 269, in import_models
    self.models_module = import_module(models_module_name)
  File "/usr/lib/python3.8/importlib/__init__.py", line 127, in import_module
    return _bootstrap._gcd_import(name[level:], package, level)
  File "<frozen importlib._bootstrap>", line 1014, in _gcd_import
  File "<frozen importlib._bootstrap>", line 991, in _find_and_load
  File "<frozen importlib._bootstrap>", line 975, in _find_and_load_unlocked
  File "<frozen importlib._bootstrap>", line 671, in _load_unlocked
  File "<frozen importlib._bootstrap_external>", line 844, in exec_module
  File "<frozen importlib._bootstrap_external>", line 981, in get_code
  File "<frozen importlib._bootstrap_external>", line 911, in source_to_code
  File "<frozen importlib._bootstrap>", line 219, in _call_with_frames_removed
  File "/home/ramachandra/movies/app1/models.py", line 14
    user=models.
               ^
SyntaxError: invalid syntax
/home/ramachandra/movies/app1/models.py changed, reloading.
Watching for file changes with StatReloader
Exception in thread django-main-thread:
Traceback (most recent call last):
  File "/usr/lib/python3.8/threading.py", line 932, in _bootstrap_inner
    self.run()
  File "/usr/lib/python3.8/threading.py", line 870, in run
    self._target(*self._args, **self._kwargs)
  File "/home/ramachandra/.local/lib/python3.8/site-packages/django/utils/autoreload.py", line 64, in wrapper
    fn(*args, **kwargs)
  File "/home/ramachandra/.local/lib/python3.8/site-packages/django/core/management/commands/runserver.py", line 125, in inner_run
    autoreload.raise_last_exception()
  File "/home/ramachandra/.local/lib/python3.8/site-packages/django/utils/autoreload.py", line 87, in raise_last_exception
    raise _exception[1]
  File "/home/ramachandra/.local/lib/python3.8/site-packages/django/core/management/__init__.py", line 394, in execute
    autoreload.check_errors(django.setup)()
  File "/home/ramachandra/.local/lib/python3.8/site-packages/django/utils/autoreload.py", line 64, in wrapper
    fn(*args, **kwargs)
  File "/home/ramachandra/.local/lib/python3.8/site-packages/django/__init__.py", line 24, in setup
    apps.populate(settings.INSTALLED_APPS)
  File "/home/ramachandra/.local/lib/python3.8/site-packages/django/apps/registry.py", line 116, in populate
    app_config.import_models()
  File "/home/ramachandra/.local/lib/python3.8/site-packages/django/apps/config.py", line 269, in import_models
    self.models_module = import_module(models_module_name)
  File "/usr/lib/python3.8/importlib/__init__.py", line 127, in import_module
    return _bootstrap._gcd_import(name[level:], package, level)
  File "<frozen importlib._bootstrap>", line 1014, in _gcd_import
  File "<frozen importlib._bootstrap>", line 991, in _find_and_load
  File "<frozen importlib._bootstrap>", line 975, in _find_and_load_unlocked
  File "<frozen importlib._bootstrap>", line 671, in _load_unlocked
  File "<frozen importlib._bootstrap_external>", line 848, in exec_module
  File "<frozen importlib._bootstrap>", line 219, in _call_with_frames_removed
  File "/home/ramachandra/movies/app1/models.py", line 13, in <module>
    class Favorites(models.Model):
  File "/home/ramachandra/movies/app1/models.py", line 14, in Favorites
    user=models.ForeignKey()
TypeError: __init__() missing 2 required positional arguments: 'to' and 'on_delete'
/home/ramachandra/movies/app1/models.py changed, reloading.
Watching for file changes with StatReloader
Exception in thread django-main-thread:
Traceback (most recent call last):
  File "/usr/lib/python3.8/threading.py", line 932, in _bootstrap_inner
    self.run()
  File "/usr/lib/python3.8/threading.py", line 870, in run
    self._target(*self._args, **self._kwargs)
  File "/home/ramachandra/.local/lib/python3.8/site-packages/django/utils/autoreload.py", line 64, in wrapper
    fn(*args, **kwargs)
  File "/home/ramachandra/.local/lib/python3.8/site-packages/django/core/management/commands/runserver.py", line 125, in inner_run
    autoreload.raise_last_exception()
  File "/home/ramachandra/.local/lib/python3.8/site-packages/django/utils/autoreload.py", line 87, in raise_last_exception
    raise _exception[1]
  File "/home/ramachandra/.local/lib/python3.8/site-packages/django/core/management/__init__.py", line 394, in execute
    autoreload.check_errors(django.setup)()
  File "/home/ramachandra/.local/lib/python3.8/site-packages/django/utils/autoreload.py", line 64, in wrapper
    fn(*args, **kwargs)
  File "/home/ramachandra/.local/lib/python3.8/site-packages/django/__init__.py", line 24, in setup
    apps.populate(settings.INSTALLED_APPS)
  File "/home/ramachandra/.local/lib/python3.8/site-packages/django/apps/registry.py", line 116, in populate
    app_config.import_models()
  File "/home/ramachandra/.local/lib/python3.8/site-packages/django/apps/config.py", line 269, in import_models
    self.models_module = import_module(models_module_name)
  File "/usr/lib/python3.8/importlib/__init__.py", line 127, in import_module
    return _bootstrap._gcd_import(name[level:], package, level)
  File "<frozen importlib._bootstrap>", line 1014, in _gcd_import
  File "<frozen importlib._bootstrap>", line 991, in _find_and_load
  File "<frozen importlib._bootstrap>", line 975, in _find_and_load_unlocked
  File "<frozen importlib._bootstrap>", line 671, in _load_unlocked
  File "<frozen importlib._bootstrap_external>", line 848, in exec_module
  File "<frozen importlib._bootstrap>", line 219, in _call_with_frames_removed
  File "/home/ramachandra/movies/app1/models.py", line 13, in <module>
    class Favorites(models.Model):
  File "/home/ramachandra/movies/app1/models.py", line 14, in Favorites
    user=models.ForeignKey(User)
NameError: name 'User' is not defined
/home/ramachandra/movies/app1/models.py changed, reloading.
Watching for file changes with StatReloader
Exception in thread django-main-thread:
Traceback (most recent call last):
  File "/usr/lib/python3.8/threading.py", line 932, in _bootstrap_inner
    self.run()
  File "/usr/lib/python3.8/threading.py", line 870, in run
    self._target(*self._args, **self._kwargs)
  File "/home/ramachandra/.local/lib/python3.8/site-packages/django/utils/autoreload.py", line 64, in wrapper
    fn(*args, **kwargs)
  File "/home/ramachandra/.local/lib/python3.8/site-packages/django/core/management/commands/runserver.py", line 125, in inner_run
    autoreload.raise_last_exception()
  File "/home/ramachandra/.local/lib/python3.8/site-packages/django/utils/autoreload.py", line 87, in raise_last_exception
    raise _exception[1]
  File "/home/ramachandra/.local/lib/python3.8/site-packages/django/core/management/__init__.py", line 394, in execute
    autoreload.check_errors(django.setup)()
  File "/home/ramachandra/.local/lib/python3.8/site-packages/django/utils/autoreload.py", line 64, in wrapper
    fn(*args, **kwargs)
  File "/home/ramachandra/.local/lib/python3.8/site-packages/django/__init__.py", line 24, in setup
    apps.populate(settings.INSTALLED_APPS)
  File "/home/ramachandra/.local/lib/python3.8/site-packages/django/apps/registry.py", line 116, in populate
    app_config.import_models()
  File "/home/ramachandra/.local/lib/python3.8/site-packages/django/apps/config.py", line 269, in import_models
    self.models_module = import_module(models_module_name)
  File "/usr/lib/python3.8/importlib/__init__.py", line 127, in import_module
    return _bootstrap._gcd_import(name[level:], package, level)
  File "<frozen importlib._bootstrap>", line 1014, in _gcd_import
  File "<frozen importlib._bootstrap>", line 991, in _find_and_load
  File "<frozen importlib._bootstrap>", line 975, in _find_and_load_unlocked
  File "<frozen importlib._bootstrap>", line 671, in _load_unlocked
  File "<frozen importlib._bootstrap_external>", line 848, in exec_module
  File "<frozen importlib._bootstrap>", line 219, in _call_with_frames_removed
  File "/home/ramachandra/movies/app1/models.py", line 13, in <module>
    class Favorites(models.Model):
  File "/home/ramachandra/movies/app1/models.py", line 14, in Favorites
    user=models.ForeignKey(User,)
NameError: name 'User' is not defined
/home/ramachandra/movies/app1/models.py changed, reloading.
Watching for file changes with StatReloader
Exception in thread django-main-thread:
Traceback (most recent call last):
  File "/usr/lib/python3.8/threading.py", line 932, in _bootstrap_inner
    self.run()
  File "/usr/lib/python3.8/threading.py", line 870, in run
    self._target(*self._args, **self._kwargs)
  File "/home/ramachandra/.local/lib/python3.8/site-packages/django/utils/autoreload.py", line 64, in wrapper
    fn(*args, **kwargs)
  File "/home/ramachandra/.local/lib/python3.8/site-packages/django/core/management/commands/runserver.py", line 125, in inner_run
    autoreload.raise_last_exception()
  File "/home/ramachandra/.local/lib/python3.8/site-packages/django/utils/autoreload.py", line 87, in raise_last_exception
    raise _exception[1]
  File "/home/ramachandra/.local/lib/python3.8/site-packages/django/core/management/__init__.py", line 394, in execute
    autoreload.check_errors(django.setup)()
  File "/home/ramachandra/.local/lib/python3.8/site-packages/django/utils/autoreload.py", line 64, in wrapper
    fn(*args, **kwargs)
  File "/home/ramachandra/.local/lib/python3.8/site-packages/django/__init__.py", line 24, in setup
    apps.populate(settings.INSTALLED_APPS)
  File "/home/ramachandra/.local/lib/python3.8/site-packages/django/apps/registry.py", line 116, in populate
    app_config.import_models()
  File "/home/ramachandra/.local/lib/python3.8/site-packages/django/apps/config.py", line 269, in import_models
    self.models_module = import_module(models_module_name)
  File "/usr/lib/python3.8/importlib/__init__.py", line 127, in import_module
    return _bootstrap._gcd_import(name[level:], package, level)
  File "<frozen importlib._bootstrap>", line 1014, in _gcd_import
  File "<frozen importlib._bootstrap>", line 991, in _find_and_load
  File "<frozen importlib._bootstrap>", line 975, in _find_and_load_unlocked
  File "<frozen importlib._bootstrap>", line 671, in _load_unlocked
  File "<frozen importlib._bootstrap_external>", line 848, in exec_module
  File "<frozen importlib._bootstrap>", line 219, in _call_with_frames_removed
  File "/home/ramachandra/movies/app1/models.py", line 13, in <module>
    class Favorites(models.Model):
  File "/home/ramachandra/movies/app1/models.py", line 14, in Favorites
    user=models.ForeignKey(User,on)
NameError: name 'User' is not defined
/home/ramachandra/movies/app1/models.py changed, reloading.
Watching for file changes with StatReloader
Exception in thread django-main-thread:
Traceback (most recent call last):
  File "/usr/lib/python3.8/threading.py", line 932, in _bootstrap_inner
    self.run()
  File "/usr/lib/python3.8/threading.py", line 870, in run
    self._target(*self._args, **self._kwargs)
  File "/home/ramachandra/.local/lib/python3.8/site-packages/django/utils/autoreload.py", line 64, in wrapper
    fn(*args, **kwargs)
  File "/home/ramachandra/.local/lib/python3.8/site-packages/django/core/management/commands/runserver.py", line 125, in inner_run
    autoreload.raise_last_exception()
  File "/home/ramachandra/.local/lib/python3.8/site-packages/django/utils/autoreload.py", line 87, in raise_last_exception
    raise _exception[1]
  File "/home/ramachandra/.local/lib/python3.8/site-packages/django/core/management/__init__.py", line 394, in execute
    autoreload.check_errors(django.setup)()
  File "/home/ramachandra/.local/lib/python3.8/site-packages/django/utils/autoreload.py", line 64, in wrapper
    fn(*args, **kwargs)
  File "/home/ramachandra/.local/lib/python3.8/site-packages/django/__init__.py", line 24, in setup
    apps.populate(settings.INSTALLED_APPS)
  File "/home/ramachandra/.local/lib/python3.8/site-packages/django/apps/registry.py", line 116, in populate
    app_config.import_models()
  File "/home/ramachandra/.local/lib/python3.8/site-packages/django/apps/config.py", line 269, in import_models
    self.models_module = import_module(models_module_name)
  File "/usr/lib/python3.8/importlib/__init__.py", line 127, in import_module
    return _bootstrap._gcd_import(name[level:], package, level)
  File "<frozen importlib._bootstrap>", line 1014, in _gcd_import
  File "<frozen importlib._bootstrap>", line 991, in _find_and_load
  File "<frozen importlib._bootstrap>", line 975, in _find_and_load_unlocked
  File "<frozen importlib._bootstrap>", line 671, in _load_unlocked
  File "<frozen importlib._bootstrap_external>", line 844, in exec_module
  File "<frozen importlib._bootstrap_external>", line 981, in get_code
  File "<frozen importlib._bootstrap_external>", line 911, in source_to_code
  File "<frozen importlib._bootstrap>", line 219, in _call_with_frames_removed
  File "/home/ramachandra/movies/app1/models.py", line 14
    user=models.ForeignKey(User,on_delete=)
                                          ^
SyntaxError: invalid syntax
/home/ramachandra/movies/app1/models.py changed, reloading.
Watching for file changes with StatReloader
Exception in thread django-main-thread:
Traceback (most recent call last):
  File "/usr/lib/python3.8/threading.py", line 932, in _bootstrap_inner
    self.run()
  File "/usr/lib/python3.8/threading.py", line 870, in run
    self._target(*self._args, **self._kwargs)
  File "/home/ramachandra/.local/lib/python3.8/site-packages/django/utils/autoreload.py", line 64, in wrapper
    fn(*args, **kwargs)
  File "/home/ramachandra/.local/lib/python3.8/site-packages/django/core/management/commands/runserver.py", line 125, in inner_run
    autoreload.raise_last_exception()
  File "/home/ramachandra/.local/lib/python3.8/site-packages/django/utils/autoreload.py", line 87, in raise_last_exception
    raise _exception[1]
  File "/home/ramachandra/.local/lib/python3.8/site-packages/django/core/management/__init__.py", line 394, in execute
    autoreload.check_errors(django.setup)()
  File "/home/ramachandra/.local/lib/python3.8/site-packages/django/utils/autoreload.py", line 64, in wrapper
    fn(*args, **kwargs)
  File "/home/ramachandra/.local/lib/python3.8/site-packages/django/__init__.py", line 24, in setup
    apps.populate(settings.INSTALLED_APPS)
  File "/home/ramachandra/.local/lib/python3.8/site-packages/django/apps/registry.py", line 116, in populate
    app_config.import_models()
  File "/home/ramachandra/.local/lib/python3.8/site-packages/django/apps/config.py", line 269, in import_models
    self.models_module = import_module(models_module_name)
  File "/usr/lib/python3.8/importlib/__init__.py", line 127, in import_module
    return _bootstrap._gcd_import(name[level:], package, level)
  File "<frozen importlib._bootstrap>", line 1014, in _gcd_import
  File "<frozen importlib._bootstrap>", line 991, in _find_and_load
  File "<frozen importlib._bootstrap>", line 975, in _find_and_load_unlocked
  File "<frozen importlib._bootstrap>", line 671, in _load_unlocked
  File "<frozen importlib._bootstrap_external>", line 848, in exec_module
  File "<frozen importlib._bootstrap>", line 219, in _call_with_frames_removed
  File "/home/ramachandra/movies/app1/models.py", line 13, in <module>
    class Favorites(models.Model):
  File "/home/ramachandra/movies/app1/models.py", line 14, in Favorites
    user=models.ForeignKey(User,on_delete=Ca)
NameError: name 'User' is not defined
/home/ramachandra/movies/app1/models.py changed, reloading.
Watching for file changes with StatReloader
Exception in thread django-main-thread:
Traceback (most recent call last):
  File "/usr/lib/python3.8/threading.py", line 932, in _bootstrap_inner
    self.run()
  File "/usr/lib/python3.8/threading.py", line 870, in run
    self._target(*self._args, **self._kwargs)
  File "/home/ramachandra/.local/lib/python3.8/site-packages/django/utils/autoreload.py", line 64, in wrapper
    fn(*args, **kwargs)
  File "/home/ramachandra/.local/lib/python3.8/site-packages/django/core/management/commands/runserver.py", line 125, in inner_run
    autoreload.raise_last_exception()
  File "/home/ramachandra/.local/lib/python3.8/site-packages/django/utils/autoreload.py", line 87, in raise_last_exception
    raise _exception[1]
  File "/home/ramachandra/.local/lib/python3.8/site-packages/django/core/management/__init__.py", line 394, in execute
    autoreload.check_errors(django.setup)()
  File "/home/ramachandra/.local/lib/python3.8/site-packages/django/utils/autoreload.py", line 64, in wrapper
    fn(*args, **kwargs)
  File "/home/ramachandra/.local/lib/python3.8/site-packages/django/__init__.py", line 24, in setup
    apps.populate(settings.INSTALLED_APPS)
  File "/home/ramachandra/.local/lib/python3.8/site-packages/django/apps/registry.py", line 116, in populate
    app_config.import_models()
  File "/home/ramachandra/.local/lib/python3.8/site-packages/django/apps/config.py", line 269, in import_models
    self.models_module = import_module(models_module_name)
  File "/usr/lib/python3.8/importlib/__init__.py", line 127, in import_module
    return _bootstrap._gcd_import(name[level:], package, level)
  File "<frozen importlib._bootstrap>", line 1014, in _gcd_import
  File "<frozen importlib._bootstrap>", line 991, in _find_and_load
  File "<frozen importlib._bootstrap>", line 975, in _find_and_load_unlocked
  File "<frozen importlib._bootstrap>", line 671, in _load_unlocked
  File "<frozen importlib._bootstrap_external>", line 848, in exec_module
  File "<frozen importlib._bootstrap>", line 219, in _call_with_frames_removed
  File "/home/ramachandra/movies/app1/models.py", line 13, in <module>
    class Favorites(models.Model):
  File "/home/ramachandra/movies/app1/models.py", line 14, in Favorites
    user=models.ForeignKey(User,on_delete=Cas)
NameError: name 'User' is not defined
/home/ramachandra/movies/app1/models.py changed, reloading.
Watching for file changes with StatReloader
Exception in thread django-main-thread:
Traceback (most recent call last):
  File "/usr/lib/python3.8/threading.py", line 932, in _bootstrap_inner
    self.run()
  File "/usr/lib/python3.8/threading.py", line 870, in run
    self._target(*self._args, **self._kwargs)
  File "/home/ramachandra/.local/lib/python3.8/site-packages/django/utils/autoreload.py", line 64, in wrapper
    fn(*args, **kwargs)
  File "/home/ramachandra/.local/lib/python3.8/site-packages/django/core/management/commands/runserver.py", line 125, in inner_run
    autoreload.raise_last_exception()
  File "/home/ramachandra/.local/lib/python3.8/site-packages/django/utils/autoreload.py", line 87, in raise_last_exception
    raise _exception[1]
  File "/home/ramachandra/.local/lib/python3.8/site-packages/django/core/management/__init__.py", line 394, in execute
    autoreload.check_errors(django.setup)()
  File "/home/ramachandra/.local/lib/python3.8/site-packages/django/utils/autoreload.py", line 64, in wrapper
    fn(*args, **kwargs)
  File "/home/ramachandra/.local/lib/python3.8/site-packages/django/__init__.py", line 24, in setup
    apps.populate(settings.INSTALLED_APPS)
  File "/home/ramachandra/.local/lib/python3.8/site-packages/django/apps/registry.py", line 116, in populate
    app_config.import_models()
  File "/home/ramachandra/.local/lib/python3.8/site-packages/django/apps/config.py", line 269, in import_models
    self.models_module = import_module(models_module_name)
  File "/usr/lib/python3.8/importlib/__init__.py", line 127, in import_module
    return _bootstrap._gcd_import(name[level:], package, level)
  File "<frozen importlib._bootstrap>", line 1014, in _gcd_import
  File "<frozen importlib._bootstrap>", line 991, in _find_and_load
  File "<frozen importlib._bootstrap>", line 975, in _find_and_load_unlocked
  File "<frozen importlib._bootstrap>", line 671, in _load_unlocked
  File "<frozen importlib._bootstrap_external>", line 848, in exec_module
  File "<frozen importlib._bootstrap>", line 219, in _call_with_frames_removed
  File "/home/ramachandra/movies/app1/models.py", line 13, in <module>
    class Favorites(models.Model):
  File "/home/ramachandra/movies/app1/models.py", line 14, in Favorites
    user=models.ForeignKey(User,on_delete=Cascade)
NameError: name 'User' is not defined
/home/ramachandra/movies/app1/models.py changed, reloading.
Watching for file changes with StatReloader
Exception in thread django-main-thread:
Traceback (most recent call last):
  File "/usr/lib/python3.8/threading.py", line 932, in _bootstrap_inner
    self.run()
  File "/usr/lib/python3.8/threading.py", line 870, in run
    self._target(*self._args, **self._kwargs)
  File "/home/ramachandra/.local/lib/python3.8/site-packages/django/utils/autoreload.py", line 64, in wrapper
    fn(*args, **kwargs)
  File "/home/ramachandra/.local/lib/python3.8/site-packages/django/core/management/commands/runserver.py", line 125, in inner_run
    autoreload.raise_last_exception()
  File "/home/ramachandra/.local/lib/python3.8/site-packages/django/utils/autoreload.py", line 87, in raise_last_exception
    raise _exception[1]
  File "/home/ramachandra/.local/lib/python3.8/site-packages/django/core/management/__init__.py", line 394, in execute
    autoreload.check_errors(django.setup)()
  File "/home/ramachandra/.local/lib/python3.8/site-packages/django/utils/autoreload.py", line 64, in wrapper
    fn(*args, **kwargs)
  File "/home/ramachandra/.local/lib/python3.8/site-packages/django/__init__.py", line 24, in setup
    apps.populate(settings.INSTALLED_APPS)
  File "/home/ramachandra/.local/lib/python3.8/site-packages/django/apps/registry.py", line 116, in populate
    app_config.import_models()
  File "/home/ramachandra/.local/lib/python3.8/site-packages/django/apps/config.py", line 269, in import_models
    self.models_module = import_module(models_module_name)
  File "/usr/lib/python3.8/importlib/__init__.py", line 127, in import_module
    return _bootstrap._gcd_import(name[level:], package, level)
  File "<frozen importlib._bootstrap>", line 1014, in _gcd_import
  File "<frozen importlib._bootstrap>", line 991, in _find_and_load
  File "<frozen importlib._bootstrap>", line 975, in _find_and_load_unlocked
  File "<frozen importlib._bootstrap>", line 671, in _load_unlocked
  File "<frozen importlib._bootstrap_external>", line 848, in exec_module
  File "<frozen importlib._bootstrap>", line 219, in _call_with_frames_removed
  File "/home/ramachandra/movies/app1/models.py", line 13, in <module>
    class Favorites(models.Model):
  File "/home/ramachandra/movies/app1/models.py", line 14, in Favorites
    user=models.ForeignKey(User,on_delete=CAS)
NameError: name 'User' is not defined
/home/ramachandra/movies/app1/models.py changed, reloading.
Watching for file changes with StatReloader
Exception in thread django-main-thread:
Traceback (most recent call last):
  File "/usr/lib/python3.8/threading.py", line 932, in _bootstrap_inner
    self.run()
  File "/usr/lib/python3.8/threading.py", line 870, in run
    self._target(*self._args, **self._kwargs)
  File "/home/ramachandra/.local/lib/python3.8/site-packages/django/utils/autoreload.py", line 64, in wrapper
    fn(*args, **kwargs)
  File "/home/ramachandra/.local/lib/python3.8/site-packages/django/core/management/commands/runserver.py", line 125, in inner_run
    autoreload.raise_last_exception()
  File "/home/ramachandra/.local/lib/python3.8/site-packages/django/utils/autoreload.py", line 87, in raise_last_exception
    raise _exception[1]
  File "/home/ramachandra/.local/lib/python3.8/site-packages/django/core/management/__init__.py", line 394, in execute
    autoreload.check_errors(django.setup)()
  File "/home/ramachandra/.local/lib/python3.8/site-packages/django/utils/autoreload.py", line 64, in wrapper
    fn(*args, **kwargs)
  File "/home/ramachandra/.local/lib/python3.8/site-packages/django/__init__.py", line 24, in setup
    apps.populate(settings.INSTALLED_APPS)
  File "/home/ramachandra/.local/lib/python3.8/site-packages/django/apps/registry.py", line 116, in populate
    app_config.import_models()
  File "/home/ramachandra/.local/lib/python3.8/site-packages/django/apps/config.py", line 269, in import_models
    self.models_module = import_module(models_module_name)
  File "/usr/lib/python3.8/importlib/__init__.py", line 127, in import_module
    return _bootstrap._gcd_import(name[level:], package, level)
  File "<frozen importlib._bootstrap>", line 1014, in _gcd_import
  File "<frozen importlib._bootstrap>", line 991, in _find_and_load
  File "<frozen importlib._bootstrap>", line 975, in _find_and_load_unlocked
  File "<frozen importlib._bootstrap>", line 671, in _load_unlocked
  File "<frozen importlib._bootstrap_external>", line 844, in exec_module
  File "<frozen importlib._bootstrap_external>", line 981, in get_code
  File "<frozen importlib._bootstrap_external>", line 911, in source_to_code
  File "<frozen importlib._bootstrap>", line 219, in _call_with_frames_removed
  File "/home/ramachandra/movies/app1/models.py", line 14
    user=models.ForeignKey(User,on_delete=)
                                          ^
SyntaxError: invalid syntax
/home/ramachandra/movies/app1/models.py changed, reloading.
Watching for file changes with StatReloader
Exception in thread django-main-thread:
Traceback (most recent call last):
  File "/usr/lib/python3.8/threading.py", line 932, in _bootstrap_inner
    self.run()
  File "/usr/lib/python3.8/threading.py", line 870, in run
    self._target(*self._args, **self._kwargs)
  File "/home/ramachandra/.local/lib/python3.8/site-packages/django/utils/autoreload.py", line 64, in wrapper
    fn(*args, **kwargs)
  File "/home/ramachandra/.local/lib/python3.8/site-packages/django/core/management/commands/runserver.py", line 125, in inner_run
    autoreload.raise_last_exception()
  File "/home/ramachandra/.local/lib/python3.8/site-packages/django/utils/autoreload.py", line 87, in raise_last_exception
    raise _exception[1]
  File "/home/ramachandra/.local/lib/python3.8/site-packages/django/core/management/__init__.py", line 394, in execute
    autoreload.check_errors(django.setup)()
  File "/home/ramachandra/.local/lib/python3.8/site-packages/django/utils/autoreload.py", line 64, in wrapper
    fn(*args, **kwargs)
  File "/home/ramachandra/.local/lib/python3.8/site-packages/django/__init__.py", line 24, in setup
    apps.populate(settings.INSTALLED_APPS)
  File "/home/ramachandra/.local/lib/python3.8/site-packages/django/apps/registry.py", line 116, in populate
    app_config.import_models()
  File "/home/ramachandra/.local/lib/python3.8/site-packages/django/apps/config.py", line 269, in import_models
    self.models_module = import_module(models_module_name)
  File "/usr/lib/python3.8/importlib/__init__.py", line 127, in import_module
    return _bootstrap._gcd_import(name[level:], package, level)
  File "<frozen importlib._bootstrap>", line 1014, in _gcd_import
  File "<frozen importlib._bootstrap>", line 991, in _find_and_load
  File "<frozen importlib._bootstrap>", line 975, in _find_and_load_unlocked
  File "<frozen importlib._bootstrap>", line 671, in _load_unlocked
  File "<frozen importlib._bootstrap_external>", line 844, in exec_module
  File "<frozen importlib._bootstrap_external>", line 981, in get_code
  File "<frozen importlib._bootstrap_external>", line 911, in source_to_code
  File "<frozen importlib._bootstrap>", line 219, in _call_with_frames_removed
  File "/home/ramachandra/movies/app1/models.py", line 2
    from djnago
              ^
SyntaxError: invalid syntax
/home/ramachandra/movies/app1/models.py changed, reloading.
Watching for file changes with StatReloader
Exception in thread django-main-thread:
Traceback (most recent call last):
  File "/usr/lib/python3.8/threading.py", line 932, in _bootstrap_inner
    self.run()
  File "/usr/lib/python3.8/threading.py", line 870, in run
    self._target(*self._args, **self._kwargs)
  File "/home/ramachandra/.local/lib/python3.8/site-packages/django/utils/autoreload.py", line 64, in wrapper
    fn(*args, **kwargs)
  File "/home/ramachandra/.local/lib/python3.8/site-packages/django/core/management/commands/runserver.py", line 125, in inner_run
    autoreload.raise_last_exception()
  File "/home/ramachandra/.local/lib/python3.8/site-packages/django/utils/autoreload.py", line 87, in raise_last_exception
    raise _exception[1]
  File "/home/ramachandra/.local/lib/python3.8/site-packages/django/core/management/__init__.py", line 394, in execute
    autoreload.check_errors(django.setup)()
  File "/home/ramachandra/.local/lib/python3.8/site-packages/django/utils/autoreload.py", line 64, in wrapper
    fn(*args, **kwargs)
  File "/home/ramachandra/.local/lib/python3.8/site-packages/django/__init__.py", line 24, in setup
    apps.populate(settings.INSTALLED_APPS)
  File "/home/ramachandra/.local/lib/python3.8/site-packages/django/apps/registry.py", line 116, in populate
    app_config.import_models()
  File "/home/ramachandra/.local/lib/python3.8/site-packages/django/apps/config.py", line 269, in import_models
    self.models_module = import_module(models_module_name)
  File "/usr/lib/python3.8/importlib/__init__.py", line 127, in import_module
    return _bootstrap._gcd_import(name[level:], package, level)
  File "<frozen importlib._bootstrap>", line 1014, in _gcd_import
  File "<frozen importlib._bootstrap>", line 991, in _find_and_load
  File "<frozen importlib._bootstrap>", line 975, in _find_and_load_unlocked
  File "<frozen importlib._bootstrap>", line 671, in _load_unlocked
  File "<frozen importlib._bootstrap_external>", line 844, in exec_module
  File "<frozen importlib._bootstrap_external>", line 981, in get_code
  File "<frozen importlib._bootstrap_external>", line 911, in source_to_code
  File "<frozen importlib._bootstrap>", line 219, in _call_with_frames_removed
  File "/home/ramachandra/movies/app1/models.py", line 2
    from djnago.con
                  ^
SyntaxError: invalid syntax
/home/ramachandra/movies/app1/models.py changed, reloading.
Watching for file changes with StatReloader
Exception in thread django-main-thread:
Traceback (most recent call last):
  File "/usr/lib/python3.8/threading.py", line 932, in _bootstrap_inner
    self.run()
  File "/usr/lib/python3.8/threading.py", line 870, in run
    self._target(*self._args, **self._kwargs)
  File "/home/ramachandra/.local/lib/python3.8/site-packages/django/utils/autoreload.py", line 64, in wrapper
    fn(*args, **kwargs)
  File "/home/ramachandra/.local/lib/python3.8/site-packages/django/core/management/commands/runserver.py", line 125, in inner_run
    autoreload.raise_last_exception()
  File "/home/ramachandra/.local/lib/python3.8/site-packages/django/utils/autoreload.py", line 87, in raise_last_exception
    raise _exception[1]
  File "/home/ramachandra/.local/lib/python3.8/site-packages/django/core/management/__init__.py", line 394, in execute
    autoreload.check_errors(django.setup)()
  File "/home/ramachandra/.local/lib/python3.8/site-packages/django/utils/autoreload.py", line 64, in wrapper
    fn(*args, **kwargs)
  File "/home/ramachandra/.local/lib/python3.8/site-packages/django/__init__.py", line 24, in setup
    apps.populate(settings.INSTALLED_APPS)
  File "/home/ramachandra/.local/lib/python3.8/site-packages/django/apps/registry.py", line 116, in populate
    app_config.import_models()
  File "/home/ramachandra/.local/lib/python3.8/site-packages/django/apps/config.py", line 269, in import_models
    self.models_module = import_module(models_module_name)
  File "/usr/lib/python3.8/importlib/__init__.py", line 127, in import_module
    return _bootstrap._gcd_import(name[level:], package, level)
  File "<frozen importlib._bootstrap>", line 1014, in _gcd_import
  File "<frozen importlib._bootstrap>", line 991, in _find_and_load
  File "<frozen importlib._bootstrap>", line 975, in _find_and_load_unlocked
  File "<frozen importlib._bootstrap>", line 671, in _load_unlocked
  File "<frozen importlib._bootstrap_external>", line 844, in exec_module
  File "<frozen importlib._bootstrap_external>", line 981, in get_code
  File "<frozen importlib._bootstrap_external>", line 911, in source_to_code
  File "<frozen importlib._bootstrap>", line 219, in _call_with_frames_removed
  File "/home/ramachandra/movies/app1/models.py", line 2
    from djanago.con
                   ^
SyntaxError: invalid syntax
/home/ramachandra/movies/app1/models.py changed, reloading.
Watching for file changes with StatReloader
Exception in thread django-main-thread:
Traceback (most recent call last):
  File "/usr/lib/python3.8/threading.py", line 932, in _bootstrap_inner
    self.run()
  File "/usr/lib/python3.8/threading.py", line 870, in run
    self._target(*self._args, **self._kwargs)
  File "/home/ramachandra/.local/lib/python3.8/site-packages/django/utils/autoreload.py", line 64, in wrapper
    fn(*args, **kwargs)
  File "/home/ramachandra/.local/lib/python3.8/site-packages/django/core/management/commands/runserver.py", line 125, in inner_run
    autoreload.raise_last_exception()
  File "/home/ramachandra/.local/lib/python3.8/site-packages/django/utils/autoreload.py", line 87, in raise_last_exception
    raise _exception[1]
  File "/home/ramachandra/.local/lib/python3.8/site-packages/django/core/management/__init__.py", line 394, in execute
    autoreload.check_errors(django.setup)()
  File "/home/ramachandra/.local/lib/python3.8/site-packages/django/utils/autoreload.py", line 64, in wrapper
    fn(*args, **kwargs)
  File "/home/ramachandra/.local/lib/python3.8/site-packages/django/__init__.py", line 24, in setup
    apps.populate(settings.INSTALLED_APPS)
  File "/home/ramachandra/.local/lib/python3.8/site-packages/django/apps/registry.py", line 116, in populate
    app_config.import_models()
  File "/home/ramachandra/.local/lib/python3.8/site-packages/django/apps/config.py", line 269, in import_models
    self.models_module = import_module(models_module_name)
  File "/usr/lib/python3.8/importlib/__init__.py", line 127, in import_module
    return _bootstrap._gcd_import(name[level:], package, level)
  File "<frozen importlib._bootstrap>", line 1014, in _gcd_import
  File "<frozen importlib._bootstrap>", line 991, in _find_and_load
  File "<frozen importlib._bootstrap>", line 975, in _find_and_load_unlocked
  File "<frozen importlib._bootstrap>", line 671, in _load_unlocked
  File "<frozen importlib._bootstrap_external>", line 844, in exec_module
  File "<frozen importlib._bootstrap_external>", line 981, in get_code
  File "<frozen importlib._bootstrap_external>", line 911, in source_to_code
  File "<frozen importlib._bootstrap>", line 219, in _call_with_frames_removed
  File "/home/ramachandra/movies/app1/models.py", line 2
    from django.con
                  ^
SyntaxError: invalid syntax
/home/ramachandra/movies/app1/models.py changed, reloading.
Watching for file changes with StatReloader
Exception in thread django-main-thread:
Traceback (most recent call last):
  File "/usr/lib/python3.8/threading.py", line 932, in _bootstrap_inner
    self.run()
  File "/usr/lib/python3.8/threading.py", line 870, in run
    self._target(*self._args, **self._kwargs)
  File "/home/ramachandra/.local/lib/python3.8/site-packages/django/utils/autoreload.py", line 64, in wrapper
    fn(*args, **kwargs)
  File "/home/ramachandra/.local/lib/python3.8/site-packages/django/core/management/commands/runserver.py", line 125, in inner_run
    autoreload.raise_last_exception()
  File "/home/ramachandra/.local/lib/python3.8/site-packages/django/utils/autoreload.py", line 87, in raise_last_exception
    raise _exception[1]
  File "/home/ramachandra/.local/lib/python3.8/site-packages/django/core/management/__init__.py", line 394, in execute
    autoreload.check_errors(django.setup)()
  File "/home/ramachandra/.local/lib/python3.8/site-packages/django/utils/autoreload.py", line 64, in wrapper
    fn(*args, **kwargs)
  File "/home/ramachandra/.local/lib/python3.8/site-packages/django/__init__.py", line 24, in setup
    apps.populate(settings.INSTALLED_APPS)
  File "/home/ramachandra/.local/lib/python3.8/site-packages/django/apps/registry.py", line 116, in populate
    app_config.import_models()
  File "/home/ramachandra/.local/lib/python3.8/site-packages/django/apps/config.py", line 269, in import_models
    self.models_module = import_module(models_module_name)
  File "/usr/lib/python3.8/importlib/__init__.py", line 127, in import_module
    return _bootstrap._gcd_import(name[level:], package, level)
  File "<frozen importlib._bootstrap>", line 1014, in _gcd_import
  File "<frozen importlib._bootstrap>", line 991, in _find_and_load
  File "<frozen importlib._bootstrap>", line 975, in _find_and_load_unlocked
  File "<frozen importlib._bootstrap>", line 671, in _load_unlocked
  File "<frozen importlib._bootstrap_external>", line 844, in exec_module
  File "<frozen importlib._bootstrap_external>", line 981, in get_code
  File "<frozen importlib._bootstrap_external>", line 911, in source_to_code
  File "<frozen importlib._bootstrap>", line 219, in _call_with_frames_removed
  File "/home/ramachandra/movies/app1/models.py", line 2
    from django.
               ^
SyntaxError: invalid syntax
/home/ramachandra/movies/app1/models.py changed, reloading.
Watching for file changes with StatReloader
Exception in thread django-main-thread:
Traceback (most recent call last):
  File "/usr/lib/python3.8/threading.py", line 932, in _bootstrap_inner
    self.run()
  File "/usr/lib/python3.8/threading.py", line 870, in run
    self._target(*self._args, **self._kwargs)
  File "/home/ramachandra/.local/lib/python3.8/site-packages/django/utils/autoreload.py", line 64, in wrapper
    fn(*args, **kwargs)
  File "/home/ramachandra/.local/lib/python3.8/site-packages/django/core/management/commands/runserver.py", line 125, in inner_run
    autoreload.raise_last_exception()
  File "/home/ramachandra/.local/lib/python3.8/site-packages/django/utils/autoreload.py", line 87, in raise_last_exception
    raise _exception[1]
  File "/home/ramachandra/.local/lib/python3.8/site-packages/django/core/management/__init__.py", line 394, in execute
    autoreload.check_errors(django.setup)()
  File "/home/ramachandra/.local/lib/python3.8/site-packages/django/utils/autoreload.py", line 64, in wrapper
    fn(*args, **kwargs)
  File "/home/ramachandra/.local/lib/python3.8/site-packages/django/__init__.py", line 24, in setup
    apps.populate(settings.INSTALLED_APPS)
  File "/home/ramachandra/.local/lib/python3.8/site-packages/django/apps/registry.py", line 116, in populate
    app_config.import_models()
  File "/home/ramachandra/.local/lib/python3.8/site-packages/django/apps/config.py", line 269, in import_models
    self.models_module = import_module(models_module_name)
  File "/usr/lib/python3.8/importlib/__init__.py", line 127, in import_module
    return _bootstrap._gcd_import(name[level:], package, level)
  File "<frozen importlib._bootstrap>", line 1014, in _gcd_import
  File "<frozen importlib._bootstrap>", line 991, in _find_and_load
  File "<frozen importlib._bootstrap>", line 975, in _find_and_load_unlocked
  File "<frozen importlib._bootstrap>", line 671, in _load_unlocked
  File "<frozen importlib._bootstrap_external>", line 844, in exec_module
  File "<frozen importlib._bootstrap_external>", line 981, in get_code
  File "<frozen importlib._bootstrap_external>", line 911, in source_to_code
  File "<frozen importlib._bootstrap>", line 219, in _call_with_frames_removed
  File "/home/ramachandra/movies/app1/models.py", line 2
    from django.contrib
                      ^
SyntaxError: invalid syntax
/home/ramachandra/movies/app1/models.py changed, reloading.
Watching for file changes with StatReloader
Exception in thread django-main-thread:
Traceback (most recent call last):
  File "/usr/lib/python3.8/threading.py", line 932, in _bootstrap_inner
    self.run()
  File "/usr/lib/python3.8/threading.py", line 870, in run
    self._target(*self._args, **self._kwargs)
  File "/home/ramachandra/.local/lib/python3.8/site-packages/django/utils/autoreload.py", line 64, in wrapper
    fn(*args, **kwargs)
  File "/home/ramachandra/.local/lib/python3.8/site-packages/django/core/management/commands/runserver.py", line 125, in inner_run
    autoreload.raise_last_exception()
  File "/home/ramachandra/.local/lib/python3.8/site-packages/django/utils/autoreload.py", line 87, in raise_last_exception
    raise _exception[1]
  File "/home/ramachandra/.local/lib/python3.8/site-packages/django/core/management/__init__.py", line 394, in execute
    autoreload.check_errors(django.setup)()
  File "/home/ramachandra/.local/lib/python3.8/site-packages/django/utils/autoreload.py", line 64, in wrapper
    fn(*args, **kwargs)
  File "/home/ramachandra/.local/lib/python3.8/site-packages/django/__init__.py", line 24, in setup
    apps.populate(settings.INSTALLED_APPS)
  File "/home/ramachandra/.local/lib/python3.8/site-packages/django/apps/registry.py", line 116, in populate
    app_config.import_models()
  File "/home/ramachandra/.local/lib/python3.8/site-packages/django/apps/config.py", line 269, in import_models
    self.models_module = import_module(models_module_name)
  File "/usr/lib/python3.8/importlib/__init__.py", line 127, in import_module
    return _bootstrap._gcd_import(name[level:], package, level)
  File "<frozen importlib._bootstrap>", line 1014, in _gcd_import
  File "<frozen importlib._bootstrap>", line 991, in _find_and_load
  File "<frozen importlib._bootstrap>", line 975, in _find_and_load_unlocked
  File "<frozen importlib._bootstrap>", line 671, in _load_unlocked
  File "<frozen importlib._bootstrap_external>", line 844, in exec_module
  File "<frozen importlib._bootstrap_external>", line 981, in get_code
  File "<frozen importlib._bootstrap_external>", line 911, in source_to_code
  File "<frozen importlib._bootstrap>", line 219, in _call_with_frames_removed
  File "/home/ramachandra/movies/app1/models.py", line 2
    from django.contrib.auth.
                            ^
SyntaxError: invalid syntax
/home/ramachandra/movies/app1/models.py changed, reloading.
Watching for file changes with StatReloader
Exception in thread django-main-thread:
Traceback (most recent call last):
  File "/usr/lib/python3.8/threading.py", line 932, in _bootstrap_inner
    self.run()
  File "/usr/lib/python3.8/threading.py", line 870, in run
    self._target(*self._args, **self._kwargs)
  File "/home/ramachandra/.local/lib/python3.8/site-packages/django/utils/autoreload.py", line 64, in wrapper
    fn(*args, **kwargs)
  File "/home/ramachandra/.local/lib/python3.8/site-packages/django/core/management/commands/runserver.py", line 125, in inner_run
    autoreload.raise_last_exception()
  File "/home/ramachandra/.local/lib/python3.8/site-packages/django/utils/autoreload.py", line 87, in raise_last_exception
    raise _exception[1]
  File "/home/ramachandra/.local/lib/python3.8/site-packages/django/core/management/__init__.py", line 394, in execute
    autoreload.check_errors(django.setup)()
  File "/home/ramachandra/.local/lib/python3.8/site-packages/django/utils/autoreload.py", line 64, in wrapper
    fn(*args, **kwargs)
  File "/home/ramachandra/.local/lib/python3.8/site-packages/django/__init__.py", line 24, in setup
    apps.populate(settings.INSTALLED_APPS)
  File "/home/ramachandra/.local/lib/python3.8/site-packages/django/apps/registry.py", line 116, in populate
    app_config.import_models()
  File "/home/ramachandra/.local/lib/python3.8/site-packages/django/apps/config.py", line 269, in import_models
    self.models_module = import_module(models_module_name)
  File "/usr/lib/python3.8/importlib/__init__.py", line 127, in import_module
    return _bootstrap._gcd_import(name[level:], package, level)
  File "<frozen importlib._bootstrap>", line 1014, in _gcd_import
  File "<frozen importlib._bootstrap>", line 991, in _find_and_load
  File "<frozen importlib._bootstrap>", line 975, in _find_and_load_unlocked
  File "<frozen importlib._bootstrap>", line 671, in _load_unlocked
  File "<frozen importlib._bootstrap_external>", line 844, in exec_module
  File "<frozen importlib._bootstrap_external>", line 981, in get_code
  File "<frozen importlib._bootstrap_external>", line 911, in source_to_code
  File "<frozen importlib._bootstrap>", line 219, in _call_with_frames_removed
  File "/home/ramachandra/movies/app1/models.py", line 14
    user=models.ForeignKey(User,on_delete=)
                                          ^
SyntaxError: invalid syntax
/home/ramachandra/movies/app1/models.py changed, reloading.
Watching for file changes with StatReloader
Exception in thread django-main-thread:
Traceback (most recent call last):
  File "/usr/lib/python3.8/threading.py", line 932, in _bootstrap_inner
    self.run()
  File "/usr/lib/python3.8/threading.py", line 870, in run
    self._target(*self._args, **self._kwargs)
  File "/home/ramachandra/.local/lib/python3.8/site-packages/django/utils/autoreload.py", line 64, in wrapper
    fn(*args, **kwargs)
  File "/home/ramachandra/.local/lib/python3.8/site-packages/django/core/management/commands/runserver.py", line 125, in inner_run
    autoreload.raise_last_exception()
  File "/home/ramachandra/.local/lib/python3.8/site-packages/django/utils/autoreload.py", line 87, in raise_last_exception
    raise _exception[1]
  File "/home/ramachandra/.local/lib/python3.8/site-packages/django/core/management/__init__.py", line 394, in execute
    autoreload.check_errors(django.setup)()
  File "/home/ramachandra/.local/lib/python3.8/site-packages/django/utils/autoreload.py", line 64, in wrapper
    fn(*args, **kwargs)
  File "/home/ramachandra/.local/lib/python3.8/site-packages/django/__init__.py", line 24, in setup
    apps.populate(settings.INSTALLED_APPS)
  File "/home/ramachandra/.local/lib/python3.8/site-packages/django/apps/registry.py", line 116, in populate
    app_config.import_models()
  File "/home/ramachandra/.local/lib/python3.8/site-packages/django/apps/config.py", line 269, in import_models
    self.models_module = import_module(models_module_name)
  File "/usr/lib/python3.8/importlib/__init__.py", line 127, in import_module
    return _bootstrap._gcd_import(name[level:], package, level)
  File "<frozen importlib._bootstrap>", line 1014, in _gcd_import
  File "<frozen importlib._bootstrap>", line 991, in _find_and_load
  File "<frozen importlib._bootstrap>", line 975, in _find_and_load_unlocked
  File "<frozen importlib._bootstrap>", line 671, in _load_unlocked
  File "<frozen importlib._bootstrap_external>", line 848, in exec_module
  File "<frozen importlib._bootstrap>", line 219, in _call_with_frames_removed
  File "/home/ramachandra/movies/app1/models.py", line 13, in <module>
    class Favorites(models.Model):
  File "/home/ramachandra/movies/app1/models.py", line 14, in Favorites
    user=models.ForeignKey(User,on_delete=Ca)
NameError: name 'Ca' is not defined
/home/ramachandra/movies/app1/models.py changed, reloading.
Watching for file changes with StatReloader
Exception in thread django-main-thread:
Traceback (most recent call last):
  File "/usr/lib/python3.8/threading.py", line 932, in _bootstrap_inner
    self.run()
  File "/usr/lib/python3.8/threading.py", line 870, in run
    self._target(*self._args, **self._kwargs)
  File "/home/ramachandra/.local/lib/python3.8/site-packages/django/utils/autoreload.py", line 64, in wrapper
    fn(*args, **kwargs)
  File "/home/ramachandra/.local/lib/python3.8/site-packages/django/core/management/commands/runserver.py", line 125, in inner_run
    autoreload.raise_last_exception()
  File "/home/ramachandra/.local/lib/python3.8/site-packages/django/utils/autoreload.py", line 87, in raise_last_exception
    raise _exception[1]
  File "/home/ramachandra/.local/lib/python3.8/site-packages/django/core/management/__init__.py", line 394, in execute
    autoreload.check_errors(django.setup)()
  File "/home/ramachandra/.local/lib/python3.8/site-packages/django/utils/autoreload.py", line 64, in wrapper
    fn(*args, **kwargs)
  File "/home/ramachandra/.local/lib/python3.8/site-packages/django/__init__.py", line 24, in setup
    apps.populate(settings.INSTALLED_APPS)
  File "/home/ramachandra/.local/lib/python3.8/site-packages/django/apps/registry.py", line 116, in populate
    app_config.import_models()
  File "/home/ramachandra/.local/lib/python3.8/site-packages/django/apps/config.py", line 269, in import_models
    self.models_module = import_module(models_module_name)
  File "/usr/lib/python3.8/importlib/__init__.py", line 127, in import_module
    return _bootstrap._gcd_import(name[level:], package, level)
  File "<frozen importlib._bootstrap>", line 1014, in _gcd_import
  File "<frozen importlib._bootstrap>", line 991, in _find_and_load
  File "<frozen importlib._bootstrap>", line 975, in _find_and_load_unlocked
  File "<frozen importlib._bootstrap>", line 671, in _load_unlocked
  File "<frozen importlib._bootstrap_external>", line 848, in exec_module
  File "<frozen importlib._bootstrap>", line 219, in _call_with_frames_removed
  File "/home/ramachandra/movies/app1/models.py", line 13, in <module>
    class Favorites(models.Model):
  File "/home/ramachandra/movies/app1/models.py", line 14, in Favorites
    user=models.ForeignKey(User,on_delete=Cas)
NameError: name 'Cas' is not defined
/home/ramachandra/movies/app1/models.py changed, reloading.
Watching for file changes with StatReloader
Exception in thread django-main-thread:
Traceback (most recent call last):
  File "/usr/lib/python3.8/threading.py", line 932, in _bootstrap_inner
    self.run()
  File "/usr/lib/python3.8/threading.py", line 870, in run
    self._target(*self._args, **self._kwargs)
  File "/home/ramachandra/.local/lib/python3.8/site-packages/django/utils/autoreload.py", line 64, in wrapper
    fn(*args, **kwargs)
  File "/home/ramachandra/.local/lib/python3.8/site-packages/django/core/management/commands/runserver.py", line 125, in inner_run
    autoreload.raise_last_exception()
  File "/home/ramachandra/.local/lib/python3.8/site-packages/django/utils/autoreload.py", line 87, in raise_last_exception
    raise _exception[1]
  File "/home/ramachandra/.local/lib/python3.8/site-packages/django/core/management/__init__.py", line 394, in execute
    autoreload.check_errors(django.setup)()
  File "/home/ramachandra/.local/lib/python3.8/site-packages/django/utils/autoreload.py", line 64, in wrapper
    fn(*args, **kwargs)
  File "/home/ramachandra/.local/lib/python3.8/site-packages/django/__init__.py", line 24, in setup
    apps.populate(settings.INSTALLED_APPS)
  File "/home/ramachandra/.local/lib/python3.8/site-packages/django/apps/registry.py", line 116, in populate
    app_config.import_models()
  File "/home/ramachandra/.local/lib/python3.8/site-packages/django/apps/config.py", line 269, in import_models
    self.models_module = import_module(models_module_name)
  File "/usr/lib/python3.8/importlib/__init__.py", line 127, in import_module
    return _bootstrap._gcd_import(name[level:], package, level)
  File "<frozen importlib._bootstrap>", line 1014, in _gcd_import
  File "<frozen importlib._bootstrap>", line 991, in _find_and_load
  File "<frozen importlib._bootstrap>", line 975, in _find_and_load_unlocked
  File "<frozen importlib._bootstrap>", line 671, in _load_unlocked
  File "<frozen importlib._bootstrap_external>", line 848, in exec_module
  File "<frozen importlib._bootstrap>", line 219, in _call_with_frames_removed
  File "/home/ramachandra/movies/app1/models.py", line 13, in <module>
    class Favorites(models.Model):
  File "/home/ramachandra/movies/app1/models.py", line 14, in Favorites
    user=models.ForeignKey(User,on_delete=Cascad)
NameError: name 'Cascad' is not defined
/home/ramachandra/movies/app1/models.py changed, reloading.
Watching for file changes with StatReloader
Exception in thread django-main-thread:
Traceback (most recent call last):
  File "/usr/lib/python3.8/threading.py", line 932, in _bootstrap_inner
    self.run()
  File "/usr/lib/python3.8/threading.py", line 870, in run
    self._target(*self._args, **self._kwargs)
  File "/home/ramachandra/.local/lib/python3.8/site-packages/django/utils/autoreload.py", line 64, in wrapper
    fn(*args, **kwargs)
  File "/home/ramachandra/.local/lib/python3.8/site-packages/django/core/management/commands/runserver.py", line 125, in inner_run
    autoreload.raise_last_exception()
  File "/home/ramachandra/.local/lib/python3.8/site-packages/django/utils/autoreload.py", line 87, in raise_last_exception
    raise _exception[1]
  File "/home/ramachandra/.local/lib/python3.8/site-packages/django/core/management/__init__.py", line 394, in execute
    autoreload.check_errors(django.setup)()
  File "/home/ramachandra/.local/lib/python3.8/site-packages/django/utils/autoreload.py", line 64, in wrapper
    fn(*args, **kwargs)
  File "/home/ramachandra/.local/lib/python3.8/site-packages/django/__init__.py", line 24, in setup
    apps.populate(settings.INSTALLED_APPS)
  File "/home/ramachandra/.local/lib/python3.8/site-packages/django/apps/registry.py", line 116, in populate
    app_config.import_models()
  File "/home/ramachandra/.local/lib/python3.8/site-packages/django/apps/config.py", line 269, in import_models
    self.models_module = import_module(models_module_name)
  File "/usr/lib/python3.8/importlib/__init__.py", line 127, in import_module
    return _bootstrap._gcd_import(name[level:], package, level)
  File "<frozen importlib._bootstrap>", line 1014, in _gcd_import
  File "<frozen importlib._bootstrap>", line 991, in _find_and_load
  File "<frozen importlib._bootstrap>", line 975, in _find_and_load_unlocked
  File "<frozen importlib._bootstrap>", line 671, in _load_unlocked
  File "<frozen importlib._bootstrap_external>", line 844, in exec_module
  File "<frozen importlib._bootstrap_external>", line 981, in get_code
  File "<frozen importlib._bootstrap_external>", line 911, in source_to_code
  File "<frozen importlib._bootstrap>", line 219, in _call_with_frames_removed
  File "/home/ramachandra/movies/app1/models.py", line 14
    user=models.ForeignKey(User,on_delete=)
                                          ^
SyntaxError: invalid syntax
/home/ramachandra/movies/app1/models.py changed, reloading.
Watching for file changes with StatReloader
Exception in thread django-main-thread:
Traceback (most recent call last):
  File "/usr/lib/python3.8/threading.py", line 932, in _bootstrap_inner
    self.run()
  File "/usr/lib/python3.8/threading.py", line 870, in run
    self._target(*self._args, **self._kwargs)
  File "/home/ramachandra/.local/lib/python3.8/site-packages/django/utils/autoreload.py", line 64, in wrapper
    fn(*args, **kwargs)
  File "/home/ramachandra/.local/lib/python3.8/site-packages/django/core/management/commands/runserver.py", line 125, in inner_run
    autoreload.raise_last_exception()
  File "/home/ramachandra/.local/lib/python3.8/site-packages/django/utils/autoreload.py", line 87, in raise_last_exception
    raise _exception[1]
  File "/home/ramachandra/.local/lib/python3.8/site-packages/django/core/management/__init__.py", line 394, in execute
    autoreload.check_errors(django.setup)()
  File "/home/ramachandra/.local/lib/python3.8/site-packages/django/utils/autoreload.py", line 64, in wrapper
    fn(*args, **kwargs)
  File "/home/ramachandra/.local/lib/python3.8/site-packages/django/__init__.py", line 24, in setup
    apps.populate(settings.INSTALLED_APPS)
  File "/home/ramachandra/.local/lib/python3.8/site-packages/django/apps/registry.py", line 116, in populate
    app_config.import_models()
  File "/home/ramachandra/.local/lib/python3.8/site-packages/django/apps/config.py", line 269, in import_models
    self.models_module = import_module(models_module_name)
  File "/usr/lib/python3.8/importlib/__init__.py", line 127, in import_module
    return _bootstrap._gcd_import(name[level:], package, level)
  File "<frozen importlib._bootstrap>", line 1014, in _gcd_import
  File "<frozen importlib._bootstrap>", line 991, in _find_and_load
  File "<frozen importlib._bootstrap>", line 975, in _find_and_load_unlocked
  File "<frozen importlib._bootstrap>", line 671, in _load_unlocked
  File "<frozen importlib._bootstrap_external>", line 844, in exec_module
  File "<frozen importlib._bootstrap_external>", line 981, in get_code
  File "<frozen importlib._bootstrap_external>", line 911, in source_to_code
  File "<frozen importlib._bootstrap>", line 219, in _call_with_frames_removed
  File "/home/ramachandra/movies/app1/models.py", line 14
    user=models.ForeignKey(User,on_delete=models.)
                                                 ^
SyntaxError: invalid syntax
/home/ramachandra/movies/app1/models.py changed, reloading.
Watching for file changes with StatReloader
Exception in thread django-main-thread:
Traceback (most recent call last):
  File "/usr/lib/python3.8/threading.py", line 932, in _bootstrap_inner
    self.run()
  File "/usr/lib/python3.8/threading.py", line 870, in run
    self._target(*self._args, **self._kwargs)
  File "/home/ramachandra/.local/lib/python3.8/site-packages/django/utils/autoreload.py", line 64, in wrapper
    fn(*args, **kwargs)
  File "/home/ramachandra/.local/lib/python3.8/site-packages/django/core/management/commands/runserver.py", line 125, in inner_run
    autoreload.raise_last_exception()
  File "/home/ramachandra/.local/lib/python3.8/site-packages/django/utils/autoreload.py", line 87, in raise_last_exception
    raise _exception[1]
  File "/home/ramachandra/.local/lib/python3.8/site-packages/django/core/management/__init__.py", line 394, in execute
    autoreload.check_errors(django.setup)()
  File "/home/ramachandra/.local/lib/python3.8/site-packages/django/utils/autoreload.py", line 64, in wrapper
    fn(*args, **kwargs)
  File "/home/ramachandra/.local/lib/python3.8/site-packages/django/__init__.py", line 24, in setup
    apps.populate(settings.INSTALLED_APPS)
  File "/home/ramachandra/.local/lib/python3.8/site-packages/django/apps/registry.py", line 116, in populate
    app_config.import_models()
  File "/home/ramachandra/.local/lib/python3.8/site-packages/django/apps/config.py", line 269, in import_models
    self.models_module = import_module(models_module_name)
  File "/usr/lib/python3.8/importlib/__init__.py", line 127, in import_module
    return _bootstrap._gcd_import(name[level:], package, level)
  File "<frozen importlib._bootstrap>", line 1014, in _gcd_import
  File "<frozen importlib._bootstrap>", line 991, in _find_and_load
  File "<frozen importlib._bootstrap>", line 975, in _find_and_load_unlocked
  File "<frozen importlib._bootstrap>", line 671, in _load_unlocked
  File "<frozen importlib._bootstrap_external>", line 848, in exec_module
  File "<frozen importlib._bootstrap>", line 219, in _call_with_frames_removed
  File "/home/ramachandra/movies/app1/models.py", line 13, in <module>
    class Favorites(models.Model):
  File "/home/ramachandra/movies/app1/models.py", line 14, in Favorites
    user=models.ForeignKey(User,on_delete=models.ca)
AttributeError: module 'django.db.models' has no attribute 'ca'
/home/ramachandra/movies/app1/models.py changed, reloading.
Watching for file changes with StatReloader
Exception in thread django-main-thread:
Traceback (most recent call last):
  File "/usr/lib/python3.8/threading.py", line 932, in _bootstrap_inner
    self.run()
  File "/usr/lib/python3.8/threading.py", line 870, in run
    self._target(*self._args, **self._kwargs)
  File "/home/ramachandra/.local/lib/python3.8/site-packages/django/utils/autoreload.py", line 64, in wrapper
    fn(*args, **kwargs)
  File "/home/ramachandra/.local/lib/python3.8/site-packages/django/core/management/commands/runserver.py", line 125, in inner_run
    autoreload.raise_last_exception()
  File "/home/ramachandra/.local/lib/python3.8/site-packages/django/utils/autoreload.py", line 87, in raise_last_exception
    raise _exception[1]
  File "/home/ramachandra/.local/lib/python3.8/site-packages/django/core/management/__init__.py", line 394, in execute
    autoreload.check_errors(django.setup)()
  File "/home/ramachandra/.local/lib/python3.8/site-packages/django/utils/autoreload.py", line 64, in wrapper
    fn(*args, **kwargs)
  File "/home/ramachandra/.local/lib/python3.8/site-packages/django/__init__.py", line 24, in setup
    apps.populate(settings.INSTALLED_APPS)
  File "/home/ramachandra/.local/lib/python3.8/site-packages/django/apps/registry.py", line 116, in populate
    app_config.import_models()
  File "/home/ramachandra/.local/lib/python3.8/site-packages/django/apps/config.py", line 269, in import_models
    self.models_module = import_module(models_module_name)
  File "/usr/lib/python3.8/importlib/__init__.py", line 127, in import_module
    return _bootstrap._gcd_import(name[level:], package, level)
  File "<frozen importlib._bootstrap>", line 1014, in _gcd_import
  File "<frozen importlib._bootstrap>", line 991, in _find_and_load
  File "<frozen importlib._bootstrap>", line 975, in _find_and_load_unlocked
  File "<frozen importlib._bootstrap>", line 671, in _load_unlocked
  File "<frozen importlib._bootstrap_external>", line 848, in exec_module
  File "<frozen importlib._bootstrap>", line 219, in _call_with_frames_removed
  File "/home/ramachandra/movies/app1/models.py", line 13, in <module>
    class Favorites(models.Model):
  File "/home/ramachandra/movies/app1/models.py", line 15, in Favorites
    m
NameError: name 'm' is not defined
/home/ramachandra/movies/app1/models.py changed, reloading.
Watching for file changes with StatReloader
Exception in thread django-main-thread:
Traceback (most recent call last):
  File "/usr/lib/python3.8/threading.py", line 932, in _bootstrap_inner
    self.run()
  File "/usr/lib/python3.8/threading.py", line 870, in run
    self._target(*self._args, **self._kwargs)
  File "/home/ramachandra/.local/lib/python3.8/site-packages/django/utils/autoreload.py", line 64, in wrapper
    fn(*args, **kwargs)
  File "/home/ramachandra/.local/lib/python3.8/site-packages/django/core/management/commands/runserver.py", line 125, in inner_run
    autoreload.raise_last_exception()
  File "/home/ramachandra/.local/lib/python3.8/site-packages/django/utils/autoreload.py", line 87, in raise_last_exception
    raise _exception[1]
  File "/home/ramachandra/.local/lib/python3.8/site-packages/django/core/management/__init__.py", line 394, in execute
    autoreload.check_errors(django.setup)()
  File "/home/ramachandra/.local/lib/python3.8/site-packages/django/utils/autoreload.py", line 64, in wrapper
    fn(*args, **kwargs)
  File "/home/ramachandra/.local/lib/python3.8/site-packages/django/__init__.py", line 24, in setup
    apps.populate(settings.INSTALLED_APPS)
  File "/home/ramachandra/.local/lib/python3.8/site-packages/django/apps/registry.py", line 116, in populate
    app_config.import_models()
  File "/home/ramachandra/.local/lib/python3.8/site-packages/django/apps/config.py", line 269, in import_models
    self.models_module = import_module(models_module_name)
  File "/usr/lib/python3.8/importlib/__init__.py", line 127, in import_module
    return _bootstrap._gcd_import(name[level:], package, level)
  File "<frozen importlib._bootstrap>", line 1014, in _gcd_import
  File "<frozen importlib._bootstrap>", line 991, in _find_and_load
  File "<frozen importlib._bootstrap>", line 975, in _find_and_load_unlocked
  File "<frozen importlib._bootstrap>", line 671, in _load_unlocked
  File "<frozen importlib._bootstrap_external>", line 848, in exec_module
  File "<frozen importlib._bootstrap>", line 219, in _call_with_frames_removed
  File "/home/ramachandra/movies/app1/models.py", line 13, in <module>
    class Favorites(models.Model):
  File "/home/ramachandra/movies/app1/models.py", line 15, in Favorites
    mo
NameError: name 'mo' is not defined
/home/ramachandra/movies/app1/models.py changed, reloading.
Watching for file changes with StatReloader
Exception in thread django-main-thread:
Traceback (most recent call last):
  File "/usr/lib/python3.8/threading.py", line 932, in _bootstrap_inner
    self.run()
  File "/usr/lib/python3.8/threading.py", line 870, in run
    self._target(*self._args, **self._kwargs)
  File "/home/ramachandra/.local/lib/python3.8/site-packages/django/utils/autoreload.py", line 64, in wrapper
    fn(*args, **kwargs)
  File "/home/ramachandra/.local/lib/python3.8/site-packages/django/core/management/commands/runserver.py", line 125, in inner_run
    autoreload.raise_last_exception()
  File "/home/ramachandra/.local/lib/python3.8/site-packages/django/utils/autoreload.py", line 87, in raise_last_exception
    raise _exception[1]
  File "/home/ramachandra/.local/lib/python3.8/site-packages/django/core/management/__init__.py", line 394, in execute
    autoreload.check_errors(django.setup)()
  File "/home/ramachandra/.local/lib/python3.8/site-packages/django/utils/autoreload.py", line 64, in wrapper
    fn(*args, **kwargs)
  File "/home/ramachandra/.local/lib/python3.8/site-packages/django/__init__.py", line 24, in setup
    apps.populate(settings.INSTALLED_APPS)
  File "/home/ramachandra/.local/lib/python3.8/site-packages/django/apps/registry.py", line 116, in populate
    app_config.import_models()
  File "/home/ramachandra/.local/lib/python3.8/site-packages/django/apps/config.py", line 269, in import_models
    self.models_module = import_module(models_module_name)
  File "/usr/lib/python3.8/importlib/__init__.py", line 127, in import_module
    return _bootstrap._gcd_import(name[level:], package, level)
  File "<frozen importlib._bootstrap>", line 1014, in _gcd_import
  File "<frozen importlib._bootstrap>", line 991, in _find_and_load
  File "<frozen importlib._bootstrap>", line 975, in _find_and_load_unlocked
  File "<frozen importlib._bootstrap>", line 671, in _load_unlocked
  File "<frozen importlib._bootstrap_external>", line 848, in exec_module
  File "<frozen importlib._bootstrap>", line 219, in _call_with_frames_removed
  File "/home/ramachandra/movies/app1/models.py", line 13, in <module>
    class Favorites(models.Model):
  File "/home/ramachandra/movies/app1/models.py", line 15, in Favorites
    movie
NameError: name 'movie' is not defined
/home/ramachandra/movies/app1/models.py changed, reloading.
Watching for file changes with StatReloader
Exception in thread django-main-thread:
Traceback (most recent call last):
  File "/usr/lib/python3.8/threading.py", line 932, in _bootstrap_inner
    self.run()
  File "/usr/lib/python3.8/threading.py", line 870, in run
    self._target(*self._args, **self._kwargs)
  File "/home/ramachandra/.local/lib/python3.8/site-packages/django/utils/autoreload.py", line 64, in wrapper
    fn(*args, **kwargs)
  File "/home/ramachandra/.local/lib/python3.8/site-packages/django/core/management/commands/runserver.py", line 125, in inner_run
    autoreload.raise_last_exception()
  File "/home/ramachandra/.local/lib/python3.8/site-packages/django/utils/autoreload.py", line 87, in raise_last_exception
    raise _exception[1]
  File "/home/ramachandra/.local/lib/python3.8/site-packages/django/core/management/__init__.py", line 394, in execute
    autoreload.check_errors(django.setup)()
  File "/home/ramachandra/.local/lib/python3.8/site-packages/django/utils/autoreload.py", line 64, in wrapper
    fn(*args, **kwargs)
  File "/home/ramachandra/.local/lib/python3.8/site-packages/django/__init__.py", line 24, in setup
    apps.populate(settings.INSTALLED_APPS)
  File "/home/ramachandra/.local/lib/python3.8/site-packages/django/apps/registry.py", line 116, in populate
    app_config.import_models()
  File "/home/ramachandra/.local/lib/python3.8/site-packages/django/apps/config.py", line 269, in import_models
    self.models_module = import_module(models_module_name)
  File "/usr/lib/python3.8/importlib/__init__.py", line 127, in import_module
    return _bootstrap._gcd_import(name[level:], package, level)
  File "<frozen importlib._bootstrap>", line 1014, in _gcd_import
  File "<frozen importlib._bootstrap>", line 991, in _find_and_load
  File "<frozen importlib._bootstrap>", line 975, in _find_and_load_unlocked
  File "<frozen importlib._bootstrap>", line 671, in _load_unlocked
  File "<frozen importlib._bootstrap_external>", line 844, in exec_module
  File "<frozen importlib._bootstrap_external>", line 981, in get_code
  File "<frozen importlib._bootstrap_external>", line 911, in source_to_code
  File "<frozen importlib._bootstrap>", line 219, in _call_with_frames_removed
  File "/home/ramachandra/movies/app1/models.py", line 15
    movie=models.
                ^
SyntaxError: invalid syntax
/home/ramachandra/movies/app1/models.py changed, reloading.
Watching for file changes with StatReloader
Performing system checks...

System check identified no issues (0 silenced).
May 24, 2024 - 01:13:49
Django version 4.2.13, using settings 'movies.settings'
Starting development server at http://0.0.0.0:3000/
Quit the server with CONTROL-C.

/home/ramachandra/movies/app1/models.py changed, reloading.
Watching for file changes with StatReloader
Exception in thread django-main-thread:
Traceback (most recent call last):
  File "/usr/lib/python3.8/threading.py", line 932, in _bootstrap_inner
    self.run()
  File "/usr/lib/python3.8/threading.py", line 870, in run
    self._target(*self._args, **self._kwargs)
  File "/home/ramachandra/.local/lib/python3.8/site-packages/django/utils/autoreload.py", line 64, in wrapper
    fn(*args, **kwargs)
  File "/home/ramachandra/.local/lib/python3.8/site-packages/django/core/management/commands/runserver.py", line 125, in inner_run
    autoreload.raise_last_exception()
  File "/home/ramachandra/.local/lib/python3.8/site-packages/django/utils/autoreload.py", line 87, in raise_last_exception
    raise _exception[1]
  File "/home/ramachandra/.local/lib/python3.8/site-packages/django/core/management/__init__.py", line 394, in execute
    autoreload.check_errors(django.setup)()
  File "/home/ramachandra/.local/lib/python3.8/site-packages/django/utils/autoreload.py", line 64, in wrapper
    fn(*args, **kwargs)
  File "/home/ramachandra/.local/lib/python3.8/site-packages/django/__init__.py", line 24, in setup
    apps.populate(settings.INSTALLED_APPS)
  File "/home/ramachandra/.local/lib/python3.8/site-packages/django/apps/registry.py", line 116, in populate
    app_config.import_models()
  File "/home/ramachandra/.local/lib/python3.8/site-packages/django/apps/config.py", line 269, in import_models
    self.models_module = import_module(models_module_name)
  File "/usr/lib/python3.8/importlib/__init__.py", line 127, in import_module
    return _bootstrap._gcd_import(name[level:], package, level)
  File "<frozen importlib._bootstrap>", line 1014, in _gcd_import
  File "<frozen importlib._bootstrap>", line 991, in _find_and_load
  File "<frozen importlib._bootstrap>", line 975, in _find_and_load_unlocked
  File "<frozen importlib._bootstrap>", line 671, in _load_unlocked
  File "<frozen importlib._bootstrap_external>", line 848, in exec_module
  File "<frozen importlib._bootstrap>", line 219, in _call_with_frames_removed
  File "/home/ramachandra/movies/app1/models.py", line 13, in <module>
    class Favorites(models.Model):
  File "/home/ramachandra/movies/app1/models.py", line 15, in Favorites
    movie=models.ForeignKey(U)
NameError: name 'U' is not defined
/home/ramachandra/movies/app1/models.py changed, reloading.
Watching for file changes with StatReloader
Exception in thread django-main-thread:
Traceback (most recent call last):
  File "/usr/lib/python3.8/threading.py", line 932, in _bootstrap_inner
    self.run()
  File "/usr/lib/python3.8/threading.py", line 870, in run
    self._target(*self._args, **self._kwargs)
  File "/home/ramachandra/.local/lib/python3.8/site-packages/django/utils/autoreload.py", line 64, in wrapper
    fn(*args, **kwargs)
  File "/home/ramachandra/.local/lib/python3.8/site-packages/django/core/management/commands/runserver.py", line 125, in inner_run
    autoreload.raise_last_exception()
  File "/home/ramachandra/.local/lib/python3.8/site-packages/django/utils/autoreload.py", line 87, in raise_last_exception
    raise _exception[1]
  File "/home/ramachandra/.local/lib/python3.8/site-packages/django/core/management/__init__.py", line 394, in execute
    autoreload.check_errors(django.setup)()
  File "/home/ramachandra/.local/lib/python3.8/site-packages/django/utils/autoreload.py", line 64, in wrapper
    fn(*args, **kwargs)
  File "/home/ramachandra/.local/lib/python3.8/site-packages/django/__init__.py", line 24, in setup
    apps.populate(settings.INSTALLED_APPS)
  File "/home/ramachandra/.local/lib/python3.8/site-packages/django/apps/registry.py", line 116, in populate
    app_config.import_models()
  File "/home/ramachandra/.local/lib/python3.8/site-packages/django/apps/config.py", line 269, in import_models
    self.models_module = import_module(models_module_name)
  File "/usr/lib/python3.8/importlib/__init__.py", line 127, in import_module
    return _bootstrap._gcd_import(name[level:], package, level)
  File "<frozen importlib._bootstrap>", line 1014, in _gcd_import
  File "<frozen importlib._bootstrap>", line 991, in _find_and_load
  File "<frozen importlib._bootstrap>", line 975, in _find_and_load_unlocked
  File "<frozen importlib._bootstrap>", line 671, in _load_unlocked
  File "<frozen importlib._bootstrap_external>", line 848, in exec_module
  File "<frozen importlib._bootstrap>", line 219, in _call_with_frames_removed
  File "/home/ramachandra/movies/app1/models.py", line 13, in <module>
    class Favorites(models.Model):
  File "/home/ramachandra/movies/app1/models.py", line 15, in Favorites
    movie=models.ForeignKey(Mo)
NameError: name 'Mo' is not defined
/home/ramachandra/movies/app1/models.py changed, reloading.
Watching for file changes with StatReloader
Exception in thread django-main-thread:
Traceback (most recent call last):
  File "/usr/lib/python3.8/threading.py", line 932, in _bootstrap_inner
    self.run()
  File "/usr/lib/python3.8/threading.py", line 870, in run
    self._target(*self._args, **self._kwargs)
  File "/home/ramachandra/.local/lib/python3.8/site-packages/django/utils/autoreload.py", line 64, in wrapper
    fn(*args, **kwargs)
  File "/home/ramachandra/.local/lib/python3.8/site-packages/django/core/management/commands/runserver.py", line 125, in inner_run
    autoreload.raise_last_exception()
  File "/home/ramachandra/.local/lib/python3.8/site-packages/django/utils/autoreload.py", line 87, in raise_last_exception
    raise _exception[1]
  File "/home/ramachandra/.local/lib/python3.8/site-packages/django/core/management/__init__.py", line 394, in execute
    autoreload.check_errors(django.setup)()
  File "/home/ramachandra/.local/lib/python3.8/site-packages/django/utils/autoreload.py", line 64, in wrapper
    fn(*args, **kwargs)
  File "/home/ramachandra/.local/lib/python3.8/site-packages/django/__init__.py", line 24, in setup
    apps.populate(settings.INSTALLED_APPS)
  File "/home/ramachandra/.local/lib/python3.8/site-packages/django/apps/registry.py", line 116, in populate
    app_config.import_models()
  File "/home/ramachandra/.local/lib/python3.8/site-packages/django/apps/config.py", line 269, in import_models
    self.models_module = import_module(models_module_name)
  File "/usr/lib/python3.8/importlib/__init__.py", line 127, in import_module
    return _bootstrap._gcd_import(name[level:], package, level)
  File "<frozen importlib._bootstrap>", line 1014, in _gcd_import
  File "<frozen importlib._bootstrap>", line 991, in _find_and_load
  File "<frozen importlib._bootstrap>", line 975, in _find_and_load_unlocked
  File "<frozen importlib._bootstrap>", line 671, in _load_unlocked
  File "<frozen importlib._bootstrap_external>", line 848, in exec_module
  File "<frozen importlib._bootstrap>", line 219, in _call_with_frames_removed
  File "/home/ramachandra/movies/app1/models.py", line 13, in <module>
    class Favorites(models.Model):
  File "/home/ramachandra/movies/app1/models.py", line 15, in Favorites
    movie=models.ForeignKey(Movies)
TypeError: __init__() missing 1 required positional argument: 'on_delete'
/home/ramachandra/movies/app1/models.py changed, reloading.
Watching for file changes with StatReloader
Exception in thread django-main-thread:
Traceback (most recent call last):
  File "/usr/lib/python3.8/threading.py", line 932, in _bootstrap_inner
    self.run()
  File "/usr/lib/python3.8/threading.py", line 870, in run
    self._target(*self._args, **self._kwargs)
  File "/home/ramachandra/.local/lib/python3.8/site-packages/django/utils/autoreload.py", line 64, in wrapper
    fn(*args, **kwargs)
  File "/home/ramachandra/.local/lib/python3.8/site-packages/django/core/management/commands/runserver.py", line 125, in inner_run
    autoreload.raise_last_exception()
  File "/home/ramachandra/.local/lib/python3.8/site-packages/django/utils/autoreload.py", line 87, in raise_last_exception
    raise _exception[1]
  File "/home/ramachandra/.local/lib/python3.8/site-packages/django/core/management/__init__.py", line 394, in execute
    autoreload.check_errors(django.setup)()
  File "/home/ramachandra/.local/lib/python3.8/site-packages/django/utils/autoreload.py", line 64, in wrapper
    fn(*args, **kwargs)
  File "/home/ramachandra/.local/lib/python3.8/site-packages/django/__init__.py", line 24, in setup
    apps.populate(settings.INSTALLED_APPS)
  File "/home/ramachandra/.local/lib/python3.8/site-packages/django/apps/registry.py", line 116, in populate
    app_config.import_models()
  File "/home/ramachandra/.local/lib/python3.8/site-packages/django/apps/config.py", line 269, in import_models
    self.models_module = import_module(models_module_name)
  File "/usr/lib/python3.8/importlib/__init__.py", line 127, in import_module
    return _bootstrap._gcd_import(name[level:], package, level)
  File "<frozen importlib._bootstrap>", line 1014, in _gcd_import
  File "<frozen importlib._bootstrap>", line 991, in _find_and_load
  File "<frozen importlib._bootstrap>", line 975, in _find_and_load_unlocked
  File "<frozen importlib._bootstrap>", line 671, in _load_unlocked
  File "<frozen importlib._bootstrap_external>", line 848, in exec_module
  File "<frozen importlib._bootstrap>", line 219, in _call_with_frames_removed
  File "/home/ramachandra/movies/app1/models.py", line 13, in <module>
    class Favorites(models.Model):
  File "/home/ramachandra/movies/app1/models.py", line 15, in Favorites
    movie=models.ForeignKey(Movies,)
TypeError: __init__() missing 1 required positional argument: 'on_delete'
/home/ramachandra/movies/app1/models.py changed, reloading.
Watching for file changes with StatReloader
Exception in thread django-main-thread:
Traceback (most recent call last):
  File "/usr/lib/python3.8/threading.py", line 932, in _bootstrap_inner
    self.run()
  File "/usr/lib/python3.8/threading.py", line 870, in run
    self._target(*self._args, **self._kwargs)
  File "/home/ramachandra/.local/lib/python3.8/site-packages/django/utils/autoreload.py", line 64, in wrapper
    fn(*args, **kwargs)
  File "/home/ramachandra/.local/lib/python3.8/site-packages/django/core/management/commands/runserver.py", line 125, in inner_run
    autoreload.raise_last_exception()
  File "/home/ramachandra/.local/lib/python3.8/site-packages/django/utils/autoreload.py", line 87, in raise_last_exception
    raise _exception[1]
  File "/home/ramachandra/.local/lib/python3.8/site-packages/django/core/management/__init__.py", line 394, in execute
    autoreload.check_errors(django.setup)()
  File "/home/ramachandra/.local/lib/python3.8/site-packages/django/utils/autoreload.py", line 64, in wrapper
    fn(*args, **kwargs)
  File "/home/ramachandra/.local/lib/python3.8/site-packages/django/__init__.py", line 24, in setup
    apps.populate(settings.INSTALLED_APPS)
  File "/home/ramachandra/.local/lib/python3.8/site-packages/django/apps/registry.py", line 116, in populate
    app_config.import_models()
  File "/home/ramachandra/.local/lib/python3.8/site-packages/django/apps/config.py", line 269, in import_models
    self.models_module = import_module(models_module_name)
  File "/usr/lib/python3.8/importlib/__init__.py", line 127, in import_module
    return _bootstrap._gcd_import(name[level:], package, level)
  File "<frozen importlib._bootstrap>", line 1014, in _gcd_import
  File "<frozen importlib._bootstrap>", line 991, in _find_and_load
  File "<frozen importlib._bootstrap>", line 975, in _find_and_load_unlocked
  File "<frozen importlib._bootstrap>", line 671, in _load_unlocked
  File "<frozen importlib._bootstrap_external>", line 848, in exec_module
  File "<frozen importlib._bootstrap>", line 219, in _call_with_frames_removed
  File "/home/ramachandra/movies/app1/models.py", line 13, in <module>
    class Favorites(models.Model):
  File "/home/ramachandra/movies/app1/models.py", line 15, in Favorites
    movie=models.ForeignKey(Movies,on)
NameError: name 'on' is not defined
/home/ramachandra/movies/app1/models.py changed, reloading.
Watching for file changes with StatReloader
Exception in thread django-main-thread:
Traceback (most recent call last):
  File "/usr/lib/python3.8/threading.py", line 932, in _bootstrap_inner
    self.run()
  File "/usr/lib/python3.8/threading.py", line 870, in run
    self._target(*self._args, **self._kwargs)
  File "/home/ramachandra/.local/lib/python3.8/site-packages/django/utils/autoreload.py", line 64, in wrapper
    fn(*args, **kwargs)
  File "/home/ramachandra/.local/lib/python3.8/site-packages/django/core/management/commands/runserver.py", line 125, in inner_run
    autoreload.raise_last_exception()
  File "/home/ramachandra/.local/lib/python3.8/site-packages/django/utils/autoreload.py", line 87, in raise_last_exception
    raise _exception[1]
  File "/home/ramachandra/.local/lib/python3.8/site-packages/django/core/management/__init__.py", line 394, in execute
    autoreload.check_errors(django.setup)()
  File "/home/ramachandra/.local/lib/python3.8/site-packages/django/utils/autoreload.py", line 64, in wrapper
    fn(*args, **kwargs)
  File "/home/ramachandra/.local/lib/python3.8/site-packages/django/__init__.py", line 24, in setup
    apps.populate(settings.INSTALLED_APPS)
  File "/home/ramachandra/.local/lib/python3.8/site-packages/django/apps/registry.py", line 116, in populate
    app_config.import_models()
  File "/home/ramachandra/.local/lib/python3.8/site-packages/django/apps/config.py", line 269, in import_models
    self.models_module = import_module(models_module_name)
  File "/usr/lib/python3.8/importlib/__init__.py", line 127, in import_module
    return _bootstrap._gcd_import(name[level:], package, level)
  File "<frozen importlib._bootstrap>", line 1014, in _gcd_import
  File "<frozen importlib._bootstrap>", line 991, in _find_and_load
  File "<frozen importlib._bootstrap>", line 975, in _find_and_load_unlocked
  File "<frozen importlib._bootstrap>", line 671, in _load_unlocked
  File "<frozen importlib._bootstrap_external>", line 844, in exec_module
  File "<frozen importlib._bootstrap_external>", line 981, in get_code
  File "<frozen importlib._bootstrap_external>", line 911, in source_to_code
  File "<frozen importlib._bootstrap>", line 219, in _call_with_frames_removed
  File "/home/ramachandra/movies/app1/models.py", line 15
    movie=models.ForeignKey(Movies,on_delete=)
                                             ^
SyntaxError: invalid syntax
/home/ramachandra/movies/app1/models.py changed, reloading.
Watching for file changes with StatReloader
Performing system checks...

System check identified no issues (0 silenced).
May 24, 2024 - 01:14:11
Django version 4.2.13, using settings 'movies.settings'
Starting development server at http://0.0.0.0:3000/
Quit the server with CONTROL-C.

/home/ramachandra/movies/app1/models.py changed, reloading.
Watching for file changes with StatReloader
Performing system checks...

System check identified no issues (0 silenced).
May 24, 2024 - 01:14:15
Django version 4.2.13, using settings 'movies.settings'
Starting development server at http://0.0.0.0:3000/
Quit the server with CONTROL-C.

/home/ramachandra/movies/app1/models.py changed, reloading.
Watching for file changes with StatReloader
Performing system checks...

System check identified no issues (0 silenced).
May 24, 2024 - 01:14:22
Django version 4.2.13, using settings 'movies.settings'
Starting development server at http://0.0.0.0:3000/
Quit the server with CONTROL-C.

[24/May/2024 01:15:15] "GET /app1/profile HTTP/1.1" 200 4838
/home/ramachandra/movies/app1/models.py changed, reloading.
Watching for file changes with StatReloader
Performing system checks...

System check identified no issues (0 silenced).
May 24, 2024 - 01:19:24
Django version 4.2.13, using settings 'movies.settings'
Starting development server at http://0.0.0.0:3000/
Quit the server with CONTROL-C.

/home/ramachandra/movies/app1/views.py changed, reloading.
Watching for file changes with StatReloader
Performing system checks...

System check identified no issues (0 silenced).
May 24, 2024 - 01:20:03
Django version 4.2.13, using settings 'movies.settings'
Starting development server at http://0.0.0.0:3000/
Quit the server with CONTROL-C.

/home/ramachandra/movies/app1/views.py changed, reloading.
Watching for file changes with StatReloader
Performing system checks...

System check identified no issues (0 silenced).
May 24, 2024 - 01:20:13
Django version 4.2.13, using settings 'movies.settings'
Starting development server at http://0.0.0.0:3000/
Quit the server with CONTROL-C.

/home/ramachandra/movies/app1/views.py changed, reloading.
Watching for file changes with StatReloader
Performing system checks...

System check identified no issues (0 silenced).
May 24, 2024 - 01:20:18
Django version 4.2.13, using settings 'movies.settings'
Starting development server at http://0.0.0.0:3000/
Quit the server with CONTROL-C.

[24/May/2024 01:25:04] "GET /app1/profile HTTP/1.1" 200 4838
[24/May/2024 01:25:07] "GET /app1/profile HTTP/1.1" 200 4838
[24/May/2024 01:25:12] "GET /app1/home HTTP/1.1" 200 131316
Not Found: /add/
[24/May/2024 01:25:16] "POST /add/ HTTP/1.1" 404 2199
Not Found: /add/
[24/May/2024 01:25:26] "POST /add/ HTTP/1.1" 404 2199
/home/ramachandra/movies/app1/views.py changed, reloading.
Watching for file changes with StatReloader
Performing system checks...

System check identified no issues (0 silenced).
May 24, 2024 - 01:26:51
Django version 4.2.13, using settings 'movies.settings'
Starting development server at http://0.0.0.0:3000/
Quit the server with CONTROL-C.

/home/ramachandra/movies/app1/views.py changed, reloading.
Watching for file changes with StatReloader
Performing system checks...

System check identified no issues (0 silenced).
May 24, 2024 - 01:26:55
Django version 4.2.13, using settings 'movies.settings'
Starting development server at http://0.0.0.0:3000/
Quit the server with CONTROL-C.

[24/May/2024 01:26:57] "GET /app1/home HTTP/1.1" 200 125646
Not Found: /add/
[24/May/2024 01:27:01] "POST /add/ HTTP/1.1" 404 2199
/home/ramachandra/movies/app1/urls.py changed, reloading.
Watching for file changes with StatReloader
Performing system checks...

System check identified no issues (0 silenced).
May 24, 2024 - 01:28:04
Django version 4.2.13, using settings 'movies.settings'
Starting development server at http://0.0.0.0:3000/
Quit the server with CONTROL-C.

[24/May/2024 01:28:49] "GET /app1/home HTTP/1.1" 200 131250
Not Found: /add/2573/
[24/May/2024 01:28:53] "POST /add/2573/ HTTP/1.1" 404 2214
Not Found: /add/2573/
[24/May/2024 01:28:57] "POST /add/2573/ HTTP/1.1" 404 2214
[24/May/2024 01:29:27] "GET /app1/home HTTP/1.1" 200 126952
Internal Server Error: /app1/add/169/
Traceback (most recent call last):
  File "/home/ramachandra/.local/lib/python3.8/site-packages/django/core/handlers/exception.py", line 55, in inner
    response = get_response(request)
  File "/home/ramachandra/.local/lib/python3.8/site-packages/django/core/handlers/base.py", line 197, in _get_response
    response = wrapped_callback(request, *callback_args, **callback_kwargs)
  File "/home/ramachandra/movies/app1/views.py", line 108, in add
    return redirect('favorites_list')  # Redirect to favorites list page
  File "/home/ramachandra/.local/lib/python3.8/site-packages/django/shortcuts.py", line 48, in redirect
    return redirect_class(resolve_url(to, *args, **kwargs))
  File "/home/ramachandra/.local/lib/python3.8/site-packages/django/shortcuts.py", line 145, in resolve_url
    return reverse(to, args=args, kwargs=kwargs)
  File "/home/ramachandra/.local/lib/python3.8/site-packages/django/urls/base.py", line 88, in reverse
    return resolver._reverse_with_prefix(view, prefix, *args, **kwargs)
  File "/home/ramachandra/.local/lib/python3.8/site-packages/django/urls/resolvers.py", line 828, in _reverse_with_prefix
    raise NoReverseMatch(msg)
django.urls.exceptions.NoReverseMatch: Reverse for 'favorites_list' not found. 'favorites_list' is not a valid view function or pattern name.
[24/May/2024 01:29:31] "POST /app1/add/169/ HTTP/1.1" 500 80944
/home/ramachandra/movies/app1/views.py changed, reloading.
Watching for file changes with StatReloader
Performing system checks...

System check identified no issues (0 silenced).
May 24, 2024 - 01:30:17
Django version 4.2.13, using settings 'movies.settings'
Starting development server at http://0.0.0.0:3000/
Quit the server with CONTROL-C.

/home/ramachandra/movies/app1/views.py changed, reloading.
Watching for file changes with StatReloader
Performing system checks...

System check identified no issues (0 silenced).
May 24, 2024 - 01:30:27
Django version 4.2.13, using settings 'movies.settings'
Starting development server at http://0.0.0.0:3000/
Quit the server with CONTROL-C.

/home/ramachandra/movies/app1/views.py changed, reloading.
Watching for file changes with StatReloader
Performing system checks...

System check identified no issues (0 silenced).
May 24, 2024 - 01:30:32
Django version 4.2.13, using settings 'movies.settings'
Starting development server at http://0.0.0.0:3000/
Quit the server with CONTROL-C.

[24/May/2024 01:30:33] "GET /app1/home HTTP/1.1" 200 126005
Internal Server Error: /app1/add/3375/
Traceback (most recent call last):
  File "/home/ramachandra/.local/lib/python3.8/site-packages/django/core/handlers/exception.py", line 55, in inner
    response = get_response(request)
  File "/home/ramachandra/.local/lib/python3.8/site-packages/django/utils/deprecation.py", line 136, in __call__
    response = self.process_response(request, response)
  File "/home/ramachandra/.local/lib/python3.8/site-packages/django/middleware/clickjacking.py", line 27, in process_response
    if response.get("X-Frame-Options") is not None:
AttributeError: 'bool' object has no attribute 'get'
[24/May/2024 01:30:38] "POST /app1/add/3375/ HTTP/1.1" 500 61385
/home/ramachandra/movies/app1/views.py changed, reloading.
Watching for file changes with StatReloader
Performing system checks...

System check identified no issues (0 silenced).
May 24, 2024 - 01:31:16
Django version 4.2.13, using settings 'movies.settings'
Starting development server at http://0.0.0.0:3000/
Quit the server with CONTROL-C.

/home/ramachandra/movies/app1/views.py changed, reloading.
Watching for file changes with StatReloader
Performing system checks...

System check identified no issues (0 silenced).
May 24, 2024 - 01:31:21
Django version 4.2.13, using settings 'movies.settings'
Starting development server at http://0.0.0.0:3000/
Quit the server with CONTROL-C.

/home/ramachandra/movies/app1/views.py changed, reloading.
Watching for file changes with StatReloader
Performing system checks...

Exception in thread django-main-thread:
Traceback (most recent call last):
  File "/usr/lib/python3.8/threading.py", line 932, in _bootstrap_inner
    self.run()
  File "/usr/lib/python3.8/threading.py", line 870, in run
    self._target(*self._args, **self._kwargs)
  File "/home/ramachandra/.local/lib/python3.8/site-packages/django/utils/autoreload.py", line 64, in wrapper
    fn(*args, **kwargs)
  File "/home/ramachandra/.local/lib/python3.8/site-packages/django/core/management/commands/runserver.py", line 133, in inner_run
    self.check(display_num_errors=True)
  File "/home/ramachandra/.local/lib/python3.8/site-packages/django/core/management/base.py", line 485, in check
    all_issues = checks.run_checks(
  File "/home/ramachandra/.local/lib/python3.8/site-packages/django/core/checks/registry.py", line 88, in run_checks
    new_errors = check(app_configs=app_configs, databases=databases)
  File "/home/ramachandra/.local/lib/python3.8/site-packages/django/core/checks/urls.py", line 14, in check_url_config
    return check_resolver(resolver)
  File "/home/ramachandra/.local/lib/python3.8/site-packages/django/core/checks/urls.py", line 24, in check_resolver
    return check_method()
  File "/home/ramachandra/.local/lib/python3.8/site-packages/django/urls/resolvers.py", line 494, in check
    for pattern in self.url_patterns:
  File "/home/ramachandra/.local/lib/python3.8/site-packages/django/utils/functional.py", line 57, in __get__
    res = instance.__dict__[self.name] = self.func(instance)
  File "/home/ramachandra/.local/lib/python3.8/site-packages/django/urls/resolvers.py", line 715, in url_patterns
    patterns = getattr(self.urlconf_module, "urlpatterns", self.urlconf_module)
  File "/home/ramachandra/.local/lib/python3.8/site-packages/django/utils/functional.py", line 57, in __get__
    res = instance.__dict__[self.name] = self.func(instance)
  File "/home/ramachandra/.local/lib/python3.8/site-packages/django/urls/resolvers.py", line 708, in urlconf_module
    return import_module(self.urlconf_name)
  File "/usr/lib/python3.8/importlib/__init__.py", line 127, in import_module
    return _bootstrap._gcd_import(name[level:], package, level)
  File "<frozen importlib._bootstrap>", line 1014, in _gcd_import
  File "<frozen importlib._bootstrap>", line 991, in _find_and_load
  File "<frozen importlib._bootstrap>", line 975, in _find_and_load_unlocked
  File "<frozen importlib._bootstrap>", line 671, in _load_unlocked
  File "<frozen importlib._bootstrap_external>", line 848, in exec_module
  File "<frozen importlib._bootstrap>", line 219, in _call_with_frames_removed
  File "/home/ramachandra/movies/movies/urls.py", line 21, in <module>
    path('app1/',include('app1.urls')),
  File "/home/ramachandra/.local/lib/python3.8/site-packages/django/urls/conf.py", line 38, in include
    urlconf_module = import_module(urlconf_module)
  File "/usr/lib/python3.8/importlib/__init__.py", line 127, in import_module
    return _bootstrap._gcd_import(name[level:], package, level)
  File "<frozen importlib._bootstrap>", line 1014, in _gcd_import
  File "<frozen importlib._bootstrap>", line 991, in _find_and_load
  File "<frozen importlib._bootstrap>", line 975, in _find_and_load_unlocked
  File "<frozen importlib._bootstrap>", line 671, in _load_unlocked
  File "<frozen importlib._bootstrap_external>", line 848, in exec_module
  File "<frozen importlib._bootstrap>", line 219, in _call_with_frames_removed
  File "/home/ramachandra/movies/app1/urls.py", line 3, in <module>
    from .views import upload_file,search_movies,land,login_view,logout_view,home,movie_detail,profile,add,search
  File "/home/ramachandra/movies/app1/views.py", line 108
    return JsonResponse(list[])
                             ^
SyntaxError: invalid syntax
/home/ramachandra/movies/app1/views.py changed, reloading.
Watching for file changes with StatReloader
Performing system checks...

System check identified no issues (0 silenced).
May 24, 2024 - 01:31:27
Django version 4.2.13, using settings 'movies.settings'
Starting development server at http://0.0.0.0:3000/
Quit the server with CONTROL-C.

/home/ramachandra/movies/app1/views.py changed, reloading.
Watching for file changes with StatReloader
Performing system checks...

System check identified no issues (0 silenced).
May 24, 2024 - 01:31:30
Django version 4.2.13, using settings 'movies.settings'
Starting development server at http://0.0.0.0:3000/
Quit the server with CONTROL-C.

/home/ramachandra/movies/app1/views.py changed, reloading.
Watching for file changes with StatReloader
Performing system checks...

Exception in thread django-main-thread:
Traceback (most recent call last):
  File "/usr/lib/python3.8/threading.py", line 932, in _bootstrap_inner
    self.run()
  File "/usr/lib/python3.8/threading.py", line 870, in run
    self._target(*self._args, **self._kwargs)
  File "/home/ramachandra/.local/lib/python3.8/site-packages/django/utils/autoreload.py", line 64, in wrapper
    fn(*args, **kwargs)
  File "/home/ramachandra/.local/lib/python3.8/site-packages/django/core/management/commands/runserver.py", line 133, in inner_run
    self.check(display_num_errors=True)
  File "/home/ramachandra/.local/lib/python3.8/site-packages/django/core/management/base.py", line 485, in check
    all_issues = checks.run_checks(
  File "/home/ramachandra/.local/lib/python3.8/site-packages/django/core/checks/registry.py", line 88, in run_checks
    new_errors = check(app_configs=app_configs, databases=databases)
  File "/home/ramachandra/.local/lib/python3.8/site-packages/django/core/checks/urls.py", line 14, in check_url_config
    return check_resolver(resolver)
  File "/home/ramachandra/.local/lib/python3.8/site-packages/django/core/checks/urls.py", line 24, in check_resolver
    return check_method()
  File "/home/ramachandra/.local/lib/python3.8/site-packages/django/urls/resolvers.py", line 494, in check
    for pattern in self.url_patterns:
  File "/home/ramachandra/.local/lib/python3.8/site-packages/django/utils/functional.py", line 57, in __get__
    res = instance.__dict__[self.name] = self.func(instance)
  File "/home/ramachandra/.local/lib/python3.8/site-packages/django/urls/resolvers.py", line 715, in url_patterns
    patterns = getattr(self.urlconf_module, "urlpatterns", self.urlconf_module)
  File "/home/ramachandra/.local/lib/python3.8/site-packages/django/utils/functional.py", line 57, in __get__
    res = instance.__dict__[self.name] = self.func(instance)
  File "/home/ramachandra/.local/lib/python3.8/site-packages/django/urls/resolvers.py", line 708, in urlconf_module
    return import_module(self.urlconf_name)
  File "/usr/lib/python3.8/importlib/__init__.py", line 127, in import_module
    return _bootstrap._gcd_import(name[level:], package, level)
  File "<frozen importlib._bootstrap>", line 1014, in _gcd_import
  File "<frozen importlib._bootstrap>", line 991, in _find_and_load
  File "<frozen importlib._bootstrap>", line 975, in _find_and_load_unlocked
  File "<frozen importlib._bootstrap>", line 671, in _load_unlocked
  File "<frozen importlib._bootstrap_external>", line 848, in exec_module
  File "<frozen importlib._bootstrap>", line 219, in _call_with_frames_removed
  File "/home/ramachandra/movies/movies/urls.py", line 21, in <module>
    path('app1/',include('app1.urls')),
  File "/home/ramachandra/.local/lib/python3.8/site-packages/django/urls/conf.py", line 38, in include
    urlconf_module = import_module(urlconf_module)
  File "/usr/lib/python3.8/importlib/__init__.py", line 127, in import_module
    return _bootstrap._gcd_import(name[level:], package, level)
  File "<frozen importlib._bootstrap>", line 1014, in _gcd_import
  File "<frozen importlib._bootstrap>", line 991, in _find_and_load
  File "<frozen importlib._bootstrap>", line 975, in _find_and_load_unlocked
  File "<frozen importlib._bootstrap>", line 671, in _load_unlocked
  File "<frozen importlib._bootstrap_external>", line 848, in exec_module
  File "<frozen importlib._bootstrap>", line 219, in _call_with_frames_removed
  File "/home/ramachandra/movies/app1/urls.py", line 3, in <module>
    from .views import upload_file,search_movies,land,login_view,logout_view,home,movie_detail,profile,add,search
  File "/home/ramachandra/movies/app1/views.py", line 108
    return JsonResponse(list({data:}))
                                   ^
SyntaxError: invalid syntax
/home/ramachandra/movies/app1/views.py changed, reloading.
Watching for file changes with StatReloader
Performing system checks...

System check identified no issues (0 silenced).
May 24, 2024 - 01:31:35
Django version 4.2.13, using settings 'movies.settings'
Starting development server at http://0.0.0.0:3000/
Quit the server with CONTROL-C.

/home/ramachandra/movies/app1/views.py changed, reloading.
Watching for file changes with StatReloader
Performing system checks...

System check identified no issues (0 silenced).
May 24, 2024 - 01:31:40
Django version 4.2.13, using settings 'movies.settings'
Starting development server at http://0.0.0.0:3000/
Quit the server with CONTROL-C.

/home/ramachandra/movies/app1/views.py changed, reloading.
Watching for file changes with StatReloader
Performing system checks...

System check identified no issues (0 silenced).
May 24, 2024 - 01:31:50
Django version 4.2.13, using settings 'movies.settings'
Starting development server at http://0.0.0.0:3000/
Quit the server with CONTROL-C.

/home/ramachandra/movies/app1/views.py changed, reloading.
Watching for file changes with StatReloader
Performing system checks...

System check identified no issues (0 silenced).
May 24, 2024 - 01:31:53
Django version 4.2.13, using settings 'movies.settings'
Starting development server at http://0.0.0.0:3000/
Quit the server with CONTROL-C.

[24/May/2024 01:32:00] "GET /app1/home HTTP/1.1" 200 126873
Internal Server Error: /app1/add/2864/
Traceback (most recent call last):
  File "/home/ramachandra/.local/lib/python3.8/site-packages/django/core/handlers/exception.py", line 55, in inner
    response = get_response(request)
  File "/home/ramachandra/.local/lib/python3.8/site-packages/django/core/handlers/base.py", line 197, in _get_response
    response = wrapped_callback(request, *callback_args, **callback_kwargs)
  File "/home/ramachandra/movies/app1/views.py", line 108, in add
    return JsonResponse(list({"status":True}))
  File "/home/ramachandra/.local/lib/python3.8/site-packages/django/http/response.py", line 724, in __init__
    raise TypeError(
TypeError: In order to allow non-dict objects to be serialized set the safe parameter to False.
[24/May/2024 01:32:03] "POST /app1/add/2864/ HTTP/1.1" 500 67319
/home/ramachandra/movies/app1/views.py changed, reloading.
Watching for file changes with StatReloader
Performing system checks...

System check identified no issues (0 silenced).
May 24, 2024 - 01:32:31
Django version 4.2.13, using settings 'movies.settings'
Starting development server at http://0.0.0.0:3000/
Quit the server with CONTROL-C.

/home/ramachandra/movies/app1/views.py changed, reloading.
Watching for file changes with StatReloader
Performing system checks...

Exception in thread django-main-thread:
Traceback (most recent call last):
  File "/usr/lib/python3.8/threading.py", line 932, in _bootstrap_inner
    self.run()
  File "/usr/lib/python3.8/threading.py", line 870, in run
    self._target(*self._args, **self._kwargs)
  File "/home/ramachandra/.local/lib/python3.8/site-packages/django/utils/autoreload.py", line 64, in wrapper
    fn(*args, **kwargs)
  File "/home/ramachandra/.local/lib/python3.8/site-packages/django/core/management/commands/runserver.py", line 133, in inner_run
    self.check(display_num_errors=True)
  File "/home/ramachandra/.local/lib/python3.8/site-packages/django/core/management/base.py", line 485, in check
    all_issues = checks.run_checks(
  File "/home/ramachandra/.local/lib/python3.8/site-packages/django/core/checks/registry.py", line 88, in run_checks
    new_errors = check(app_configs=app_configs, databases=databases)
  File "/home/ramachandra/.local/lib/python3.8/site-packages/django/core/checks/urls.py", line 14, in check_url_config
    return check_resolver(resolver)
  File "/home/ramachandra/.local/lib/python3.8/site-packages/django/core/checks/urls.py", line 24, in check_resolver
    return check_method()
  File "/home/ramachandra/.local/lib/python3.8/site-packages/django/urls/resolvers.py", line 494, in check
    for pattern in self.url_patterns:
  File "/home/ramachandra/.local/lib/python3.8/site-packages/django/utils/functional.py", line 57, in __get__
    res = instance.__dict__[self.name] = self.func(instance)
  File "/home/ramachandra/.local/lib/python3.8/site-packages/django/urls/resolvers.py", line 715, in url_patterns
    patterns = getattr(self.urlconf_module, "urlpatterns", self.urlconf_module)
  File "/home/ramachandra/.local/lib/python3.8/site-packages/django/utils/functional.py", line 57, in __get__
    res = instance.__dict__[self.name] = self.func(instance)
  File "/home/ramachandra/.local/lib/python3.8/site-packages/django/urls/resolvers.py", line 708, in urlconf_module
    return import_module(self.urlconf_name)
  File "/usr/lib/python3.8/importlib/__init__.py", line 127, in import_module
    return _bootstrap._gcd_import(name[level:], package, level)
  File "<frozen importlib._bootstrap>", line 1014, in _gcd_import
  File "<frozen importlib._bootstrap>", line 991, in _find_and_load
  File "<frozen importlib._bootstrap>", line 975, in _find_and_load_unlocked
  File "<frozen importlib._bootstrap>", line 671, in _load_unlocked
  File "<frozen importlib._bootstrap_external>", line 848, in exec_module
  File "<frozen importlib._bootstrap>", line 219, in _call_with_frames_removed
  File "/home/ramachandra/movies/movies/urls.py", line 21, in <module>
    path('app1/',include('app1.urls')),
  File "/home/ramachandra/.local/lib/python3.8/site-packages/django/urls/conf.py", line 38, in include
    urlconf_module = import_module(urlconf_module)
  File "/usr/lib/python3.8/importlib/__init__.py", line 127, in import_module
    return _bootstrap._gcd_import(name[level:], package, level)
  File "<frozen importlib._bootstrap>", line 1014, in _gcd_import
  File "<frozen importlib._bootstrap>", line 991, in _find_and_load
  File "<frozen importlib._bootstrap>", line 975, in _find_and_load_unlocked
  File "<frozen importlib._bootstrap>", line 671, in _load_unlocked
  File "<frozen importlib._bootstrap_external>", line 848, in exec_module
  File "<frozen importlib._bootstrap>", line 219, in _call_with_frames_removed
  File "/home/ramachandra/movies/app1/urls.py", line 3, in <module>
    from .views import upload_file,search_movies,land,login_view,logout_view,home,movie_detail,profile,add,search
  File "/home/ramachandra/movies/app1/views.py", line 111
    return JsonResponse(list({"status":False}),safe=)
                                                    ^
SyntaxError: invalid syntax
/home/ramachandra/movies/app1/views.py changed, reloading.
Watching for file changes with StatReloader
Performing system checks...

System check identified no issues (0 silenced).
May 24, 2024 - 01:32:37
Django version 4.2.13, using settings 'movies.settings'
Starting development server at http://0.0.0.0:3000/
Quit the server with CONTROL-C.

[24/May/2024 01:32:39] "GET /app1/home HTTP/1.1" 200 126798
[24/May/2024 01:32:42] "GET /app1/movie_detail/1616/ HTTP/1.1" 200 4401
Internal Server Error: /app1/add/1616/
Traceback (most recent call last):
  File "/home/ramachandra/.local/lib/python3.8/site-packages/django/core/handlers/exception.py", line 55, in inner
    response = get_response(request)
  File "/home/ramachandra/.local/lib/python3.8/site-packages/django/core/handlers/base.py", line 197, in _get_response
    response = wrapped_callback(request, *callback_args, **callback_kwargs)
  File "/home/ramachandra/movies/app1/views.py", line 108, in add
    return JsonResponse(list({"status":True}))
  File "/home/ramachandra/.local/lib/python3.8/site-packages/django/http/response.py", line 724, in __init__
    raise TypeError(
TypeError: In order to allow non-dict objects to be serialized set the safe parameter to False.
[24/May/2024 01:32:48] "POST /app1/add/1616/ HTTP/1.1" 500 67309
/home/ramachandra/movies/app1/views.py changed, reloading.
Watching for file changes with StatReloader
Performing system checks...

Exception in thread django-main-thread:
Traceback (most recent call last):
  File "/usr/lib/python3.8/threading.py", line 932, in _bootstrap_inner
    self.run()
  File "/usr/lib/python3.8/threading.py", line 870, in run
    self._target(*self._args, **self._kwargs)
  File "/home/ramachandra/.local/lib/python3.8/site-packages/django/utils/autoreload.py", line 64, in wrapper
    fn(*args, **kwargs)
  File "/home/ramachandra/.local/lib/python3.8/site-packages/django/core/management/commands/runserver.py", line 133, in inner_run
    self.check(display_num_errors=True)
  File "/home/ramachandra/.local/lib/python3.8/site-packages/django/core/management/base.py", line 485, in check
    all_issues = checks.run_checks(
  File "/home/ramachandra/.local/lib/python3.8/site-packages/django/core/checks/registry.py", line 88, in run_checks
    new_errors = check(app_configs=app_configs, databases=databases)
  File "/home/ramachandra/.local/lib/python3.8/site-packages/django/core/checks/urls.py", line 14, in check_url_config
    return check_resolver(resolver)
  File "/home/ramachandra/.local/lib/python3.8/site-packages/django/core/checks/urls.py", line 24, in check_resolver
    return check_method()
  File "/home/ramachandra/.local/lib/python3.8/site-packages/django/urls/resolvers.py", line 494, in check
    for pattern in self.url_patterns:
  File "/home/ramachandra/.local/lib/python3.8/site-packages/django/utils/functional.py", line 57, in __get__
    res = instance.__dict__[self.name] = self.func(instance)
  File "/home/ramachandra/.local/lib/python3.8/site-packages/django/urls/resolvers.py", line 715, in url_patterns
    patterns = getattr(self.urlconf_module, "urlpatterns", self.urlconf_module)
  File "/home/ramachandra/.local/lib/python3.8/site-packages/django/utils/functional.py", line 57, in __get__
    res = instance.__dict__[self.name] = self.func(instance)
  File "/home/ramachandra/.local/lib/python3.8/site-packages/django/urls/resolvers.py", line 708, in urlconf_module
    return import_module(self.urlconf_name)
  File "/usr/lib/python3.8/importlib/__init__.py", line 127, in import_module
    return _bootstrap._gcd_import(name[level:], package, level)
  File "<frozen importlib._bootstrap>", line 1014, in _gcd_import
  File "<frozen importlib._bootstrap>", line 991, in _find_and_load
  File "<frozen importlib._bootstrap>", line 975, in _find_and_load_unlocked
  File "<frozen importlib._bootstrap>", line 671, in _load_unlocked
  File "<frozen importlib._bootstrap_external>", line 848, in exec_module
  File "<frozen importlib._bootstrap>", line 219, in _call_with_frames_removed
  File "/home/ramachandra/movies/movies/urls.py", line 21, in <module>
    path('app1/',include('app1.urls')),
  File "/home/ramachandra/.local/lib/python3.8/site-packages/django/urls/conf.py", line 38, in include
    urlconf_module = import_module(urlconf_module)
  File "/usr/lib/python3.8/importlib/__init__.py", line 127, in import_module
    return _bootstrap._gcd_import(name[level:], package, level)
  File "<frozen importlib._bootstrap>", line 1014, in _gcd_import
  File "<frozen importlib._bootstrap>", line 991, in _find_and_load
  File "<frozen importlib._bootstrap>", line 975, in _find_and_load_unlocked
  File "<frozen importlib._bootstrap>", line 671, in _load_unlocked
  File "<frozen importlib._bootstrap_external>", line 848, in exec_module
  File "<frozen importlib._bootstrap>", line 219, in _call_with_frames_removed
  File "/home/ramachandra/movies/app1/urls.py", line 3, in <module>
    from .views import upload_file,search_movies,land,login_view,logout_view,home,movie_detail,profile,add,search
  File "/home/ramachandra/movies/app1/views.py", line 111
    return JsonResponse({"status":False}),safe=False)
                                              ^
SyntaxError: invalid syntax
/home/ramachandra/movies/app1/views.py changed, reloading.
Watching for file changes with StatReloader
Performing system checks...

System check identified no issues (0 silenced).
May 24, 2024 - 01:33:13
Django version 4.2.13, using settings 'movies.settings'
Starting development server at http://0.0.0.0:3000/
Quit the server with CONTROL-C.

/home/ramachandra/movies/app1/views.py changed, reloading.
Watching for file changes with StatReloader
Performing system checks...

Exception in thread django-main-thread:
Traceback (most recent call last):
  File "/usr/lib/python3.8/threading.py", line 932, in _bootstrap_inner
    self.run()
  File "/usr/lib/python3.8/threading.py", line 870, in run
    self._target(*self._args, **self._kwargs)
  File "/home/ramachandra/.local/lib/python3.8/site-packages/django/utils/autoreload.py", line 64, in wrapper
    fn(*args, **kwargs)
  File "/home/ramachandra/.local/lib/python3.8/site-packages/django/core/management/commands/runserver.py", line 133, in inner_run
    self.check(display_num_errors=True)
  File "/home/ramachandra/.local/lib/python3.8/site-packages/django/core/management/base.py", line 485, in check
    all_issues = checks.run_checks(
  File "/home/ramachandra/.local/lib/python3.8/site-packages/django/core/checks/registry.py", line 88, in run_checks
    new_errors = check(app_configs=app_configs, databases=databases)
  File "/home/ramachandra/.local/lib/python3.8/site-packages/django/core/checks/urls.py", line 14, in check_url_config
    return check_resolver(resolver)
  File "/home/ramachandra/.local/lib/python3.8/site-packages/django/core/checks/urls.py", line 24, in check_resolver
    return check_method()
  File "/home/ramachandra/.local/lib/python3.8/site-packages/django/urls/resolvers.py", line 494, in check
    for pattern in self.url_patterns:
  File "/home/ramachandra/.local/lib/python3.8/site-packages/django/utils/functional.py", line 57, in __get__
    res = instance.__dict__[self.name] = self.func(instance)
  File "/home/ramachandra/.local/lib/python3.8/site-packages/django/urls/resolvers.py", line 715, in url_patterns
    patterns = getattr(self.urlconf_module, "urlpatterns", self.urlconf_module)
  File "/home/ramachandra/.local/lib/python3.8/site-packages/django/utils/functional.py", line 57, in __get__
    res = instance.__dict__[self.name] = self.func(instance)
  File "/home/ramachandra/.local/lib/python3.8/site-packages/django/urls/resolvers.py", line 708, in urlconf_module
    return import_module(self.urlconf_name)
  File "/usr/lib/python3.8/importlib/__init__.py", line 127, in import_module
    return _bootstrap._gcd_import(name[level:], package, level)
  File "<frozen importlib._bootstrap>", line 1014, in _gcd_import
  File "<frozen importlib._bootstrap>", line 991, in _find_and_load
  File "<frozen importlib._bootstrap>", line 975, in _find_and_load_unlocked
  File "<frozen importlib._bootstrap>", line 671, in _load_unlocked
  File "<frozen importlib._bootstrap_external>", line 848, in exec_module
  File "<frozen importlib._bootstrap>", line 219, in _call_with_frames_removed
  File "/home/ramachandra/movies/movies/urls.py", line 21, in <module>
    path('app1/',include('app1.urls')),
  File "/home/ramachandra/.local/lib/python3.8/site-packages/django/urls/conf.py", line 38, in include
    urlconf_module = import_module(urlconf_module)
  File "/usr/lib/python3.8/importlib/__init__.py", line 127, in import_module
    return _bootstrap._gcd_import(name[level:], package, level)
  File "<frozen importlib._bootstrap>", line 1014, in _gcd_import
  File "<frozen importlib._bootstrap>", line 991, in _find_and_load
  File "<frozen importlib._bootstrap>", line 975, in _find_and_load_unlocked
  File "<frozen importlib._bootstrap>", line 671, in _load_unlocked
  File "<frozen importlib._bootstrap_external>", line 848, in exec_module
  File "<frozen importlib._bootstrap>", line 219, in _call_with_frames_removed
  File "/home/ramachandra/movies/app1/urls.py", line 3, in <module>
    from .views import upload_file,search_movies,land,login_view,logout_view,home,movie_detail,profile,add,search
  File "/home/ramachandra/movies/app1/views.py", line 108
    return JsonResponse(list({"status":True}),safe=)
                                                   ^
SyntaxError: invalid syntax
/home/ramachandra/movies/app1/views.py changed, reloading.
Watching for file changes with StatReloader
Performing system checks...

System check identified no issues (0 silenced).
May 24, 2024 - 01:33:25
Django version 4.2.13, using settings 'movies.settings'
Starting development server at http://0.0.0.0:3000/
Quit the server with CONTROL-C.

/home/ramachandra/movies/app1/views.py changed, reloading.
Watching for file changes with StatReloader
Performing system checks...

System check identified no issues (0 silenced).
May 24, 2024 - 01:33:53
Django version 4.2.13, using settings 'movies.settings'
Starting development server at http://0.0.0.0:3000/
Quit the server with CONTROL-C.

/home/ramachandra/movies/app1/views.py changed, reloading.
Watching for file changes with StatReloader
Performing system checks...

System check identified no issues (0 silenced).
May 24, 2024 - 01:34:01
Django version 4.2.13, using settings 'movies.settings'
Starting development server at http://0.0.0.0:3000/
Quit the server with CONTROL-C.

/home/ramachandra/movies/app1/views.py changed, reloading.
Watching for file changes with StatReloader
Performing system checks...

System check identified no issues (0 silenced).
May 24, 2024 - 01:34:03
Django version 4.2.13, using settings 'movies.settings'
Starting development server at http://0.0.0.0:3000/
Quit the server with CONTROL-C.

[24/May/2024 01:34:06] "GET /app1/home HTTP/1.1" 200 130121
[24/May/2024 01:34:08] "GET /app1/movie_detail/5458/ HTTP/1.1" 200 4582
[24/May/2024 01:34:10] "POST /app1/add/5458/ HTTP/1.1" 200 16
[24/May/2024 01:35:07] "GET /app1/movie_detail/5458/ HTTP/1.1" 200 4582
[24/May/2024 01:35:12] "GET /app1/movie_detail/5458/ HTTP/1.1" 200 4582
[24/May/2024 01:35:15] "GET /app1/home HTTP/1.1" 200 128832
[24/May/2024 01:35:19] "POST /app1/add/5625/ HTTP/1.1" 200 16
[24/May/2024 01:35:25] "POST /app1/add/5625/ HTTP/1.1" 200 17
[24/May/2024 01:35:31] "POST /app1/add/5625/ HTTP/1.1" 200 17
[24/May/2024 01:35:36] "GET /app1/movie_detail/8852/ HTTP/1.1" 200 4407
[24/May/2024 01:35:40] "POST /app1/add/8852/ HTTP/1.1" 200 16
[24/May/2024 01:35:49] "GET /app1/movie_detail/6737/ HTTP/1.1" 200 4546
[24/May/2024 01:35:53] "POST /app1/add/6737/ HTTP/1.1" 200 16
[24/May/2024 01:36:48] "GET /app1/home HTTP/1.1" 200 127481
[24/May/2024 01:37:07] "GET /app1/home HTTP/1.1" 200 125100
[24/May/2024 01:37:11] "POST /app1/add/4200/ HTTP/1.1" 200 16
[24/May/2024 01:37:32] "POST /app1/add/4200/ HTTP/1.1" 200 17
[24/May/2024 01:37:51] "GET /app1/home HTTP/1.1" 200 124901
[24/May/2024 01:37:54] "POST /app1/add/9164/ HTTP/1.1" 200 16
[24/May/2024 01:37:59] "POST /app1/add/9164/ HTTP/1.1" 200 17
[24/May/2024 01:38:03] "POST /app1/add/9164/ HTTP/1.1" 200 17
[24/May/2024 01:38:08] "POST /app1/add/1602/ HTTP/1.1" 200 16
[24/May/2024 01:38:16] "POST /app1/add/6078/ HTTP/1.1" 200 16
[24/May/2024 01:38:21] "POST /app1/add/6078/ HTTP/1.1" 200 17
[24/May/2024 01:38:35] "GET /app1/profile HTTP/1.1" 200 4838
/home/ramachandra/movies/app1/views.py changed, reloading.
Watching for file changes with StatReloader
Performing system checks...

System check identified no issues (0 silenced).
May 24, 2024 - 01:39:05
Django version 4.2.13, using settings 'movies.settings'
Starting development server at http://0.0.0.0:3000/
Quit the server with CONTROL-C.

/home/ramachandra/movies/app1/views.py changed, reloading.
Watching for file changes with StatReloader
Performing system checks...

System check identified no issues (0 silenced).
May 24, 2024 - 01:39:10
Django version 4.2.13, using settings 'movies.settings'
Starting development server at http://0.0.0.0:3000/
Quit the server with CONTROL-C.

/home/ramachandra/movies/app1/views.py changed, reloading.
Watching for file changes with StatReloader
Performing system checks...

System check identified no issues (0 silenced).
May 24, 2024 - 01:39:18
Django version 4.2.13, using settings 'movies.settings'
Starting development server at http://0.0.0.0:3000/
Quit the server with CONTROL-C.

/home/ramachandra/movies/app1/views.py changed, reloading.
Watching for file changes with StatReloader
Performing system checks...

Exception in thread django-main-thread:
Traceback (most recent call last):
  File "/usr/lib/python3.8/threading.py", line 932, in _bootstrap_inner
    self.run()
  File "/usr/lib/python3.8/threading.py", line 870, in run
    self._target(*self._args, **self._kwargs)
  File "/home/ramachandra/.local/lib/python3.8/site-packages/django/utils/autoreload.py", line 64, in wrapper
    fn(*args, **kwargs)
  File "/home/ramachandra/.local/lib/python3.8/site-packages/django/core/management/commands/runserver.py", line 133, in inner_run
    self.check(display_num_errors=True)
  File "/home/ramachandra/.local/lib/python3.8/site-packages/django/core/management/base.py", line 485, in check
    all_issues = checks.run_checks(
  File "/home/ramachandra/.local/lib/python3.8/site-packages/django/core/checks/registry.py", line 88, in run_checks
    new_errors = check(app_configs=app_configs, databases=databases)
  File "/home/ramachandra/.local/lib/python3.8/site-packages/django/core/checks/urls.py", line 14, in check_url_config
    return check_resolver(resolver)
  File "/home/ramachandra/.local/lib/python3.8/site-packages/django/core/checks/urls.py", line 24, in check_resolver
    return check_method()
  File "/home/ramachandra/.local/lib/python3.8/site-packages/django/urls/resolvers.py", line 494, in check
    for pattern in self.url_patterns:
  File "/home/ramachandra/.local/lib/python3.8/site-packages/django/utils/functional.py", line 57, in __get__
    res = instance.__dict__[self.name] = self.func(instance)
  File "/home/ramachandra/.local/lib/python3.8/site-packages/django/urls/resolvers.py", line 715, in url_patterns
    patterns = getattr(self.urlconf_module, "urlpatterns", self.urlconf_module)
  File "/home/ramachandra/.local/lib/python3.8/site-packages/django/utils/functional.py", line 57, in __get__
    res = instance.__dict__[self.name] = self.func(instance)
  File "/home/ramachandra/.local/lib/python3.8/site-packages/django/urls/resolvers.py", line 708, in urlconf_module
    return import_module(self.urlconf_name)
  File "/usr/lib/python3.8/importlib/__init__.py", line 127, in import_module
    return _bootstrap._gcd_import(name[level:], package, level)
  File "<frozen importlib._bootstrap>", line 1014, in _gcd_import
  File "<frozen importlib._bootstrap>", line 991, in _find_and_load
  File "<frozen importlib._bootstrap>", line 975, in _find_and_load_unlocked
  File "<frozen importlib._bootstrap>", line 671, in _load_unlocked
  File "<frozen importlib._bootstrap_external>", line 848, in exec_module
  File "<frozen importlib._bootstrap>", line 219, in _call_with_frames_removed
  File "/home/ramachandra/movies/movies/urls.py", line 21, in <module>
    path('app1/',include('app1.urls')),
  File "/home/ramachandra/.local/lib/python3.8/site-packages/django/urls/conf.py", line 38, in include
    urlconf_module = import_module(urlconf_module)
  File "/usr/lib/python3.8/importlib/__init__.py", line 127, in import_module
    return _bootstrap._gcd_import(name[level:], package, level)
  File "<frozen importlib._bootstrap>", line 1014, in _gcd_import
  File "<frozen importlib._bootstrap>", line 991, in _find_and_load
  File "<frozen importlib._bootstrap>", line 975, in _find_and_load_unlocked
  File "<frozen importlib._bootstrap>", line 671, in _load_unlocked
  File "<frozen importlib._bootstrap_external>", line 848, in exec_module
  File "<frozen importlib._bootstrap>", line 219, in _call_with_frames_removed
  File "/home/ramachandra/movies/app1/urls.py", line 3, in <module>
    from .views import upload_file,search_movies,land,login_view,logout_view,home,movie_detail,profile,add,search
  File "/home/ramachandra/movies/app1/views.py", line 78
    Favorites=Favorites.objects.
                               ^
SyntaxError: invalid syntax
/home/ramachandra/movies/app1/views.py changed, reloading.
Watching for file changes with StatReloader
Performing system checks...

System check identified no issues (0 silenced).
May 24, 2024 - 01:39:22
Django version 4.2.13, using settings 'movies.settings'
Starting development server at http://0.0.0.0:3000/
Quit the server with CONTROL-C.

/home/ramachandra/movies/app1/views.py changed, reloading.
Watching for file changes with StatReloader
Performing system checks...

System check identified no issues (0 silenced).
May 24, 2024 - 01:39:26
Django version 4.2.13, using settings 'movies.settings'
Starting development server at http://0.0.0.0:3000/
Quit the server with CONTROL-C.

/home/ramachandra/movies/app1/views.py changed, reloading.
Watching for file changes with StatReloader
Performing system checks...

System check identified no issues (0 silenced).
May 24, 2024 - 01:39:32
Django version 4.2.13, using settings 'movies.settings'
Starting development server at http://0.0.0.0:3000/
Quit the server with CONTROL-C.

/home/ramachandra/movies/app1/views.py changed, reloading.
Watching for file changes with StatReloader
Performing system checks...

System check identified no issues (0 silenced).
May 24, 2024 - 01:39:36
Django version 4.2.13, using settings 'movies.settings'
Starting development server at http://0.0.0.0:3000/
Quit the server with CONTROL-C.

/home/ramachandra/movies/app1/views.py changed, reloading.
Watching for file changes with StatReloader
Performing system checks...

System check identified no issues (0 silenced).
May 24, 2024 - 01:39:41
Django version 4.2.13, using settings 'movies.settings'
Starting development server at http://0.0.0.0:3000/
Quit the server with CONTROL-C.

/home/ramachandra/movies/app1/views.py changed, reloading.
Watching for file changes with StatReloader
Performing system checks...

System check identified no issues (0 silenced).
May 24, 2024 - 01:39:49
Django version 4.2.13, using settings 'movies.settings'
Starting development server at http://0.0.0.0:3000/
Quit the server with CONTROL-C.

/home/ramachandra/movies/app1/views.py changed, reloading.
Watching for file changes with StatReloader
Performing system checks...

Exception in thread django-main-thread:
Traceback (most recent call last):
  File "/usr/lib/python3.8/threading.py", line 932, in _bootstrap_inner
    self.run()
  File "/usr/lib/python3.8/threading.py", line 870, in run
    self._target(*self._args, **self._kwargs)
  File "/home/ramachandra/.local/lib/python3.8/site-packages/django/utils/autoreload.py", line 64, in wrapper
    fn(*args, **kwargs)
  File "/home/ramachandra/.local/lib/python3.8/site-packages/django/core/management/commands/runserver.py", line 133, in inner_run
    self.check(display_num_errors=True)
  File "/home/ramachandra/.local/lib/python3.8/site-packages/django/core/management/base.py", line 485, in check
    all_issues = checks.run_checks(
  File "/home/ramachandra/.local/lib/python3.8/site-packages/django/core/checks/registry.py", line 88, in run_checks
    new_errors = check(app_configs=app_configs, databases=databases)
  File "/home/ramachandra/.local/lib/python3.8/site-packages/django/core/checks/urls.py", line 14, in check_url_config
    return check_resolver(resolver)
  File "/home/ramachandra/.local/lib/python3.8/site-packages/django/core/checks/urls.py", line 24, in check_resolver
    return check_method()
  File "/home/ramachandra/.local/lib/python3.8/site-packages/django/urls/resolvers.py", line 494, in check
    for pattern in self.url_patterns:
  File "/home/ramachandra/.local/lib/python3.8/site-packages/django/utils/functional.py", line 57, in __get__
    res = instance.__dict__[self.name] = self.func(instance)
  File "/home/ramachandra/.local/lib/python3.8/site-packages/django/urls/resolvers.py", line 715, in url_patterns
    patterns = getattr(self.urlconf_module, "urlpatterns", self.urlconf_module)
  File "/home/ramachandra/.local/lib/python3.8/site-packages/django/utils/functional.py", line 57, in __get__
    res = instance.__dict__[self.name] = self.func(instance)
  File "/home/ramachandra/.local/lib/python3.8/site-packages/django/urls/resolvers.py", line 708, in urlconf_module
    return import_module(self.urlconf_name)
  File "/usr/lib/python3.8/importlib/__init__.py", line 127, in import_module
    return _bootstrap._gcd_import(name[level:], package, level)
  File "<frozen importlib._bootstrap>", line 1014, in _gcd_import
  File "<frozen importlib._bootstrap>", line 991, in _find_and_load
  File "<frozen importlib._bootstrap>", line 975, in _find_and_load_unlocked
  File "<frozen importlib._bootstrap>", line 671, in _load_unlocked
  File "<frozen importlib._bootstrap_external>", line 848, in exec_module
  File "<frozen importlib._bootstrap>", line 219, in _call_with_frames_removed
  File "/home/ramachandra/movies/movies/urls.py", line 21, in <module>
    path('app1/',include('app1.urls')),
  File "/home/ramachandra/.local/lib/python3.8/site-packages/django/urls/conf.py", line 38, in include
    urlconf_module = import_module(urlconf_module)
  File "/usr/lib/python3.8/importlib/__init__.py", line 127, in import_module
    return _bootstrap._gcd_import(name[level:], package, level)
  File "<frozen importlib._bootstrap>", line 1014, in _gcd_import
  File "<frozen importlib._bootstrap>", line 991, in _find_and_load
  File "<frozen importlib._bootstrap>", line 975, in _find_and_load_unlocked
  File "<frozen importlib._bootstrap>", line 671, in _load_unlocked
  File "<frozen importlib._bootstrap_external>", line 848, in exec_module
  File "<frozen importlib._bootstrap>", line 219, in _call_with_frames_removed
  File "/home/ramachandra/movies/app1/urls.py", line 3, in <module>
    from .views import upload_file,search_movies,land,login_view,logout_view,home,movie_detail,profile,add,search
  File "/home/ramachandra/movies/app1/views.py", line 79
    return render(request,"app1/profile.html",{"user":user,"fav"})
                                                                ^
SyntaxError: invalid syntax
/home/ramachandra/movies/app1/views.py changed, reloading.
Watching for file changes with StatReloader
Performing system checks...

System check identified no issues (0 silenced).
May 24, 2024 - 01:39:55
Django version 4.2.13, using settings 'movies.settings'
Starting development server at http://0.0.0.0:3000/
Quit the server with CONTROL-C.

[24/May/2024 01:41:46] "GET /app1/profile HTTP/1.1" 200 6527
/home/ramachandra/movies/app1/views.py changed, reloading.
Watching for file changes with StatReloader
Performing system checks...

System check identified no issues (0 silenced).
May 24, 2024 - 01:42:18
Django version 4.2.13, using settings 'movies.settings'
Starting development server at http://0.0.0.0:3000/
Quit the server with CONTROL-C.

/home/ramachandra/movies/app1/views.py changed, reloading.
Watching for file changes with StatReloader
Performing system checks...

System check identified no issues (0 silenced).
May 24, 2024 - 01:42:21
Django version 4.2.13, using settings 'movies.settings'
Starting development server at http://0.0.0.0:3000/
Quit the server with CONTROL-C.

/home/ramachandra/movies/app1/views.py changed, reloading.
Watching for file changes with StatReloader
Performing system checks...

System check identified no issues (0 silenced).
May 24, 2024 - 01:42:24
Django version 4.2.13, using settings 'movies.settings'
Starting development server at http://0.0.0.0:3000/
Quit the server with CONTROL-C.

[24/May/2024 01:44:45] "GET /app1/profile HTTP/1.1" 200 6795
[24/May/2024 01:45:02] "GET /app1/profile HTTP/1.1" 200 6930
[24/May/2024 01:45:21] "GET /app1/profile HTTP/1.1" 200 6930
[24/May/2024 01:45:39] "GET /app1/profile HTTP/1.1" 200 6860
[24/May/2024 01:46:22] "GET /app1/profile HTTP/1.1" 200 7217
Not Found: /
[24/May/2024 01:46:23] "GET / HTTP/1.1" 404 2168
Not Found: /favicon.ico
[24/May/2024 01:46:37] "GET /favicon.ico HTTP/1.1" 404 2219
[24/May/2024 01:46:45] "GET /app1/profile HTTP/1.1" 200 6913
[24/May/2024 01:49:00] "GET /app1/profile HTTP/1.1" 200 6929
[24/May/2024 01:49:26] "GET /app1/profile HTTP/1.1" 200 6929
[24/May/2024 01:50:38] "GET /app1/ HTTP/1.1" 200 21942
Not Found: /favicon.ico
[24/May/2024 01:50:40] "GET /favicon.ico HTTP/1.1" 404 2219
[24/May/2024 01:50:42] "GET /app1/home HTTP/1.1" 200 128937
[24/May/2024 01:50:47] "GET /app1/profile HTTP/1.1" 200 6929
[24/May/2024 01:51:57] "GET /app1/profile HTTP/1.1" 200 11361
[24/May/2024 01:52:33] "GET /app1/profile HTTP/1.1" 200 11452
[24/May/2024 01:53:24] "GET /app1/profile HTTP/1.1" 200 11673
[24/May/2024 01:55:23] "GET /app1/profile HTTP/1.1" 200 8529
Not Found: /app1/movie_detail/${item.id}
[24/May/2024 01:55:26] "GET /app1/movie_detail/$%7Bitem.id%7D HTTP/1.1" 404 3952
Internal Server Error: /app1/profile
Traceback (most recent call last):
  File "/home/ramachandra/.local/lib/python3.8/site-packages/django/core/handlers/exception.py", line 55, in inner
    response = get_response(request)
  File "/home/ramachandra/.local/lib/python3.8/site-packages/django/core/handlers/base.py", line 197, in _get_response
    response = wrapped_callback(request, *callback_args, **callback_kwargs)
  File "/home/ramachandra/movies/app1/views.py", line 79, in profile
    return render(request,"app1/profile.html",{"user":user,"fav":favorites})
  File "/home/ramachandra/.local/lib/python3.8/site-packages/django/shortcuts.py", line 24, in render
    content = loader.render_to_string(template_name, context, request, using=using)
  File "/home/ramachandra/.local/lib/python3.8/site-packages/django/template/loader.py", line 62, in render_to_string
    return template.render(context, request)
  File "/home/ramachandra/.local/lib/python3.8/site-packages/django/template/backends/django.py", line 61, in render
    return self.template.render(context)
  File "/home/ramachandra/.local/lib/python3.8/site-packages/django/template/base.py", line 175, in render
    return self._render(context)
  File "/home/ramachandra/.local/lib/python3.8/site-packages/django/template/base.py", line 167, in _render
    return self.nodelist.render(context)
  File "/home/ramachandra/.local/lib/python3.8/site-packages/django/template/base.py", line 1005, in render
    return SafeString("".join([node.render_annotated(context) for node in self]))
  File "/home/ramachandra/.local/lib/python3.8/site-packages/django/template/base.py", line 1005, in <listcomp>
    return SafeString("".join([node.render_annotated(context) for node in self]))
  File "/home/ramachandra/.local/lib/python3.8/site-packages/django/template/base.py", line 966, in render_annotated
    return self.render(context)
  File "/home/ramachandra/.local/lib/python3.8/site-packages/django/template/defaulttags.py", line 238, in render
    nodelist.append(node.render_annotated(context))
  File "/home/ramachandra/.local/lib/python3.8/site-packages/django/template/base.py", line 966, in render_annotated
    return self.render(context)
  File "/home/ramachandra/.local/lib/python3.8/site-packages/django/template/defaulttags.py", line 471, in render
    url = reverse(view_name, args=args, kwargs=kwargs, current_app=current_app)
  File "/home/ramachandra/.local/lib/python3.8/site-packages/django/urls/base.py", line 88, in reverse
    return resolver._reverse_with_prefix(view, prefix, *args, **kwargs)
  File "/home/ramachandra/.local/lib/python3.8/site-packages/django/urls/resolvers.py", line 828, in _reverse_with_prefix
    raise NoReverseMatch(msg)
django.urls.exceptions.NoReverseMatch: Reverse for 'movie_detail' with arguments '('',)' not found. 1 pattern(s) tried: ['app1/movie_detail/(?P<movie_id>[0-9]+)/\\Z']
[24/May/2024 01:56:08] "GET /app1/profile HTTP/1.1" 500 133824
[24/May/2024 01:56:25] "GET /app1/profile HTTP/1.1" 200 8533
[24/May/2024 01:56:34] "GET /app1/profile HTTP/1.1" 200 8533
[24/May/2024 01:56:38] "GET /app1/profile HTTP/1.1" 200 8533
[24/May/2024 01:56:43] "GET /app1/profile HTTP/1.1" 200 8533
[24/May/2024 01:56:51] "GET /app1/movie_detail/4200/ HTTP/1.1" 200 4549
[24/May/2024 01:57:06] "GET /app1/profile HTTP/1.1" 200 8533
[24/May/2024 01:57:08] "GET /app1/profile HTTP/1.1" 200 8533
[24/May/2024 01:57:10] "GET /app1/profile HTTP/1.1" 200 8533
[24/May/2024 01:57:15] "GET /app1/profile HTTP/1.1" 200 8533
[24/May/2024 01:57:17] "GET /app1/profile HTTP/1.1" 200 8532
[24/May/2024 01:57:30] "GET /app1/profile HTTP/1.1" 200 8532
[24/May/2024 01:57:38] "GET /app1/profile HTTP/1.1" 200 8532
Not Found: /
[24/May/2024 02:45:44] "GET / HTTP/1.0" 404 2188
[24/May/2024 02:45:44] code 400, message Bad request syntax ('HELP')
[24/May/2024 02:45:44] "HELP" 400 -
[24/May/2024 02:45:46] code 400, message Bad request syntax ('DmdT\x00\x00\x00\x17\x00\x00\x00\x01\x00\x00\x00\x00\x11\x11\x00ÿ\x01ÿ\x13')
[24/May/2024 02:45:46] "DmdT           ÿÿ" 400 -
[24/May/2024 02:53:10] code 400, message Bad request version ('\x00/\x00')
[24/May/2024 02:53:10] You're accessing the development server over HTTPS, but it only supports HTTP.
Not Found: /
[24/May/2024 02:53:48] "GET / HTTP/1.1" 404 2168
Not Found: /
[24/May/2024 05:33:25] "GET / HTTP/1.0" 404 2188
Not Found: /favicon.ico
[24/May/2024 06:52:43] "GET /favicon.ico HTTP/1.1" 404 2219
[24/May/2024 07:26:58] "GET /app1/ HTTP/1.1" 200 21343
[24/May/2024 07:27:05] "GET /app1/home HTTP/1.1" 200 126335
[24/May/2024 07:27:10] "GET /app1/profile HTTP/1.1" 200 8532
[24/May/2024 07:27:47] "GET /app1/profile HTTP/1.1" 200 8532
[24/May/2024 07:29:15] "POST /app1/add/1964/ HTTP/1.1" 200 16
[24/May/2024 07:29:21] "POST /app1/add/5261/ HTTP/1.1" 200 16
[24/May/2024 07:29:26] "GET /app1/profile HTTP/1.1" 200 10498
[24/May/2024 07:29:58] "GET /app1/movie_detail/806/ HTTP/1.1" 200 4416
[24/May/2024 07:30:25] "GET /app1/search HTTP/1.1" 200 9813
[24/May/2024 07:30:30] "GET /app1/ajax/search/?query=&genre=action&year=&rating= HTTP/1.1" 200 50655
[24/May/2024 07:31:18] "GET /app1/movie_detail/65 HTTP/1.1" 301 0
[24/May/2024 07:31:19] "GET /app1/movie_detail/65/ HTTP/1.1" 200 4504
[24/May/2024 07:31:30] "GET /app1/ajax/search/?query=&genre=action&year=&rating=8 HTTP/1.1" 200 46419
Not Found: /
[24/May/2024 07:45:17] "GET / HTTP/1.1" 404 2168
[24/May/2024 11:35:57] code 400, message Bad request version ("¯nãY»bhlÿ(=':©\x82ÙoÈ¢×\x93\x98´ï\x80å¹\x90\x00(À")
[24/May/2024 11:35:57] You're accessing the development server over HTTPS, but it only supports HTTP.
[24/May/2024 13:41:18] code 400, message Bad request syntax ('\x02\x01\x00\x00\x00\x00\x00\x06build')
[24/May/2024 13:41:18] "     build" 400 -
[24/May/2024 13:41:18] code 400, message Bad request syntax ('\x02\x01\x00\x00\x00\x00\x00\x06build')
[24/May/2024 13:41:18] "     build" 400 -
[24/May/2024 16:55:30] code 400, message Bad HTTP/0.9 request type ('\x03\x00\x00/*à\x00\x00\x00\x00\x00Cookie:')
[24/May/2024 16:55:30] "  /*à     Cookie: mstshash=Administr" 400 -
Not Found: /favicon.ico
[24/May/2024 19:48:24] "GET /favicon.ico HTTP/1.1" 404 2219
Not Found: /
[24/May/2024 20:31:02] "GET / HTTP/1.0" 404 2188
Not Found: /
[24/May/2024 20:40:12] "GET / HTTP/1.1" 404 2168
[24/May/2024 22:03:10] code 400, message Bad request version ('À\x13À')
[24/May/2024 22:03:10] You're accessing the development server over HTTPS, but it only supports HTTP.
[24/May/2024 22:03:10] code 400, message Bad request version ('À(À$À\x14À')
[24/May/2024 22:03:10] You're accessing the development server over HTTPS, but it only supports HTTP.
[24/May/2024 22:51:28] code 400, message Bad HTTP/0.9 request type ('\x03\x00\x00/*à\x00\x00\x00\x00\x00Cookie:')
[24/May/2024 22:51:28] "  /*à     Cookie: mstshash=Administr" 400 -
Not Found: /
[24/May/2024 23:02:36] "GET / HTTP/1.1" 404 2168
Not Found: /favicon.ico
[24/May/2024 23:02:36] "GET /favicon.ico HTTP/1.1" 404 2219
Not Found: /favicon.ico
[24/May/2024 23:57:20] "GET /favicon.ico HTTP/1.1" 404 2219
[25/May/2024 00:03:26] code 400, message Bad HTTP/0.9 request type ('\x16\x03\x01\x00')
[25/May/2024 00:03:26] You're accessing the development server over HTTPS, but it only supports HTTP.
Not Found: /
[25/May/2024 02:35:26] "GET / HTTP/1.1" 404 2168
[25/May/2024 02:35:29] code 505, message Invalid HTTP version (2.0)
[25/May/2024 02:35:29] "PRI * HTTP/2.0" 505 -
Not Found: /
[25/May/2024 02:53:14] "GET / HTTP/1.1" 404 2168
Not Found: /
[25/May/2024 05:06:44] "GET / HTTP/1.1" 404 2168
Not Found: /favicon.ico
[25/May/2024 05:07:00] "GET /favicon.ico HTTP/1.1" 404 2219
[25/May/2024 07:09:47] code 400, message Bad HTTP/0.9 request type ('\x03\x00\x00/*à\x00\x00\x00\x00\x00Cookie:')
[25/May/2024 07:09:47] "  /*à     Cookie: mstshash=Administr" 400 -
Not Found: /
[25/May/2024 10:55:00] "GET / HTTP/1.1" 404 2168
Not Found: /
[25/May/2024 10:58:21] "GET / HTTP/1.0" 404 2188
[25/May/2024 11:47:08] code 400, message Bad request version ("¯nãY»bhlÿ(=':©\x82ÙoÈ¢×\x93\x98´ï\x80å¹\x90\x00(À")
[25/May/2024 11:47:08] You're accessing the development server over HTTPS, but it only supports HTTP.
[25/May/2024 14:32:57] "GET /app1/ HTTP/1.1" 200 22787
Not Found: /favicon.ico
[25/May/2024 14:33:29] "GET /favicon.ico HTTP/1.1" 404 2219
[25/May/2024 14:33:29] "GET /app1/ HTTP/1.1" 200 22937
[25/May/2024 14:34:23] "GET /app1/ HTTP/1.1" 200 22089
[25/May/2024 14:34:37] "GET /app1/ HTTP/1.1" 200 22712
[25/May/2024 14:34:58] "GET /app1/ HTTP/1.1" 200 22405
[25/May/2024 14:35:20] "GET /app1/ HTTP/1.1" 200 22199
[25/May/2024 14:35:33] "GET /app1/ HTTP/1.1" 200 22606
[25/May/2024 14:36:40] "GET /app1/ HTTP/1.1" 200 22547
[25/May/2024 14:37:11] "GET /app1/movie_detail/2826/ HTTP/1.1" 200 4650
[25/May/2024 14:37:24] "GET /app1/login HTTP/1.1" 302 0
[25/May/2024 14:37:26] "GET /app1/home HTTP/1.1" 200 128228
[25/May/2024 14:37:29] "GET /app1/profile HTTP/1.1" 200 10498
[25/May/2024 14:37:58] "GET /app1/profile HTTP/1.1" 200 10498
[25/May/2024 14:40:09] "GET /app1/movie_detail/6340/ HTTP/1.1" 200 4375
[25/May/2024 14:42:21] "GET /app1/movie_detail/6340/ HTTP/1.1" 200 5664
[25/May/2024 14:42:32] "GET /app1/profile HTTP/1.1" 200 10498
[25/May/2024 14:42:37] "GET /app1/profile HTTP/1.1" 200 10498
[25/May/2024 14:42:55] "GET /app1/home HTTP/1.1" 200 126980
[25/May/2024 14:42:59] "GET /app1/movie_detail/1619/ HTTP/1.1" 200 5810
[25/May/2024 14:44:22] "GET /app1/movie_detail/1619/ HTTP/1.1" 200 5904
Not Found: /app1/add/undefined/
[25/May/2024 14:44:31] "POST /app1/add/undefined/ HTTP/1.1" 404 3922
Not Found: /app1/add/undefined/
[25/May/2024 14:44:34] "POST /app1/add/undefined/ HTTP/1.1" 404 3922
[25/May/2024 14:44:41] "GET /app1/movie_detail/1619/ HTTP/1.1" 200 5904
Not Found: /app1/add/undefined/
[25/May/2024 14:44:50] "POST /app1/add/undefined/ HTTP/1.1" 404 3922
[25/May/2024 14:45:23] "GET /app1/movie_detail/1619/ HTTP/1.1" 200 5938
Not Found: /app1/add/undefined/
[25/May/2024 14:45:26] "POST /app1/add/undefined/ HTTP/1.1" 404 3922
[25/May/2024 14:45:51] "GET /app1/movie_detail/1619/ HTTP/1.1" 200 5930
Not Found: /app1/add/undefined/
[25/May/2024 14:45:54] "POST /app1/add/undefined/ HTTP/1.1" 404 3922
[25/May/2024 14:46:51] "GET /app1/movie_detail/1619/ HTTP/1.1" 200 5932
Not Found: /app1/add/undefined/
[25/May/2024 14:46:54] "POST /app1/add/undefined/ HTTP/1.1" 404 3922
[25/May/2024 14:47:45] "GET /app1/movie_detail/1619/ HTTP/1.1" 200 5930
Not Found: /app1/add/undefined/
[25/May/2024 14:47:47] "POST /app1/add/undefined/ HTTP/1.1" 404 3922
[25/May/2024 14:48:13] "GET /app1/movie_detail/1619/ HTTP/1.1" 200 5809
[25/May/2024 14:49:23] "GET /app1/movie_detail/1619/ HTTP/1.1" 200 5783
Not Found: /app1/add//
[25/May/2024 14:49:25] "POST /app1/add// HTTP/1.1" 404 3895
[25/May/2024 14:49:47] "GET /app1/movie_detail/1619/ HTTP/1.1" 200 5818
Not Found: /app1/add//
[25/May/2024 14:49:49] "POST /app1/add// HTTP/1.1" 404 3895
[25/May/2024 14:50:03] "GET /app1/movie_detail/1619/ HTTP/1.1" 200 5816
Not Found: /app1/add/undefined/
[25/May/2024 14:50:05] "POST /app1/add/undefined/ HTTP/1.1" 404 3922
[25/May/2024 14:51:32] "GET /app1/movie_detail/1619/ HTTP/1.1" 200 5819
Not Found: /app1/add//
[25/May/2024 14:51:34] "POST /app1/add// HTTP/1.1" 404 3895
[25/May/2024 14:52:13] "GET /app1/movie_detail/1619/ HTTP/1.1" 200 5818
Not Found: /app1/add//
[25/May/2024 14:52:16] "POST /app1/add// HTTP/1.1" 404 3895
[25/May/2024 14:53:01] "GET /app1/movie_detail/1619/ HTTP/1.1" 200 5827
Not Found: /app1/add//
[25/May/2024 14:53:03] "POST /app1/add// HTTP/1.1" 404 3895
Not Found: /app1/add//
[25/May/2024 14:53:16] "POST /app1/add// HTTP/1.1" 404 3895
/home/ramachandra/movies/app1/views.py changed, reloading.
Watching for file changes with StatReloader
Performing system checks...

System check identified no issues (0 silenced).
May 25, 2024 - 14:53:41
Django version 4.2.13, using settings 'movies.settings'
Starting development server at http://0.0.0.0:3000/
Quit the server with CONTROL-C.

/home/ramachandra/movies/app1/views.py changed, reloading.
Watching for file changes with StatReloader
Performing system checks...

Exception in thread django-main-thread:
Traceback (most recent call last):
  File "/usr/lib/python3.8/threading.py", line 932, in _bootstrap_inner
    self.run()
  File "/usr/lib/python3.8/threading.py", line 870, in run
    self._target(*self._args, **self._kwargs)
  File "/home/ramachandra/.local/lib/python3.8/site-packages/django/utils/autoreload.py", line 64, in wrapper
    fn(*args, **kwargs)
  File "/home/ramachandra/.local/lib/python3.8/site-packages/django/core/management/commands/runserver.py", line 133, in inner_run
    self.check(display_num_errors=True)
  File "/home/ramachandra/.local/lib/python3.8/site-packages/django/core/management/base.py", line 485, in check
    all_issues = checks.run_checks(
  File "/home/ramachandra/.local/lib/python3.8/site-packages/django/core/checks/registry.py", line 88, in run_checks
    new_errors = check(app_configs=app_configs, databases=databases)
  File "/home/ramachandra/.local/lib/python3.8/site-packages/django/core/checks/urls.py", line 14, in check_url_config
    return check_resolver(resolver)
  File "/home/ramachandra/.local/lib/python3.8/site-packages/django/core/checks/urls.py", line 24, in check_resolver
    return check_method()
  File "/home/ramachandra/.local/lib/python3.8/site-packages/django/urls/resolvers.py", line 494, in check
    for pattern in self.url_patterns:
  File "/home/ramachandra/.local/lib/python3.8/site-packages/django/utils/functional.py", line 57, in __get__
    res = instance.__dict__[self.name] = self.func(instance)
  File "/home/ramachandra/.local/lib/python3.8/site-packages/django/urls/resolvers.py", line 715, in url_patterns
    patterns = getattr(self.urlconf_module, "urlpatterns", self.urlconf_module)
  File "/home/ramachandra/.local/lib/python3.8/site-packages/django/utils/functional.py", line 57, in __get__
    res = instance.__dict__[self.name] = self.func(instance)
  File "/home/ramachandra/.local/lib/python3.8/site-packages/django/urls/resolvers.py", line 708, in urlconf_module
    return import_module(self.urlconf_name)
  File "/usr/lib/python3.8/importlib/__init__.py", line 127, in import_module
    return _bootstrap._gcd_import(name[level:], package, level)
  File "<frozen importlib._bootstrap>", line 1014, in _gcd_import
  File "<frozen importlib._bootstrap>", line 991, in _find_and_load
  File "<frozen importlib._bootstrap>", line 975, in _find_and_load_unlocked
  File "<frozen importlib._bootstrap>", line 671, in _load_unlocked
  File "<frozen importlib._bootstrap_external>", line 848, in exec_module
  File "<frozen importlib._bootstrap>", line 219, in _call_with_frames_removed
  File "/home/ramachandra/movies/movies/urls.py", line 21, in <module>
    path('app1/',include('app1.urls')),
  File "/home/ramachandra/.local/lib/python3.8/site-packages/django/urls/conf.py", line 38, in include
    urlconf_module = import_module(urlconf_module)
  File "/usr/lib/python3.8/importlib/__init__.py", line 127, in import_module
    return _bootstrap._gcd_import(name[level:], package, level)
  File "<frozen importlib._bootstrap>", line 1014, in _gcd_import
  File "<frozen importlib._bootstrap>", line 991, in _find_and_load
  File "<frozen importlib._bootstrap>", line 975, in _find_and_load_unlocked
  File "<frozen importlib._bootstrap>", line 671, in _load_unlocked
  File "<frozen importlib._bootstrap_external>", line 848, in exec_module
  File "<frozen importlib._bootstrap>", line 219, in _call_with_frames_removed
  File "/home/ramachandra/movies/app1/urls.py", line 3, in <module>
    from .views import upload_file,search_movies,land,login_view,logout_view,home,movie_detail,profile,add,search
  File "/home/ramachandra/movies/app1/views.py", line 124
    'title':movie.title,
    ^
SyntaxError: invalid syntax
/home/ramachandra/movies/app1/views.py changed, reloading.
Watching for file changes with StatReloader
Performing system checks...

Exception in thread django-main-thread:
Traceback (most recent call last):
  File "/usr/lib/python3.8/threading.py", line 932, in _bootstrap_inner
    self.run()
  File "/usr/lib/python3.8/threading.py", line 870, in run
    self._target(*self._args, **self._kwargs)
  File "/home/ramachandra/.local/lib/python3.8/site-packages/django/utils/autoreload.py", line 64, in wrapper
    fn(*args, **kwargs)
  File "/home/ramachandra/.local/lib/python3.8/site-packages/django/core/management/commands/runserver.py", line 133, in inner_run
    self.check(display_num_errors=True)
  File "/home/ramachandra/.local/lib/python3.8/site-packages/django/core/management/base.py", line 485, in check
    all_issues = checks.run_checks(
  File "/home/ramachandra/.local/lib/python3.8/site-packages/django/core/checks/registry.py", line 88, in run_checks
    new_errors = check(app_configs=app_configs, databases=databases)
  File "/home/ramachandra/.local/lib/python3.8/site-packages/django/core/checks/urls.py", line 14, in check_url_config
    return check_resolver(resolver)
  File "/home/ramachandra/.local/lib/python3.8/site-packages/django/core/checks/urls.py", line 24, in check_resolver
    return check_method()
  File "/home/ramachandra/.local/lib/python3.8/site-packages/django/urls/resolvers.py", line 494, in check
    for pattern in self.url_patterns:
  File "/home/ramachandra/.local/lib/python3.8/site-packages/django/utils/functional.py", line 57, in __get__
    res = instance.__dict__[self.name] = self.func(instance)
  File "/home/ramachandra/.local/lib/python3.8/site-packages/django/urls/resolvers.py", line 715, in url_patterns
    patterns = getattr(self.urlconf_module, "urlpatterns", self.urlconf_module)
  File "/home/ramachandra/.local/lib/python3.8/site-packages/django/utils/functional.py", line 57, in __get__
    res = instance.__dict__[self.name] = self.func(instance)
  File "/home/ramachandra/.local/lib/python3.8/site-packages/django/urls/resolvers.py", line 708, in urlconf_module
    return import_module(self.urlconf_name)
  File "/usr/lib/python3.8/importlib/__init__.py", line 127, in import_module
    return _bootstrap._gcd_import(name[level:], package, level)
  File "<frozen importlib._bootstrap>", line 1014, in _gcd_import
  File "<frozen importlib._bootstrap>", line 991, in _find_and_load
  File "<frozen importlib._bootstrap>", line 975, in _find_and_load_unlocked
  File "<frozen importlib._bootstrap>", line 671, in _load_unlocked
  File "<frozen importlib._bootstrap_external>", line 848, in exec_module
  File "<frozen importlib._bootstrap>", line 219, in _call_with_frames_removed
  File "/home/ramachandra/movies/movies/urls.py", line 21, in <module>
    path('app1/',include('app1.urls')),
  File "/home/ramachandra/.local/lib/python3.8/site-packages/django/urls/conf.py", line 38, in include
    urlconf_module = import_module(urlconf_module)
  File "/usr/lib/python3.8/importlib/__init__.py", line 127, in import_module
    return _bootstrap._gcd_import(name[level:], package, level)
  File "<frozen importlib._bootstrap>", line 1014, in _gcd_import
  File "<frozen importlib._bootstrap>", line 991, in _find_and_load
  File "<frozen importlib._bootstrap>", line 975, in _find_and_load_unlocked
  File "<frozen importlib._bootstrap>", line 671, in _load_unlocked
  File "<frozen importlib._bootstrap_external>", line 848, in exec_module
  File "<frozen importlib._bootstrap>", line 219, in _call_with_frames_removed
  File "/home/ramachandra/movies/app1/urls.py", line 3, in <module>
    from .views import upload_file,search_movies,land,login_view,logout_view,home,movie_detail,profile,add,search
  File "/home/ramachandra/movies/app1/views.py", line 124
    'title':movie.title,
    ^
SyntaxError: invalid syntax
/home/ramachandra/movies/app1/views.py changed, reloading.
Watching for file changes with StatReloader
Performing system checks...

System check identified no issues (0 silenced).
May 25, 2024 - 14:53:50
Django version 4.2.13, using settings 'movies.settings'
Starting development server at http://0.0.0.0:3000/
Quit the server with CONTROL-C.

/home/ramachandra/movies/app1/views.py changed, reloading.
Watching for file changes with StatReloader
Performing system checks...

System check identified no issues (0 silenced).
May 25, 2024 - 14:53:52
Django version 4.2.13, using settings 'movies.settings'
Starting development server at http://0.0.0.0:3000/
Quit the server with CONTROL-C.

[25/May/2024 14:53:55] "GET /app1/movie_detail/1619/ HTTP/1.1" 200 5831
[25/May/2024 14:53:57] "POST /app1/add/1619/ HTTP/1.1" 200 16
[25/May/2024 14:54:13] "GET /app1/movie_detail/1619/ HTTP/1.1" 200 5796
[25/May/2024 14:54:15] "POST /app1/add/1619/ HTTP/1.1" 200 17
[25/May/2024 14:54:29] "POST /app1/add/1495/ HTTP/1.1" 200 16
[25/May/2024 14:54:36] "GET /app1/profile HTTP/1.1" 200 12443
[25/May/2024 14:54:47] "GET /app1/movie_detail/1495/ HTTP/1.1" 200 5646
[25/May/2024 14:54:50] "POST /app1/add/1495/ HTTP/1.1" 200 17
[25/May/2024 14:55:07] "GET /app1/search HTTP/1.1" 200 9813
[25/May/2024 14:55:11] "GET /app1/ajax/search/?query=&genre=action&year=&rating= HTTP/1.1" 200 50655
[25/May/2024 14:55:19] "GET /app1/movie_detail/1 HTTP/1.1" 301 0
[25/May/2024 14:55:19] "GET /app1/movie_detail/1/ HTTP/1.1" 200 5750
[25/May/2024 14:55:24] "GET /app1/movie_detail/1/ HTTP/1.1" 200 5750
[25/May/2024 14:57:30] "GET /app1/search HTTP/1.1" 200 11059
[25/May/2024 14:57:34] "GET /app1/ajax/search/?query=&genre=action&year=&rating= HTTP/1.1" 200 50655
[25/May/2024 14:57:38] "GET /app1/movie_detail/1/ HTTP/1.1" 200 5750
[25/May/2024 14:57:47] "GET /app1/search HTTP/1.1" 200 11059
[25/May/2024 14:57:55] "GET /app1/ajax/search/?query=&genre=action&year=&rating= HTTP/1.1" 200 50655
[25/May/2024 14:57:59] "GET /app1/movie_detail/1/ HTTP/1.1" 200 5750
[25/May/2024 14:58:46] "GET /app1/search HTTP/1.1" 200 11058
[25/May/2024 14:58:49] "GET /app1/ajax/search/?query=&genre=action&year=&rating= HTTP/1.1" 200 50655
[25/May/2024 14:58:52] "POST /app1/add/1/ HTTP/1.1" 200 16
[25/May/2024 14:58:59] "POST /app1/add/5/ HTTP/1.1" 200 16
[25/May/2024 14:59:07] "GET /app1/profile HTTP/1.1" 200 14415
[25/May/2024 15:01:15] "GET /app1/home HTTP/1.1" 200 126401
Not Found: /app1/login 
[25/May/2024 15:01:20] "GET /app1/login%20 HTTP/1.1" 404 3899
[25/May/2024 15:01:40] "GET /app1/home HTTP/1.1" 200 127076
[25/May/2024 15:01:48] "GET /app1/profile HTTP/1.1" 200 14424
Not Found: /app1/profile 
[25/May/2024 15:01:53] "GET /app1/profile%20 HTTP/1.1" 404 3905
[25/May/2024 15:02:04] "GET /app1/home HTTP/1.1" 200 129872
[25/May/2024 15:02:07] "GET /app1/profile HTTP/1.1" 200 14424
[25/May/2024 15:02:26] "GET /app1/home HTTP/1.1" 200 125805
[25/May/2024 15:02:32] "GET /app1/profile HTTP/1.1" 200 14424
[25/May/2024 15:02:39] "GET /app1/profile HTTP/1.1" 200 14424
[25/May/2024 15:02:44] "GET /app1/profile HTTP/1.1" 200 14424
[25/May/2024 15:02:50] "GET /app1/profile HTTP/1.1" 200 14424
[25/May/2024 15:02:58] "GET /app1/profile HTTP/1.1" 200 14424
