nohup: ignoring input
Watching for file changes with StatReloader
Performing system checks...

System check identified no issues (0 silenced).
May 19, 2024 - 05:22:53
Django version 4.2.13, using settings 'movies.settings'
Starting development server at http://0.0.0.0:3000/
Quit the server with CONTROL-C.

Not Found: /home
[19/May/2024 05:23:23] "GET /home HTTP/1.1" 404 2198
[19/May/2024 05:23:29] "GET /app1/home HTTP/1.1" 200 17766
[19/May/2024 05:23:52] "GET /app1/login HTTP/1.1" 200 4205
[19/May/2024 05:23:57] "POST /app1/login HTTP/1.1" 302 0
[19/May/2024 05:23:57] "GET /app1/home HTTP/1.1" 200 19012
Forbidden (CSRF token from POST incorrect.): /app1/login
[19/May/2024 05:24:02] "POST /app1/login HTTP/1.1" 403 2518
[19/May/2024 05:24:04] "GET /app1/login HTTP/1.1" 200 4205
[19/May/2024 05:24:08] "POST /app1/login HTTP/1.1" 200 4531
[19/May/2024 05:25:37] "GET /app1/login HTTP/1.1" 200 4205
[19/May/2024 05:25:38] "GET /app1/login HTTP/1.1" 200 4205
[19/May/2024 05:25:42] "GET /app1/ HTTP/1.1" 200 28154
[19/May/2024 05:25:43] "GET /app1/ HTTP/1.1" 200 26903
[19/May/2024 05:25:44] "GET /app1/ HTTP/1.1" 200 27363
[19/May/2024 05:28:07] "GET /app1/login HTTP/1.1" 200 4205
[19/May/2024 05:28:25] "POST /app1/login HTTP/1.1" 302 0
[19/May/2024 05:28:26] "GET /app1/home HTTP/1.1" 200 17842
Forbidden (CSRF token from POST incorrect.): /app1/login
[19/May/2024 05:29:11] "POST /app1/login HTTP/1.1" 403 2518
[19/May/2024 05:29:12] "GET /app1/login HTTP/1.1" 200 4205
2018-November-30
[19/May/2024 05:29:19] "GET /app1/movie_detail/8089/ HTTP/1.1" 200 4355
Not Found: /app1/movie_detail/8089/styles.css
[19/May/2024 05:29:19] "GET /app1/movie_detail/8089/styles.css HTTP/1.1" 404 3426
[19/May/2024 05:29:25] "GET /app1/login HTTP/1.1" 200 4205
[19/May/2024 05:29:33] "POST /app1/login HTTP/1.1" 200 4445
[19/May/2024 05:29:40] "POST /app1/login HTTP/1.1" 302 0
[19/May/2024 05:29:40] "GET /app1/home HTTP/1.1" 200 18310
Forbidden (CSRF token from POST incorrect.): /app1/login
[19/May/2024 05:29:47] "POST /app1/login HTTP/1.1" 403 2518
[19/May/2024 05:29:48] "GET /app1/login HTTP/1.1" 200 4205
[19/May/2024 05:30:02] "POST /app1/login HTTP/1.1" 302 0
[19/May/2024 05:30:02] "GET /app1/home HTTP/1.1" 200 18799
[19/May/2024 05:41:18] "GET /app1/home HTTP/1.1" 200 18352
Not Found: /
[19/May/2024 05:58:43] "GET / HTTP/1.0" 404 2188
[19/May/2024 07:07:11,586] - Broken pipe from ('167.94.145.108', 33892)
[19/May/2024 07:07:11] code 400, message Bad request version ('öò')
[19/May/2024 07:07:11] You're accessing the development server over HTTPS, but it only supports HTTP.
Not Found: /
[19/May/2024 07:07:14] "GET / HTTP/1.1" 404 2168
[19/May/2024 07:07:15,122] - Broken pipe from ('167.94.145.108', 38904)
Not Found: /
[19/May/2024 07:07:18] "GET / HTTP/1.1" 404 2168
[19/May/2024 07:07:18] code 505, message Invalid HTTP version (2.0)
[19/May/2024 07:07:18] "PRI * HTTP/2.0" 505 -
[19/May/2024 07:25:27] "GET /app1/ HTTP/1.1" 200 26327
[19/May/2024 07:25:33] "GET /app1/ HTTP/1.1" 200 26624
[19/May/2024 07:26:19] "GET /app1/ajax/search/?query=a HTTP/1.1" 200 11874
[19/May/2024 07:26:29] "GET /app1/movie_detail/7 HTTP/1.1" 301 0
[19/May/2024 07:26:29] "GET /app1/movie_detail/7/ HTTP/1.1" 302 0
[19/May/2024 07:26:29] "GET /app1/login HTTP/1.1" 200 4205
[19/May/2024 07:26:35] "POST /app1/login HTTP/1.1" 200 4535
[19/May/2024 07:26:42] "POST /app1/login HTTP/1.1" 302 0
[19/May/2024 07:26:42] "GET /app1/home HTTP/1.1" 200 18268
[19/May/2024 07:27:13] "GET /app1/login HTTP/1.1" 200 4205
[19/May/2024 07:28:09] "GET /app1/ HTTP/1.1" 200 26755
[19/May/2024 07:28:32] "GET /app1/ HTTP/1.1" 200 27735
[19/May/2024 07:28:59] "GET /app1/ HTTP/1.1" 200 27116
[19/May/2024 07:29:18] "GET /app1/ HTTP/1.1" 200 27527
[19/May/2024 07:29:20] "GET /app1/ HTTP/1.1" 200 26087
[19/May/2024 07:29:27] "GET /app1/login HTTP/1.1" 200 4205
[19/May/2024 07:30:13] "GET /app1/ HTTP/1.1" 200 25967
[19/May/2024 07:31:13] "GET /app1/ HTTP/1.1" 200 27272
[19/May/2024 07:32:06] "GET /app1/ HTTP/1.1" 200 26938
[19/May/2024 07:32:53] "GET /app1/ HTTP/1.1" 200 26510
[19/May/2024 07:33:15] "GET /app1/ajax/search/?query=a HTTP/1.1" 200 11874
[19/May/2024 07:33:27] "GET /app1/movie_detail/29 HTTP/1.1" 301 0
2020-October-16
[19/May/2024 07:33:27] "GET /app1/movie_detail/29/ HTTP/1.1" 200 4332
Not Found: /app1/movie_detail/29/styles.css
[19/May/2024 07:33:28] "GET /app1/movie_detail/29/styles.css HTTP/1.1" 404 3420
[19/May/2024 07:33:41] "GET /app1/login HTTP/1.1" 200 4205
[19/May/2024 07:33:48] "POST /app1/login HTTP/1.1" 302 0
[19/May/2024 07:33:48] "GET /app1/home HTTP/1.1" 200 18204
/home/ramachandra/movies/app1/views.py changed, reloading.
Watching for file changes with StatReloader
Performing system checks...

Exception in thread django-main-thread:
Traceback (most recent call last):
  File "/usr/lib/python3.8/threading.py", line 932, in _bootstrap_inner
    self.run()
  File "/usr/lib/python3.8/threading.py", line 870, in run
    self._target(*self._args, **self._kwargs)
  File "/home/ramachandra/.local/lib/python3.8/site-packages/django/utils/autoreload.py", line 64, in wrapper
    fn(*args, **kwargs)
  File "/home/ramachandra/.local/lib/python3.8/site-packages/django/core/management/commands/runserver.py", line 133, in inner_run
    self.check(display_num_errors=True)
  File "/home/ramachandra/.local/lib/python3.8/site-packages/django/core/management/base.py", line 485, in check
    all_issues = checks.run_checks(
  File "/home/ramachandra/.local/lib/python3.8/site-packages/django/core/checks/registry.py", line 88, in run_checks
    new_errors = check(app_configs=app_configs, databases=databases)
  File "/home/ramachandra/.local/lib/python3.8/site-packages/django/core/checks/urls.py", line 14, in check_url_config
    return check_resolver(resolver)
  File "/home/ramachandra/.local/lib/python3.8/site-packages/django/core/checks/urls.py", line 24, in check_resolver
    return check_method()
  File "/home/ramachandra/.local/lib/python3.8/site-packages/django/urls/resolvers.py", line 494, in check
    for pattern in self.url_patterns:
  File "/home/ramachandra/.local/lib/python3.8/site-packages/django/utils/functional.py", line 57, in __get__
    res = instance.__dict__[self.name] = self.func(instance)
  File "/home/ramachandra/.local/lib/python3.8/site-packages/django/urls/resolvers.py", line 715, in url_patterns
    patterns = getattr(self.urlconf_module, "urlpatterns", self.urlconf_module)
  File "/home/ramachandra/.local/lib/python3.8/site-packages/django/utils/functional.py", line 57, in __get__
    res = instance.__dict__[self.name] = self.func(instance)
  File "/home/ramachandra/.local/lib/python3.8/site-packages/django/urls/resolvers.py", line 708, in urlconf_module
    return import_module(self.urlconf_name)
  File "/usr/lib/python3.8/importlib/__init__.py", line 127, in import_module
    return _bootstrap._gcd_import(name[level:], package, level)
  File "<frozen importlib._bootstrap>", line 1014, in _gcd_import
  File "<frozen importlib._bootstrap>", line 991, in _find_and_load
  File "<frozen importlib._bootstrap>", line 975, in _find_and_load_unlocked
  File "<frozen importlib._bootstrap>", line 671, in _load_unlocked
  File "<frozen importlib._bootstrap_external>", line 848, in exec_module
  File "<frozen importlib._bootstrap>", line 219, in _call_with_frames_removed
  File "/home/ramachandra/movies/movies/urls.py", line 21, in <module>
    path('app1/',include('app1.urls')),
  File "/home/ramachandra/.local/lib/python3.8/site-packages/django/urls/conf.py", line 38, in include
    urlconf_module = import_module(urlconf_module)
  File "/usr/lib/python3.8/importlib/__init__.py", line 127, in import_module
    return _bootstrap._gcd_import(name[level:], package, level)
  File "<frozen importlib._bootstrap>", line 1014, in _gcd_import
  File "<frozen importlib._bootstrap>", line 991, in _find_and_load
  File "<frozen importlib._bootstrap>", line 975, in _find_and_load_unlocked
  File "<frozen importlib._bootstrap>", line 671, in _load_unlocked
  File "<frozen importlib._bootstrap_external>", line 848, in exec_module
  File "<frozen importlib._bootstrap>", line 219, in _call_with_frames_removed
  File "/home/ramachandra/movies/app1/urls.py", line 3, in <module>
    from .views import upload_file,search_items,land,login_view,logout_view,home,movie_detail
  File "/home/ramachandra/movies/app1/views.py", line 53, in <module>
    profil
NameError: name 'profil' is not defined
/home/ramachandra/movies/app1/views.py changed, reloading.
Watching for file changes with StatReloader
Performing system checks...

Exception in thread django-main-thread:
Traceback (most recent call last):
  File "/usr/lib/python3.8/threading.py", line 932, in _bootstrap_inner
    self.run()
  File "/usr/lib/python3.8/threading.py", line 870, in run
    self._target(*self._args, **self._kwargs)
  File "/home/ramachandra/.local/lib/python3.8/site-packages/django/utils/autoreload.py", line 64, in wrapper
    fn(*args, **kwargs)
  File "/home/ramachandra/.local/lib/python3.8/site-packages/django/core/management/commands/runserver.py", line 133, in inner_run
    self.check(display_num_errors=True)
  File "/home/ramachandra/.local/lib/python3.8/site-packages/django/core/management/base.py", line 485, in check
    all_issues = checks.run_checks(
  File "/home/ramachandra/.local/lib/python3.8/site-packages/django/core/checks/registry.py", line 88, in run_checks
    new_errors = check(app_configs=app_configs, databases=databases)
  File "/home/ramachandra/.local/lib/python3.8/site-packages/django/core/checks/urls.py", line 14, in check_url_config
    return check_resolver(resolver)
  File "/home/ramachandra/.local/lib/python3.8/site-packages/django/core/checks/urls.py", line 24, in check_resolver
    return check_method()
  File "/home/ramachandra/.local/lib/python3.8/site-packages/django/urls/resolvers.py", line 494, in check
    for pattern in self.url_patterns:
  File "/home/ramachandra/.local/lib/python3.8/site-packages/django/utils/functional.py", line 57, in __get__
    res = instance.__dict__[self.name] = self.func(instance)
  File "/home/ramachandra/.local/lib/python3.8/site-packages/django/urls/resolvers.py", line 715, in url_patterns
    patterns = getattr(self.urlconf_module, "urlpatterns", self.urlconf_module)
  File "/home/ramachandra/.local/lib/python3.8/site-packages/django/utils/functional.py", line 57, in __get__
    res = instance.__dict__[self.name] = self.func(instance)
  File "/home/ramachandra/.local/lib/python3.8/site-packages/django/urls/resolvers.py", line 708, in urlconf_module
    return import_module(self.urlconf_name)
  File "/usr/lib/python3.8/importlib/__init__.py", line 127, in import_module
    return _bootstrap._gcd_import(name[level:], package, level)
  File "<frozen importlib._bootstrap>", line 1014, in _gcd_import
  File "<frozen importlib._bootstrap>", line 991, in _find_and_load
  File "<frozen importlib._bootstrap>", line 975, in _find_and_load_unlocked
  File "<frozen importlib._bootstrap>", line 671, in _load_unlocked
  File "<frozen importlib._bootstrap_external>", line 848, in exec_module
  File "<frozen importlib._bootstrap>", line 219, in _call_with_frames_removed
  File "/home/ramachandra/movies/movies/urls.py", line 21, in <module>
    path('app1/',include('app1.urls')),
  File "/home/ramachandra/.local/lib/python3.8/site-packages/django/urls/conf.py", line 38, in include
    urlconf_module = import_module(urlconf_module)
  File "/usr/lib/python3.8/importlib/__init__.py", line 127, in import_module
    return _bootstrap._gcd_import(name[level:], package, level)
  File "<frozen importlib._bootstrap>", line 1014, in _gcd_import
  File "<frozen importlib._bootstrap>", line 991, in _find_and_load
  File "<frozen importlib._bootstrap>", line 975, in _find_and_load_unlocked
  File "<frozen importlib._bootstrap>", line 671, in _load_unlocked
  File "<frozen importlib._bootstrap_external>", line 848, in exec_module
  File "<frozen importlib._bootstrap>", line 219, in _call_with_frames_removed
  File "/home/ramachandra/movies/app1/urls.py", line 3, in <module>
    from .views import upload_file,search_items,land,login_view,logout_view,home,movie_detail
  File "/home/ramachandra/movies/app1/views.py", line 53, in <module>
    profile()
NameError: name 'profile' is not defined
/home/ramachandra/movies/app1/views.py changed, reloading.
Watching for file changes with StatReloader
Performing system checks...

Exception in thread django-main-thread:
Traceback (most recent call last):
  File "/usr/lib/python3.8/threading.py", line 932, in _bootstrap_inner
    self.run()
  File "/usr/lib/python3.8/threading.py", line 870, in run
    self._target(*self._args, **self._kwargs)
  File "/home/ramachandra/.local/lib/python3.8/site-packages/django/utils/autoreload.py", line 64, in wrapper
    fn(*args, **kwargs)
  File "/home/ramachandra/.local/lib/python3.8/site-packages/django/core/management/commands/runserver.py", line 133, in inner_run
    self.check(display_num_errors=True)
  File "/home/ramachandra/.local/lib/python3.8/site-packages/django/core/management/base.py", line 485, in check
    all_issues = checks.run_checks(
  File "/home/ramachandra/.local/lib/python3.8/site-packages/django/core/checks/registry.py", line 88, in run_checks
    new_errors = check(app_configs=app_configs, databases=databases)
  File "/home/ramachandra/.local/lib/python3.8/site-packages/django/core/checks/urls.py", line 14, in check_url_config
    return check_resolver(resolver)
  File "/home/ramachandra/.local/lib/python3.8/site-packages/django/core/checks/urls.py", line 24, in check_resolver
    return check_method()
  File "/home/ramachandra/.local/lib/python3.8/site-packages/django/urls/resolvers.py", line 494, in check
    for pattern in self.url_patterns:
  File "/home/ramachandra/.local/lib/python3.8/site-packages/django/utils/functional.py", line 57, in __get__
    res = instance.__dict__[self.name] = self.func(instance)
  File "/home/ramachandra/.local/lib/python3.8/site-packages/django/urls/resolvers.py", line 715, in url_patterns
    patterns = getattr(self.urlconf_module, "urlpatterns", self.urlconf_module)
  File "/home/ramachandra/.local/lib/python3.8/site-packages/django/utils/functional.py", line 57, in __get__
    res = instance.__dict__[self.name] = self.func(instance)
  File "/home/ramachandra/.local/lib/python3.8/site-packages/django/urls/resolvers.py", line 708, in urlconf_module
    return import_module(self.urlconf_name)
  File "/usr/lib/python3.8/importlib/__init__.py", line 127, in import_module
    return _bootstrap._gcd_import(name[level:], package, level)
  File "<frozen importlib._bootstrap>", line 1014, in _gcd_import
  File "<frozen importlib._bootstrap>", line 991, in _find_and_load
  File "<frozen importlib._bootstrap>", line 975, in _find_and_load_unlocked
  File "<frozen importlib._bootstrap>", line 671, in _load_unlocked
  File "<frozen importlib._bootstrap_external>", line 848, in exec_module
  File "<frozen importlib._bootstrap>", line 219, in _call_with_frames_removed
  File "/home/ramachandra/movies/movies/urls.py", line 21, in <module>
    path('app1/',include('app1.urls')),
  File "/home/ramachandra/.local/lib/python3.8/site-packages/django/urls/conf.py", line 38, in include
    urlconf_module = import_module(urlconf_module)
  File "/usr/lib/python3.8/importlib/__init__.py", line 127, in import_module
    return _bootstrap._gcd_import(name[level:], package, level)
  File "<frozen importlib._bootstrap>", line 1014, in _gcd_import
  File "<frozen importlib._bootstrap>", line 991, in _find_and_load
  File "<frozen importlib._bootstrap>", line 975, in _find_and_load_unlocked
  File "<frozen importlib._bootstrap>", line 671, in _load_unlocked
  File "<frozen importlib._bootstrap_external>", line 848, in exec_module
  File "<frozen importlib._bootstrap>", line 219, in _call_with_frames_removed
  File "/home/ramachandra/movies/app1/urls.py", line 3, in <module>
    from .views import upload_file,search_items,land,login_view,logout_view,home,movie_detail
  File "/home/ramachandra/movies/app1/views.py", line 53, in <module>
    profile(re)
NameError: name 'profile' is not defined
/home/ramachandra/movies/app1/views.py changed, reloading.
Watching for file changes with StatReloader
Performing system checks...

Exception in thread django-main-thread:
Traceback (most recent call last):
  File "/usr/lib/python3.8/threading.py", line 932, in _bootstrap_inner
    self.run()
  File "/usr/lib/python3.8/threading.py", line 870, in run
    self._target(*self._args, **self._kwargs)
  File "/home/ramachandra/.local/lib/python3.8/site-packages/django/utils/autoreload.py", line 64, in wrapper
    fn(*args, **kwargs)
  File "/home/ramachandra/.local/lib/python3.8/site-packages/django/core/management/commands/runserver.py", line 133, in inner_run
    self.check(display_num_errors=True)
  File "/home/ramachandra/.local/lib/python3.8/site-packages/django/core/management/base.py", line 485, in check
    all_issues = checks.run_checks(
  File "/home/ramachandra/.local/lib/python3.8/site-packages/django/core/checks/registry.py", line 88, in run_checks
    new_errors = check(app_configs=app_configs, databases=databases)
  File "/home/ramachandra/.local/lib/python3.8/site-packages/django/core/checks/urls.py", line 14, in check_url_config
    return check_resolver(resolver)
  File "/home/ramachandra/.local/lib/python3.8/site-packages/django/core/checks/urls.py", line 24, in check_resolver
    return check_method()
  File "/home/ramachandra/.local/lib/python3.8/site-packages/django/urls/resolvers.py", line 494, in check
    for pattern in self.url_patterns:
  File "/home/ramachandra/.local/lib/python3.8/site-packages/django/utils/functional.py", line 57, in __get__
    res = instance.__dict__[self.name] = self.func(instance)
  File "/home/ramachandra/.local/lib/python3.8/site-packages/django/urls/resolvers.py", line 715, in url_patterns
    patterns = getattr(self.urlconf_module, "urlpatterns", self.urlconf_module)
  File "/home/ramachandra/.local/lib/python3.8/site-packages/django/utils/functional.py", line 57, in __get__
    res = instance.__dict__[self.name] = self.func(instance)
  File "/home/ramachandra/.local/lib/python3.8/site-packages/django/urls/resolvers.py", line 708, in urlconf_module
    return import_module(self.urlconf_name)
  File "/usr/lib/python3.8/importlib/__init__.py", line 127, in import_module
    return _bootstrap._gcd_import(name[level:], package, level)
  File "<frozen importlib._bootstrap>", line 1014, in _gcd_import
  File "<frozen importlib._bootstrap>", line 991, in _find_and_load
  File "<frozen importlib._bootstrap>", line 975, in _find_and_load_unlocked
  File "<frozen importlib._bootstrap>", line 671, in _load_unlocked
  File "<frozen importlib._bootstrap_external>", line 848, in exec_module
  File "<frozen importlib._bootstrap>", line 219, in _call_with_frames_removed
  File "/home/ramachandra/movies/movies/urls.py", line 21, in <module>
    path('app1/',include('app1.urls')),
  File "/home/ramachandra/.local/lib/python3.8/site-packages/django/urls/conf.py", line 38, in include
    urlconf_module = import_module(urlconf_module)
  File "/usr/lib/python3.8/importlib/__init__.py", line 127, in import_module
    return _bootstrap._gcd_import(name[level:], package, level)
  File "<frozen importlib._bootstrap>", line 1014, in _gcd_import
  File "<frozen importlib._bootstrap>", line 991, in _find_and_load
  File "<frozen importlib._bootstrap>", line 975, in _find_and_load_unlocked
  File "<frozen importlib._bootstrap>", line 671, in _load_unlocked
  File "<frozen importlib._bootstrap_external>", line 848, in exec_module
  File "<frozen importlib._bootstrap>", line 219, in _call_with_frames_removed
  File "/home/ramachandra/movies/app1/urls.py", line 3, in <module>
    from .views import upload_file,search_items,land,login_view,logout_view,home,movie_detail
  File "/home/ramachandra/movies/app1/views.py", line 53, in <module>
    profile(req)
NameError: name 'profile' is not defined
/home/ramachandra/movies/app1/views.py changed, reloading.
Watching for file changes with StatReloader
Performing system checks...

Exception in thread django-main-thread:
Traceback (most recent call last):
  File "/usr/lib/python3.8/threading.py", line 932, in _bootstrap_inner
    self.run()
  File "/usr/lib/python3.8/threading.py", line 870, in run
    self._target(*self._args, **self._kwargs)
  File "/home/ramachandra/.local/lib/python3.8/site-packages/django/utils/autoreload.py", line 64, in wrapper
    fn(*args, **kwargs)
  File "/home/ramachandra/.local/lib/python3.8/site-packages/django/core/management/commands/runserver.py", line 133, in inner_run
    self.check(display_num_errors=True)
  File "/home/ramachandra/.local/lib/python3.8/site-packages/django/core/management/base.py", line 485, in check
    all_issues = checks.run_checks(
  File "/home/ramachandra/.local/lib/python3.8/site-packages/django/core/checks/registry.py", line 88, in run_checks
    new_errors = check(app_configs=app_configs, databases=databases)
  File "/home/ramachandra/.local/lib/python3.8/site-packages/django/core/checks/urls.py", line 14, in check_url_config
    return check_resolver(resolver)
  File "/home/ramachandra/.local/lib/python3.8/site-packages/django/core/checks/urls.py", line 24, in check_resolver
    return check_method()
  File "/home/ramachandra/.local/lib/python3.8/site-packages/django/urls/resolvers.py", line 494, in check
    for pattern in self.url_patterns:
  File "/home/ramachandra/.local/lib/python3.8/site-packages/django/utils/functional.py", line 57, in __get__
    res = instance.__dict__[self.name] = self.func(instance)
  File "/home/ramachandra/.local/lib/python3.8/site-packages/django/urls/resolvers.py", line 715, in url_patterns
    patterns = getattr(self.urlconf_module, "urlpatterns", self.urlconf_module)
  File "/home/ramachandra/.local/lib/python3.8/site-packages/django/utils/functional.py", line 57, in __get__
    res = instance.__dict__[self.name] = self.func(instance)
  File "/home/ramachandra/.local/lib/python3.8/site-packages/django/urls/resolvers.py", line 708, in urlconf_module
    return import_module(self.urlconf_name)
  File "/usr/lib/python3.8/importlib/__init__.py", line 127, in import_module
    return _bootstrap._gcd_import(name[level:], package, level)
  File "<frozen importlib._bootstrap>", line 1014, in _gcd_import
  File "<frozen importlib._bootstrap>", line 991, in _find_and_load
  File "<frozen importlib._bootstrap>", line 975, in _find_and_load_unlocked
  File "<frozen importlib._bootstrap>", line 671, in _load_unlocked
  File "<frozen importlib._bootstrap_external>", line 848, in exec_module
  File "<frozen importlib._bootstrap>", line 219, in _call_with_frames_removed
  File "/home/ramachandra/movies/movies/urls.py", line 21, in <module>
    path('app1/',include('app1.urls')),
  File "/home/ramachandra/.local/lib/python3.8/site-packages/django/urls/conf.py", line 38, in include
    urlconf_module = import_module(urlconf_module)
  File "/usr/lib/python3.8/importlib/__init__.py", line 127, in import_module
    return _bootstrap._gcd_import(name[level:], package, level)
  File "<frozen importlib._bootstrap>", line 1014, in _gcd_import
  File "<frozen importlib._bootstrap>", line 991, in _find_and_load
  File "<frozen importlib._bootstrap>", line 975, in _find_and_load_unlocked
  File "<frozen importlib._bootstrap>", line 671, in _load_unlocked
  File "<frozen importlib._bootstrap_external>", line 848, in exec_module
  File "<frozen importlib._bootstrap>", line 219, in _call_with_frames_removed
  File "/home/ramachandra/movies/app1/urls.py", line 3, in <module>
    from .views import upload_file,search_items,land,login_view,logout_view,home,movie_detail
  File "/home/ramachandra/movies/app1/views.py", line 53
    profile(request):
                    ^
SyntaxError: invalid syntax
/home/ramachandra/movies/app1/views.py changed, reloading.
Watching for file changes with StatReloader
Performing system checks...

Exception in thread django-main-thread:
Traceback (most recent call last):
  File "/usr/lib/python3.8/threading.py", line 932, in _bootstrap_inner
    self.run()
  File "/usr/lib/python3.8/threading.py", line 870, in run
    self._target(*self._args, **self._kwargs)
  File "/home/ramachandra/.local/lib/python3.8/site-packages/django/utils/autoreload.py", line 64, in wrapper
    fn(*args, **kwargs)
  File "/home/ramachandra/.local/lib/python3.8/site-packages/django/core/management/commands/runserver.py", line 133, in inner_run
    self.check(display_num_errors=True)
  File "/home/ramachandra/.local/lib/python3.8/site-packages/django/core/management/base.py", line 485, in check
    all_issues = checks.run_checks(
  File "/home/ramachandra/.local/lib/python3.8/site-packages/django/core/checks/registry.py", line 88, in run_checks
    new_errors = check(app_configs=app_configs, databases=databases)
  File "/home/ramachandra/.local/lib/python3.8/site-packages/django/core/checks/urls.py", line 14, in check_url_config
    return check_resolver(resolver)
  File "/home/ramachandra/.local/lib/python3.8/site-packages/django/core/checks/urls.py", line 24, in check_resolver
    return check_method()
  File "/home/ramachandra/.local/lib/python3.8/site-packages/django/urls/resolvers.py", line 494, in check
    for pattern in self.url_patterns:
  File "/home/ramachandra/.local/lib/python3.8/site-packages/django/utils/functional.py", line 57, in __get__
    res = instance.__dict__[self.name] = self.func(instance)
  File "/home/ramachandra/.local/lib/python3.8/site-packages/django/urls/resolvers.py", line 715, in url_patterns
    patterns = getattr(self.urlconf_module, "urlpatterns", self.urlconf_module)
  File "/home/ramachandra/.local/lib/python3.8/site-packages/django/utils/functional.py", line 57, in __get__
    res = instance.__dict__[self.name] = self.func(instance)
  File "/home/ramachandra/.local/lib/python3.8/site-packages/django/urls/resolvers.py", line 708, in urlconf_module
    return import_module(self.urlconf_name)
  File "/usr/lib/python3.8/importlib/__init__.py", line 127, in import_module
    return _bootstrap._gcd_import(name[level:], package, level)
  File "<frozen importlib._bootstrap>", line 1014, in _gcd_import
  File "<frozen importlib._bootstrap>", line 991, in _find_and_load
  File "<frozen importlib._bootstrap>", line 975, in _find_and_load_unlocked
  File "<frozen importlib._bootstrap>", line 671, in _load_unlocked
  File "<frozen importlib._bootstrap_external>", line 848, in exec_module
  File "<frozen importlib._bootstrap>", line 219, in _call_with_frames_removed
  File "/home/ramachandra/movies/movies/urls.py", line 21, in <module>
    path('app1/',include('app1.urls')),
  File "/home/ramachandra/.local/lib/python3.8/site-packages/django/urls/conf.py", line 38, in include
    urlconf_module = import_module(urlconf_module)
  File "/usr/lib/python3.8/importlib/__init__.py", line 127, in import_module
    return _bootstrap._gcd_import(name[level:], package, level)
  File "<frozen importlib._bootstrap>", line 1014, in _gcd_import
  File "<frozen importlib._bootstrap>", line 991, in _find_and_load
  File "<frozen importlib._bootstrap>", line 975, in _find_and_load_unlocked
  File "<frozen importlib._bootstrap>", line 671, in _load_unlocked
  File "<frozen importlib._bootstrap_external>", line 848, in exec_module
  File "<frozen importlib._bootstrap>", line 219, in _call_with_frames_removed
  File "/home/ramachandra/movies/app1/urls.py", line 3, in <module>
    from .views import upload_file,search_items,land,login_view,logout_view,home,movie_detail
  File "/home/ramachandra/movies/app1/views.py", line 54
    def logout_view(request):
    ^
IndentationError: expected an indented block
/home/ramachandra/movies/app1/views.py changed, reloading.
Watching for file changes with StatReloader
Performing system checks...

System check identified no issues (0 silenced).
May 19, 2024 - 07:41:13
Django version 4.2.13, using settings 'movies.settings'
Starting development server at http://0.0.0.0:3000/
Quit the server with CONTROL-C.

/home/ramachandra/movies/app1/views.py changed, reloading.
Watching for file changes with StatReloader
Performing system checks...

System check identified no issues (0 silenced).
May 19, 2024 - 07:41:16
Django version 4.2.13, using settings 'movies.settings'
Starting development server at http://0.0.0.0:3000/
Quit the server with CONTROL-C.

/home/ramachandra/movies/app1/views.py changed, reloading.
Watching for file changes with StatReloader
Performing system checks...

System check identified no issues (0 silenced).
May 19, 2024 - 07:41:18
Django version 4.2.13, using settings 'movies.settings'
Starting development server at http://0.0.0.0:3000/
Quit the server with CONTROL-C.

Internal Server Error: /app1/home
Traceback (most recent call last):
  File "/home/ramachandra/.local/lib/python3.8/site-packages/django/core/handlers/exception.py", line 55, in inner
    response = get_response(request)
  File "/home/ramachandra/.local/lib/python3.8/site-packages/django/core/handlers/base.py", line 197, in _get_response
    response = wrapped_callback(request, *callback_args, **callback_kwargs)
  File "/home/ramachandra/movies/app1/views.py", line 25, in home
    return render(request, 'app1/home.html',{'movies': list(random_movies.values('id','title', 'image', 'date', 'gener', 'rating', 'description'))})
  File "/home/ramachandra/.local/lib/python3.8/site-packages/django/shortcuts.py", line 24, in render
    content = loader.render_to_string(template_name, context, request, using=using)
  File "/home/ramachandra/.local/lib/python3.8/site-packages/django/template/loader.py", line 62, in render_to_string
    return template.render(context, request)
  File "/home/ramachandra/.local/lib/python3.8/site-packages/django/template/backends/django.py", line 61, in render
    return self.template.render(context)
  File "/home/ramachandra/.local/lib/python3.8/site-packages/django/template/base.py", line 175, in render
    return self._render(context)
  File "/home/ramachandra/.local/lib/python3.8/site-packages/django/template/base.py", line 167, in _render
    return self.nodelist.render(context)
  File "/home/ramachandra/.local/lib/python3.8/site-packages/django/template/base.py", line 1005, in render
    return SafeString("".join([node.render_annotated(context) for node in self]))
  File "/home/ramachandra/.local/lib/python3.8/site-packages/django/template/base.py", line 1005, in <listcomp>
    return SafeString("".join([node.render_annotated(context) for node in self]))
  File "/home/ramachandra/.local/lib/python3.8/site-packages/django/template/base.py", line 966, in render_annotated
    return self.render(context)
  File "/home/ramachandra/.local/lib/python3.8/site-packages/django/template/defaulttags.py", line 471, in render
    url = reverse(view_name, args=args, kwargs=kwargs, current_app=current_app)
  File "/home/ramachandra/.local/lib/python3.8/site-packages/django/urls/base.py", line 88, in reverse
    return resolver._reverse_with_prefix(view, prefix, *args, **kwargs)
  File "/home/ramachandra/.local/lib/python3.8/site-packages/django/urls/resolvers.py", line 828, in _reverse_with_prefix
    raise NoReverseMatch(msg)
django.urls.exceptions.NoReverseMatch: Reverse for 'profile' not found. 'profile' is not a valid view function or pattern name.
[19/May/2024 07:42:11] "GET /app1/home HTTP/1.1" 500 160648
/home/ramachandra/movies/app1/urls.py changed, reloading.
Watching for file changes with StatReloader
Performing system checks...

System check identified no issues (0 silenced).
May 19, 2024 - 07:42:19
Django version 4.2.13, using settings 'movies.settings'
Starting development server at http://0.0.0.0:3000/
Quit the server with CONTROL-C.

/home/ramachandra/movies/app1/urls.py changed, reloading.
Watching for file changes with StatReloader
Performing system checks...

System check identified no issues (0 silenced).
May 19, 2024 - 07:42:22
Django version 4.2.13, using settings 'movies.settings'
Starting development server at http://0.0.0.0:3000/
Quit the server with CONTROL-C.

/home/ramachandra/movies/app1/urls.py changed, reloading.
Watching for file changes with StatReloader
Performing system checks...

System check identified no issues (0 silenced).
May 19, 2024 - 07:42:27
Django version 4.2.13, using settings 'movies.settings'
Starting development server at http://0.0.0.0:3000/
Quit the server with CONTROL-C.

/home/ramachandra/movies/app1/urls.py changed, reloading.
Watching for file changes with StatReloader
Performing system checks...

System check identified no issues (0 silenced).
May 19, 2024 - 07:42:31
Django version 4.2.13, using settings 'movies.settings'
Starting development server at http://0.0.0.0:3000/
Quit the server with CONTROL-C.

/home/ramachandra/movies/app1/urls.py changed, reloading.
Watching for file changes with StatReloader
Performing system checks...

System check identified no issues (0 silenced).
May 19, 2024 - 07:42:35
Django version 4.2.13, using settings 'movies.settings'
Starting development server at http://0.0.0.0:3000/
Quit the server with CONTROL-C.

/home/ramachandra/movies/app1/urls.py changed, reloading.
Watching for file changes with StatReloader
Performing system checks...

System check identified no issues (0 silenced).
May 19, 2024 - 07:42:37
Django version 4.2.13, using settings 'movies.settings'
Starting development server at http://0.0.0.0:3000/
Quit the server with CONTROL-C.

[19/May/2024 07:42:38] "GET /app1/home HTTP/1.1" 200 17482
[19/May/2024 07:42:44] "GET /app1/out HTTP/1.1" 302 0
[19/May/2024 07:42:44] "GET /app1/login HTTP/1.1" 200 4205
[19/May/2024 07:42:49] "POST /app1/login HTTP/1.1" 302 0
[19/May/2024 07:42:49] "GET /app1/home HTTP/1.1" 200 18800
/home/ramachandra/movies/app1/views.py changed, reloading.
Watching for file changes with StatReloader
Performing system checks...

System check identified no issues (0 silenced).
May 19, 2024 - 07:43:04
Django version 4.2.13, using settings 'movies.settings'
Starting development server at http://0.0.0.0:3000/
Quit the server with CONTROL-C.

/home/ramachandra/movies/app1/views.py changed, reloading.
Watching for file changes with StatReloader
Performing system checks...

System check identified no issues (0 silenced).
May 19, 2024 - 07:43:07
Django version 4.2.13, using settings 'movies.settings'
Starting development server at http://0.0.0.0:3000/
Quit the server with CONTROL-C.

/home/ramachandra/movies/app1/views.py changed, reloading.
Watching for file changes with StatReloader
Performing system checks...

Exception in thread django-main-thread:
Traceback (most recent call last):
  File "/usr/lib/python3.8/threading.py", line 932, in _bootstrap_inner
    self.run()
  File "/usr/lib/python3.8/threading.py", line 870, in run
    self._target(*self._args, **self._kwargs)
  File "/home/ramachandra/.local/lib/python3.8/site-packages/django/utils/autoreload.py", line 64, in wrapper
    fn(*args, **kwargs)
  File "/home/ramachandra/.local/lib/python3.8/site-packages/django/core/management/commands/runserver.py", line 133, in inner_run
    self.check(display_num_errors=True)
  File "/home/ramachandra/.local/lib/python3.8/site-packages/django/core/management/base.py", line 485, in check
    all_issues = checks.run_checks(
  File "/home/ramachandra/.local/lib/python3.8/site-packages/django/core/checks/registry.py", line 88, in run_checks
    new_errors = check(app_configs=app_configs, databases=databases)
  File "/home/ramachandra/.local/lib/python3.8/site-packages/django/core/checks/urls.py", line 14, in check_url_config
    return check_resolver(resolver)
  File "/home/ramachandra/.local/lib/python3.8/site-packages/django/core/checks/urls.py", line 24, in check_resolver
    return check_method()
  File "/home/ramachandra/.local/lib/python3.8/site-packages/django/urls/resolvers.py", line 494, in check
    for pattern in self.url_patterns:
  File "/home/ramachandra/.local/lib/python3.8/site-packages/django/utils/functional.py", line 57, in __get__
    res = instance.__dict__[self.name] = self.func(instance)
  File "/home/ramachandra/.local/lib/python3.8/site-packages/django/urls/resolvers.py", line 715, in url_patterns
    patterns = getattr(self.urlconf_module, "urlpatterns", self.urlconf_module)
  File "/home/ramachandra/.local/lib/python3.8/site-packages/django/utils/functional.py", line 57, in __get__
    res = instance.__dict__[self.name] = self.func(instance)
  File "/home/ramachandra/.local/lib/python3.8/site-packages/django/urls/resolvers.py", line 708, in urlconf_module
    return import_module(self.urlconf_name)
  File "/usr/lib/python3.8/importlib/__init__.py", line 127, in import_module
    return _bootstrap._gcd_import(name[level:], package, level)
  File "<frozen importlib._bootstrap>", line 1014, in _gcd_import
  File "<frozen importlib._bootstrap>", line 991, in _find_and_load
  File "<frozen importlib._bootstrap>", line 975, in _find_and_load_unlocked
  File "<frozen importlib._bootstrap>", line 671, in _load_unlocked
  File "<frozen importlib._bootstrap_external>", line 848, in exec_module
  File "<frozen importlib._bootstrap>", line 219, in _call_with_frames_removed
  File "/home/ramachandra/movies/movies/urls.py", line 21, in <module>
    path('app1/',include('app1.urls')),
  File "/home/ramachandra/.local/lib/python3.8/site-packages/django/urls/conf.py", line 38, in include
    urlconf_module = import_module(urlconf_module)
  File "/usr/lib/python3.8/importlib/__init__.py", line 127, in import_module
    return _bootstrap._gcd_import(name[level:], package, level)
  File "<frozen importlib._bootstrap>", line 1014, in _gcd_import
  File "<frozen importlib._bootstrap>", line 991, in _find_and_load
  File "<frozen importlib._bootstrap>", line 975, in _find_and_load_unlocked
  File "<frozen importlib._bootstrap>", line 671, in _load_unlocked
  File "<frozen importlib._bootstrap_external>", line 848, in exec_module
  File "<frozen importlib._bootstrap>", line 219, in _call_with_frames_removed
  File "/home/ramachandra/movies/app1/urls.py", line 3, in <module>
    from .views import upload_file,search_items,land,login_view,logout_view,home,movie_detail,profile
  File "/home/ramachandra/movies/app1/views.py", line 27
    random_movies=Movies.objects.filter(gener__icontains="Action").order_by('?')[:15]
    ^
IndentationError: expected an indented block
/home/ramachandra/movies/app1/views.py changed, reloading.
Watching for file changes with StatReloader
Performing system checks...

System check identified no issues (0 silenced).
May 19, 2024 - 07:43:27
Django version 4.2.13, using settings 'movies.settings'
Starting development server at http://0.0.0.0:3000/
Quit the server with CONTROL-C.

/home/ramachandra/movies/app1/views.py changed, reloading.
Watching for file changes with StatReloader
Performing system checks...

System check identified no issues (0 silenced).
May 19, 2024 - 07:43:31
Django version 4.2.13, using settings 'movies.settings'
Starting development server at http://0.0.0.0:3000/
Quit the server with CONTROL-C.

[19/May/2024 07:43:33] "GET /app1/out HTTP/1.1" 302 0
[19/May/2024 07:43:33] "GET /app1/login HTTP/1.1" 200 4205
[19/May/2024 07:43:38] "GET /app1/home HTTP/1.1" 302 0
[19/May/2024 07:43:38] "GET /app1/login HTTP/1.1" 200 4205
[19/May/2024 07:43:43] "GET /app1/home HTTP/1.1" 302 0
[19/May/2024 07:43:44] "GET /app1/login HTTP/1.1" 200 4205
[19/May/2024 07:43:50] "POST /app1/login HTTP/1.1" 302 0
[19/May/2024 07:43:50] "GET /app1/home HTTP/1.1" 200 19034
/home/ramachandra/movies/app1/views.py changed, reloading.
Watching for file changes with StatReloader
Performing system checks...

System check identified no issues (0 silenced).
May 19, 2024 - 07:44:24
Django version 4.2.13, using settings 'movies.settings'
Starting development server at http://0.0.0.0:3000/
Quit the server with CONTROL-C.

/home/ramachandra/movies/app1/views.py changed, reloading.
Watching for file changes with StatReloader
Performing system checks...

System check identified no issues (0 silenced).
May 19, 2024 - 07:44:27
Django version 4.2.13, using settings 'movies.settings'
Starting development server at http://0.0.0.0:3000/
Quit the server with CONTROL-C.

/home/ramachandra/movies/app1/views.py changed, reloading.
Watching for file changes with StatReloader
Performing system checks...

System check identified no issues (0 silenced).
May 19, 2024 - 07:44:34
Django version 4.2.13, using settings 'movies.settings'
Starting development server at http://0.0.0.0:3000/
Quit the server with CONTROL-C.

/home/ramachandra/movies/app1/views.py changed, reloading.
Watching for file changes with StatReloader
Performing system checks...

System check identified no issues (0 silenced).
May 19, 2024 - 07:44:37
Django version 4.2.13, using settings 'movies.settings'
Starting development server at http://0.0.0.0:3000/
Quit the server with CONTROL-C.

/home/ramachandra/movies/app1/views.py changed, reloading.
Watching for file changes with StatReloader
Performing system checks...

Exception in thread django-main-thread:
Traceback (most recent call last):
  File "/usr/lib/python3.8/threading.py", line 932, in _bootstrap_inner
    self.run()
  File "/usr/lib/python3.8/threading.py", line 870, in run
    self._target(*self._args, **self._kwargs)
  File "/home/ramachandra/.local/lib/python3.8/site-packages/django/utils/autoreload.py", line 64, in wrapper
    fn(*args, **kwargs)
  File "/home/ramachandra/.local/lib/python3.8/site-packages/django/core/management/commands/runserver.py", line 133, in inner_run
    self.check(display_num_errors=True)
  File "/home/ramachandra/.local/lib/python3.8/site-packages/django/core/management/base.py", line 485, in check
    all_issues = checks.run_checks(
  File "/home/ramachandra/.local/lib/python3.8/site-packages/django/core/checks/registry.py", line 88, in run_checks
    new_errors = check(app_configs=app_configs, databases=databases)
  File "/home/ramachandra/.local/lib/python3.8/site-packages/django/core/checks/urls.py", line 14, in check_url_config
    return check_resolver(resolver)
  File "/home/ramachandra/.local/lib/python3.8/site-packages/django/core/checks/urls.py", line 24, in check_resolver
    return check_method()
  File "/home/ramachandra/.local/lib/python3.8/site-packages/django/urls/resolvers.py", line 494, in check
    for pattern in self.url_patterns:
  File "/home/ramachandra/.local/lib/python3.8/site-packages/django/utils/functional.py", line 57, in __get__
    res = instance.__dict__[self.name] = self.func(instance)
  File "/home/ramachandra/.local/lib/python3.8/site-packages/django/urls/resolvers.py", line 715, in url_patterns
    patterns = getattr(self.urlconf_module, "urlpatterns", self.urlconf_module)
  File "/home/ramachandra/.local/lib/python3.8/site-packages/django/utils/functional.py", line 57, in __get__
    res = instance.__dict__[self.name] = self.func(instance)
  File "/home/ramachandra/.local/lib/python3.8/site-packages/django/urls/resolvers.py", line 708, in urlconf_module
    return import_module(self.urlconf_name)
  File "/usr/lib/python3.8/importlib/__init__.py", line 127, in import_module
    return _bootstrap._gcd_import(name[level:], package, level)
  File "<frozen importlib._bootstrap>", line 1014, in _gcd_import
  File "<frozen importlib._bootstrap>", line 991, in _find_and_load
  File "<frozen importlib._bootstrap>", line 975, in _find_and_load_unlocked
  File "<frozen importlib._bootstrap>", line 671, in _load_unlocked
  File "<frozen importlib._bootstrap_external>", line 848, in exec_module
  File "<frozen importlib._bootstrap>", line 219, in _call_with_frames_removed
  File "/home/ramachandra/movies/movies/urls.py", line 21, in <module>
    path('app1/',include('app1.urls')),
  File "/home/ramachandra/.local/lib/python3.8/site-packages/django/urls/conf.py", line 38, in include
    urlconf_module = import_module(urlconf_module)
  File "/usr/lib/python3.8/importlib/__init__.py", line 127, in import_module
    return _bootstrap._gcd_import(name[level:], package, level)
  File "<frozen importlib._bootstrap>", line 1014, in _gcd_import
  File "<frozen importlib._bootstrap>", line 991, in _find_and_load
  File "<frozen importlib._bootstrap>", line 975, in _find_and_load_unlocked
  File "<frozen importlib._bootstrap>", line 671, in _load_unlocked
  File "<frozen importlib._bootstrap_external>", line 848, in exec_module
  File "<frozen importlib._bootstrap>", line 219, in _call_with_frames_removed
  File "/home/ramachandra/movies/app1/urls.py", line 3, in <module>
    from .views import upload_file,search_items,land,login_view,logout_view,home,movie_detail,profile
  File "/home/ramachandra/movies/app1/views.py", line 58
    user=
        ^
SyntaxError: invalid syntax
/home/ramachandra/movies/app1/views.py changed, reloading.
Watching for file changes with StatReloader
Performing system checks...

System check identified no issues (0 silenced).
May 19, 2024 - 07:44:41
Django version 4.2.13, using settings 'movies.settings'
Starting development server at http://0.0.0.0:3000/
Quit the server with CONTROL-C.

/home/ramachandra/movies/app1/views.py changed, reloading.
Watching for file changes with StatReloader
Performing system checks...

System check identified no issues (0 silenced).
May 19, 2024 - 07:44:44
Django version 4.2.13, using settings 'movies.settings'
Starting development server at http://0.0.0.0:3000/
Quit the server with CONTROL-C.

/home/ramachandra/movies/app1/views.py changed, reloading.
Watching for file changes with StatReloader
Performing system checks...

System check identified no issues (0 silenced).
May 19, 2024 - 07:44:46
Django version 4.2.13, using settings 'movies.settings'
Starting development server at http://0.0.0.0:3000/
Quit the server with CONTROL-C.

/home/ramachandra/movies/app1/views.py changed, reloading.
Watching for file changes with StatReloader
Performing system checks...

System check identified no issues (0 silenced).
May 19, 2024 - 07:44:48
Django version 4.2.13, using settings 'movies.settings'
Starting development server at http://0.0.0.0:3000/
Quit the server with CONTROL-C.

/home/ramachandra/movies/app1/views.py changed, reloading.
Watching for file changes with StatReloader
Performing system checks...

System check identified no issues (0 silenced).
May 19, 2024 - 07:45:05
Django version 4.2.13, using settings 'movies.settings'
Starting development server at http://0.0.0.0:3000/
Quit the server with CONTROL-C.

/home/ramachandra/movies/app1/views.py changed, reloading.
Watching for file changes with StatReloader
Performing system checks...

System check identified no issues (0 silenced).
May 19, 2024 - 07:45:09
Django version 4.2.13, using settings 'movies.settings'
Starting development server at http://0.0.0.0:3000/
Quit the server with CONTROL-C.

/home/ramachandra/movies/app1/views.py changed, reloading.
Watching for file changes with StatReloader
Performing system checks...

System check identified no issues (0 silenced).
May 19, 2024 - 07:45:11
Django version 4.2.13, using settings 'movies.settings'
Starting development server at http://0.0.0.0:3000/
Quit the server with CONTROL-C.

/home/ramachandra/movies/app1/views.py changed, reloading.
Watching for file changes with StatReloader
Performing system checks...

System check identified no issues (0 silenced).
May 19, 2024 - 07:45:13
Django version 4.2.13, using settings 'movies.settings'
Starting development server at http://0.0.0.0:3000/
Quit the server with CONTROL-C.

/home/ramachandra/movies/app1/views.py changed, reloading.
Watching for file changes with StatReloader
Performing system checks...

System check identified no issues (0 silenced).
May 19, 2024 - 07:45:16
Django version 4.2.13, using settings 'movies.settings'
Starting development server at http://0.0.0.0:3000/
Quit the server with CONTROL-C.

/home/ramachandra/movies/app1/views.py changed, reloading.
Watching for file changes with StatReloader
Performing system checks...

System check identified no issues (0 silenced).
May 19, 2024 - 07:45:19
Django version 4.2.13, using settings 'movies.settings'
Starting development server at http://0.0.0.0:3000/
Quit the server with CONTROL-C.

/home/ramachandra/movies/app1/views.py changed, reloading.
Watching for file changes with StatReloader
Performing system checks...

Exception in thread django-main-thread:
Traceback (most recent call last):
  File "/usr/lib/python3.8/threading.py", line 932, in _bootstrap_inner
    self.run()
  File "/usr/lib/python3.8/threading.py", line 870, in run
    self._target(*self._args, **self._kwargs)
  File "/home/ramachandra/.local/lib/python3.8/site-packages/django/utils/autoreload.py", line 64, in wrapper
    fn(*args, **kwargs)
  File "/home/ramachandra/.local/lib/python3.8/site-packages/django/core/management/commands/runserver.py", line 133, in inner_run
    self.check(display_num_errors=True)
  File "/home/ramachandra/.local/lib/python3.8/site-packages/django/core/management/base.py", line 485, in check
    all_issues = checks.run_checks(
  File "/home/ramachandra/.local/lib/python3.8/site-packages/django/core/checks/registry.py", line 88, in run_checks
    new_errors = check(app_configs=app_configs, databases=databases)
  File "/home/ramachandra/.local/lib/python3.8/site-packages/django/core/checks/urls.py", line 14, in check_url_config
    return check_resolver(resolver)
  File "/home/ramachandra/.local/lib/python3.8/site-packages/django/core/checks/urls.py", line 24, in check_resolver
    return check_method()
  File "/home/ramachandra/.local/lib/python3.8/site-packages/django/urls/resolvers.py", line 494, in check
    for pattern in self.url_patterns:
  File "/home/ramachandra/.local/lib/python3.8/site-packages/django/utils/functional.py", line 57, in __get__
    res = instance.__dict__[self.name] = self.func(instance)
  File "/home/ramachandra/.local/lib/python3.8/site-packages/django/urls/resolvers.py", line 715, in url_patterns
    patterns = getattr(self.urlconf_module, "urlpatterns", self.urlconf_module)
  File "/home/ramachandra/.local/lib/python3.8/site-packages/django/utils/functional.py", line 57, in __get__
    res = instance.__dict__[self.name] = self.func(instance)
  File "/home/ramachandra/.local/lib/python3.8/site-packages/django/urls/resolvers.py", line 708, in urlconf_module
    return import_module(self.urlconf_name)
  File "/usr/lib/python3.8/importlib/__init__.py", line 127, in import_module
    return _bootstrap._gcd_import(name[level:], package, level)
  File "<frozen importlib._bootstrap>", line 1014, in _gcd_import
  File "<frozen importlib._bootstrap>", line 991, in _find_and_load
  File "<frozen importlib._bootstrap>", line 975, in _find_and_load_unlocked
  File "<frozen importlib._bootstrap>", line 671, in _load_unlocked
  File "<frozen importlib._bootstrap_external>", line 848, in exec_module
  File "<frozen importlib._bootstrap>", line 219, in _call_with_frames_removed
  File "/home/ramachandra/movies/movies/urls.py", line 21, in <module>
    path('app1/',include('app1.urls')),
  File "/home/ramachandra/.local/lib/python3.8/site-packages/django/urls/conf.py", line 38, in include
    urlconf_module = import_module(urlconf_module)
  File "/usr/lib/python3.8/importlib/__init__.py", line 127, in import_module
    return _bootstrap._gcd_import(name[level:], package, level)
  File "<frozen importlib._bootstrap>", line 1014, in _gcd_import
  File "<frozen importlib._bootstrap>", line 991, in _find_and_load
  File "<frozen importlib._bootstrap>", line 975, in _find_and_load_unlocked
  File "<frozen importlib._bootstrap>", line 671, in _load_unlocked
  File "<frozen importlib._bootstrap_external>", line 848, in exec_module
  File "<frozen importlib._bootstrap>", line 219, in _call_with_frames_removed
  File "/home/ramachandra/movies/app1/urls.py", line 3, in <module>
    from .views import upload_file,search_items,land,login_view,logout_view,home,movie_detail,profile
  File "/home/ramachandra/movies/app1/views.py", line 59
    return render(request=requestm")
                                   ^
SyntaxError: EOL while scanning string literal
/home/ramachandra/movies/app1/views.py changed, reloading.
Watching for file changes with StatReloader
Performing system checks...

Exception in thread django-main-thread:
Traceback (most recent call last):
  File "/usr/lib/python3.8/threading.py", line 932, in _bootstrap_inner
    self.run()
  File "/usr/lib/python3.8/threading.py", line 870, in run
    self._target(*self._args, **self._kwargs)
  File "/home/ramachandra/.local/lib/python3.8/site-packages/django/utils/autoreload.py", line 64, in wrapper
    fn(*args, **kwargs)
  File "/home/ramachandra/.local/lib/python3.8/site-packages/django/core/management/commands/runserver.py", line 133, in inner_run
    self.check(display_num_errors=True)
  File "/home/ramachandra/.local/lib/python3.8/site-packages/django/core/management/base.py", line 485, in check
    all_issues = checks.run_checks(
  File "/home/ramachandra/.local/lib/python3.8/site-packages/django/core/checks/registry.py", line 88, in run_checks
    new_errors = check(app_configs=app_configs, databases=databases)
  File "/home/ramachandra/.local/lib/python3.8/site-packages/django/core/checks/urls.py", line 14, in check_url_config
    return check_resolver(resolver)
  File "/home/ramachandra/.local/lib/python3.8/site-packages/django/core/checks/urls.py", line 24, in check_resolver
    return check_method()
  File "/home/ramachandra/.local/lib/python3.8/site-packages/django/urls/resolvers.py", line 494, in check
    for pattern in self.url_patterns:
  File "/home/ramachandra/.local/lib/python3.8/site-packages/django/utils/functional.py", line 57, in __get__
    res = instance.__dict__[self.name] = self.func(instance)
  File "/home/ramachandra/.local/lib/python3.8/site-packages/django/urls/resolvers.py", line 715, in url_patterns
    patterns = getattr(self.urlconf_module, "urlpatterns", self.urlconf_module)
  File "/home/ramachandra/.local/lib/python3.8/site-packages/django/utils/functional.py", line 57, in __get__
    res = instance.__dict__[self.name] = self.func(instance)
  File "/home/ramachandra/.local/lib/python3.8/site-packages/django/urls/resolvers.py", line 708, in urlconf_module
    return import_module(self.urlconf_name)
  File "/usr/lib/python3.8/importlib/__init__.py", line 127, in import_module
    return _bootstrap._gcd_import(name[level:], package, level)
  File "<frozen importlib._bootstrap>", line 1014, in _gcd_import
  File "<frozen importlib._bootstrap>", line 991, in _find_and_load
  File "<frozen importlib._bootstrap>", line 975, in _find_and_load_unlocked
  File "<frozen importlib._bootstrap>", line 671, in _load_unlocked
  File "<frozen importlib._bootstrap_external>", line 848, in exec_module
  File "<frozen importlib._bootstrap>", line 219, in _call_with_frames_removed
  File "/home/ramachandra/movies/movies/urls.py", line 21, in <module>
    path('app1/',include('app1.urls')),
  File "/home/ramachandra/.local/lib/python3.8/site-packages/django/urls/conf.py", line 38, in include
    urlconf_module = import_module(urlconf_module)
  File "/usr/lib/python3.8/importlib/__init__.py", line 127, in import_module
    return _bootstrap._gcd_import(name[level:], package, level)
  File "<frozen importlib._bootstrap>", line 1014, in _gcd_import
  File "<frozen importlib._bootstrap>", line 991, in _find_and_load
  File "<frozen importlib._bootstrap>", line 975, in _find_and_load_unlocked
  File "<frozen importlib._bootstrap>", line 671, in _load_unlocked
  File "<frozen importlib._bootstrap_external>", line 848, in exec_module
  File "<frozen importlib._bootstrap>", line 219, in _call_with_frames_removed
  File "/home/ramachandra/movies/app1/urls.py", line 3, in <module>
    from .views import upload_file,search_items,land,login_view,logout_view,home,movie_detail,profile
  File "/home/ramachandra/movies/app1/views.py", line 59
    return render(request=request,")
                                   ^
SyntaxError: EOL while scanning string literal
/home/ramachandra/movies/app1/views.py changed, reloading.
Watching for file changes with StatReloader
Performing system checks...

Exception in thread django-main-thread:
Traceback (most recent call last):
  File "/usr/lib/python3.8/threading.py", line 932, in _bootstrap_inner
    self.run()
  File "/usr/lib/python3.8/threading.py", line 870, in run
    self._target(*self._args, **self._kwargs)
  File "/home/ramachandra/.local/lib/python3.8/site-packages/django/utils/autoreload.py", line 64, in wrapper
    fn(*args, **kwargs)
  File "/home/ramachandra/.local/lib/python3.8/site-packages/django/core/management/commands/runserver.py", line 133, in inner_run
    self.check(display_num_errors=True)
  File "/home/ramachandra/.local/lib/python3.8/site-packages/django/core/management/base.py", line 485, in check
    all_issues = checks.run_checks(
  File "/home/ramachandra/.local/lib/python3.8/site-packages/django/core/checks/registry.py", line 88, in run_checks
    new_errors = check(app_configs=app_configs, databases=databases)
  File "/home/ramachandra/.local/lib/python3.8/site-packages/django/core/checks/urls.py", line 14, in check_url_config
    return check_resolver(resolver)
  File "/home/ramachandra/.local/lib/python3.8/site-packages/django/core/checks/urls.py", line 24, in check_resolver
    return check_method()
  File "/home/ramachandra/.local/lib/python3.8/site-packages/django/urls/resolvers.py", line 494, in check
    for pattern in self.url_patterns:
  File "/home/ramachandra/.local/lib/python3.8/site-packages/django/utils/functional.py", line 57, in __get__
    res = instance.__dict__[self.name] = self.func(instance)
  File "/home/ramachandra/.local/lib/python3.8/site-packages/django/urls/resolvers.py", line 715, in url_patterns
    patterns = getattr(self.urlconf_module, "urlpatterns", self.urlconf_module)
  File "/home/ramachandra/.local/lib/python3.8/site-packages/django/utils/functional.py", line 57, in __get__
    res = instance.__dict__[self.name] = self.func(instance)
  File "/home/ramachandra/.local/lib/python3.8/site-packages/django/urls/resolvers.py", line 708, in urlconf_module
    return import_module(self.urlconf_name)
  File "/usr/lib/python3.8/importlib/__init__.py", line 127, in import_module
    return _bootstrap._gcd_import(name[level:], package, level)
  File "<frozen importlib._bootstrap>", line 1014, in _gcd_import
  File "<frozen importlib._bootstrap>", line 991, in _find_and_load
  File "<frozen importlib._bootstrap>", line 975, in _find_and_load_unlocked
  File "<frozen importlib._bootstrap>", line 671, in _load_unlocked
  File "<frozen importlib._bootstrap_external>", line 848, in exec_module
  File "<frozen importlib._bootstrap>", line 219, in _call_with_frames_removed
  File "/home/ramachandra/movies/movies/urls.py", line 21, in <module>
    path('app1/',include('app1.urls')),
  File "/home/ramachandra/.local/lib/python3.8/site-packages/django/urls/conf.py", line 38, in include
    urlconf_module = import_module(urlconf_module)
  File "/usr/lib/python3.8/importlib/__init__.py", line 127, in import_module
    return _bootstrap._gcd_import(name[level:], package, level)
  File "<frozen importlib._bootstrap>", line 1014, in _gcd_import
  File "<frozen importlib._bootstrap>", line 991, in _find_and_load
  File "<frozen importlib._bootstrap>", line 975, in _find_and_load_unlocked
  File "<frozen importlib._bootstrap>", line 671, in _load_unlocked
  File "<frozen importlib._bootstrap_external>", line 848, in exec_module
  File "<frozen importlib._bootstrap>", line 219, in _call_with_frames_removed
  File "/home/ramachandra/movies/app1/urls.py", line 3, in <module>
    from .views import upload_file,search_items,land,login_view,logout_view,home,movie_detail,profile
  File "/home/ramachandra/movies/app1/views.py", line 59
    return render(request=request,"")
                                  ^
SyntaxError: positional argument follows keyword argument
/home/ramachandra/movies/app1/views.py changed, reloading.
Watching for file changes with StatReloader
Performing system checks...

Exception in thread django-main-thread:
Traceback (most recent call last):
  File "/usr/lib/python3.8/threading.py", line 932, in _bootstrap_inner
    self.run()
  File "/usr/lib/python3.8/threading.py", line 870, in run
    self._target(*self._args, **self._kwargs)
  File "/home/ramachandra/.local/lib/python3.8/site-packages/django/utils/autoreload.py", line 64, in wrapper
    fn(*args, **kwargs)
  File "/home/ramachandra/.local/lib/python3.8/site-packages/django/core/management/commands/runserver.py", line 133, in inner_run
    self.check(display_num_errors=True)
  File "/home/ramachandra/.local/lib/python3.8/site-packages/django/core/management/base.py", line 485, in check
    all_issues = checks.run_checks(
  File "/home/ramachandra/.local/lib/python3.8/site-packages/django/core/checks/registry.py", line 88, in run_checks
    new_errors = check(app_configs=app_configs, databases=databases)
  File "/home/ramachandra/.local/lib/python3.8/site-packages/django/core/checks/urls.py", line 14, in check_url_config
    return check_resolver(resolver)
  File "/home/ramachandra/.local/lib/python3.8/site-packages/django/core/checks/urls.py", line 24, in check_resolver
    return check_method()
  File "/home/ramachandra/.local/lib/python3.8/site-packages/django/urls/resolvers.py", line 494, in check
    for pattern in self.url_patterns:
  File "/home/ramachandra/.local/lib/python3.8/site-packages/django/utils/functional.py", line 57, in __get__
    res = instance.__dict__[self.name] = self.func(instance)
  File "/home/ramachandra/.local/lib/python3.8/site-packages/django/urls/resolvers.py", line 715, in url_patterns
    patterns = getattr(self.urlconf_module, "urlpatterns", self.urlconf_module)
  File "/home/ramachandra/.local/lib/python3.8/site-packages/django/utils/functional.py", line 57, in __get__
    res = instance.__dict__[self.name] = self.func(instance)
  File "/home/ramachandra/.local/lib/python3.8/site-packages/django/urls/resolvers.py", line 708, in urlconf_module
    return import_module(self.urlconf_name)
  File "/usr/lib/python3.8/importlib/__init__.py", line 127, in import_module
    return _bootstrap._gcd_import(name[level:], package, level)
  File "<frozen importlib._bootstrap>", line 1014, in _gcd_import
  File "<frozen importlib._bootstrap>", line 991, in _find_and_load
  File "<frozen importlib._bootstrap>", line 975, in _find_and_load_unlocked
  File "<frozen importlib._bootstrap>", line 671, in _load_unlocked
  File "<frozen importlib._bootstrap_external>", line 848, in exec_module
  File "<frozen importlib._bootstrap>", line 219, in _call_with_frames_removed
  File "/home/ramachandra/movies/movies/urls.py", line 21, in <module>
    path('app1/',include('app1.urls')),
  File "/home/ramachandra/.local/lib/python3.8/site-packages/django/urls/conf.py", line 38, in include
    urlconf_module = import_module(urlconf_module)
  File "/usr/lib/python3.8/importlib/__init__.py", line 127, in import_module
    return _bootstrap._gcd_import(name[level:], package, level)
  File "<frozen importlib._bootstrap>", line 1014, in _gcd_import
  File "<frozen importlib._bootstrap>", line 991, in _find_and_load
  File "<frozen importlib._bootstrap>", line 975, in _find_and_load_unlocked
  File "<frozen importlib._bootstrap>", line 671, in _load_unlocked
  File "<frozen importlib._bootstrap_external>", line 848, in exec_module
  File "<frozen importlib._bootstrap>", line 219, in _call_with_frames_removed
  File "/home/ramachandra/movies/app1/urls.py", line 3, in <module>
    from .views import upload_file,search_items,land,login_view,logout_view,home,movie_detail,profile
  File "/home/ramachandra/movies/app1/views.py", line 59
    return render(request=request,""m{})
                                    ^
SyntaxError: invalid syntax
/home/ramachandra/movies/app1/views.py changed, reloading.
Watching for file changes with StatReloader
Performing system checks...

Exception in thread django-main-thread:
Traceback (most recent call last):
  File "/usr/lib/python3.8/threading.py", line 932, in _bootstrap_inner
    self.run()
  File "/usr/lib/python3.8/threading.py", line 870, in run
    self._target(*self._args, **self._kwargs)
  File "/home/ramachandra/.local/lib/python3.8/site-packages/django/utils/autoreload.py", line 64, in wrapper
    fn(*args, **kwargs)
  File "/home/ramachandra/.local/lib/python3.8/site-packages/django/core/management/commands/runserver.py", line 133, in inner_run
    self.check(display_num_errors=True)
  File "/home/ramachandra/.local/lib/python3.8/site-packages/django/core/management/base.py", line 485, in check
    all_issues = checks.run_checks(
  File "/home/ramachandra/.local/lib/python3.8/site-packages/django/core/checks/registry.py", line 88, in run_checks
    new_errors = check(app_configs=app_configs, databases=databases)
  File "/home/ramachandra/.local/lib/python3.8/site-packages/django/core/checks/urls.py", line 14, in check_url_config
    return check_resolver(resolver)
  File "/home/ramachandra/.local/lib/python3.8/site-packages/django/core/checks/urls.py", line 24, in check_resolver
    return check_method()
  File "/home/ramachandra/.local/lib/python3.8/site-packages/django/urls/resolvers.py", line 494, in check
    for pattern in self.url_patterns:
  File "/home/ramachandra/.local/lib/python3.8/site-packages/django/utils/functional.py", line 57, in __get__
    res = instance.__dict__[self.name] = self.func(instance)
  File "/home/ramachandra/.local/lib/python3.8/site-packages/django/urls/resolvers.py", line 715, in url_patterns
    patterns = getattr(self.urlconf_module, "urlpatterns", self.urlconf_module)
  File "/home/ramachandra/.local/lib/python3.8/site-packages/django/utils/functional.py", line 57, in __get__
    res = instance.__dict__[self.name] = self.func(instance)
  File "/home/ramachandra/.local/lib/python3.8/site-packages/django/urls/resolvers.py", line 708, in urlconf_module
    return import_module(self.urlconf_name)
  File "/usr/lib/python3.8/importlib/__init__.py", line 127, in import_module
    return _bootstrap._gcd_import(name[level:], package, level)
  File "<frozen importlib._bootstrap>", line 1014, in _gcd_import
  File "<frozen importlib._bootstrap>", line 991, in _find_and_load
  File "<frozen importlib._bootstrap>", line 975, in _find_and_load_unlocked
  File "<frozen importlib._bootstrap>", line 671, in _load_unlocked
  File "<frozen importlib._bootstrap_external>", line 848, in exec_module
  File "<frozen importlib._bootstrap>", line 219, in _call_with_frames_removed
  File "/home/ramachandra/movies/movies/urls.py", line 21, in <module>
    path('app1/',include('app1.urls')),
  File "/home/ramachandra/.local/lib/python3.8/site-packages/django/urls/conf.py", line 38, in include
    urlconf_module = import_module(urlconf_module)
  File "/usr/lib/python3.8/importlib/__init__.py", line 127, in import_module
    return _bootstrap._gcd_import(name[level:], package, level)
  File "<frozen importlib._bootstrap>", line 1014, in _gcd_import
  File "<frozen importlib._bootstrap>", line 991, in _find_and_load
  File "<frozen importlib._bootstrap>", line 975, in _find_and_load_unlocked
  File "<frozen importlib._bootstrap>", line 671, in _load_unlocked
  File "<frozen importlib._bootstrap_external>", line 848, in exec_module
  File "<frozen importlib._bootstrap>", line 219, in _call_with_frames_removed
  File "/home/ramachandra/movies/app1/urls.py", line 3, in <module>
    from .views import upload_file,search_items,land,login_view,logout_view,home,movie_detail,profile
  File "/home/ramachandra/movies/app1/views.py", line 59
    return render(request=request,""{})
                                    ^
SyntaxError: invalid syntax
/home/ramachandra/movies/app1/views.py changed, reloading.
Watching for file changes with StatReloader
Performing system checks...

Exception in thread django-main-thread:
Traceback (most recent call last):
  File "/usr/lib/python3.8/threading.py", line 932, in _bootstrap_inner
    self.run()
  File "/usr/lib/python3.8/threading.py", line 870, in run
    self._target(*self._args, **self._kwargs)
  File "/home/ramachandra/.local/lib/python3.8/site-packages/django/utils/autoreload.py", line 64, in wrapper
    fn(*args, **kwargs)
  File "/home/ramachandra/.local/lib/python3.8/site-packages/django/core/management/commands/runserver.py", line 133, in inner_run
    self.check(display_num_errors=True)
  File "/home/ramachandra/.local/lib/python3.8/site-packages/django/core/management/base.py", line 485, in check
    all_issues = checks.run_checks(
  File "/home/ramachandra/.local/lib/python3.8/site-packages/django/core/checks/registry.py", line 88, in run_checks
    new_errors = check(app_configs=app_configs, databases=databases)
  File "/home/ramachandra/.local/lib/python3.8/site-packages/django/core/checks/urls.py", line 14, in check_url_config
    return check_resolver(resolver)
  File "/home/ramachandra/.local/lib/python3.8/site-packages/django/core/checks/urls.py", line 24, in check_resolver
    return check_method()
  File "/home/ramachandra/.local/lib/python3.8/site-packages/django/urls/resolvers.py", line 494, in check
    for pattern in self.url_patterns:
  File "/home/ramachandra/.local/lib/python3.8/site-packages/django/utils/functional.py", line 57, in __get__
    res = instance.__dict__[self.name] = self.func(instance)
  File "/home/ramachandra/.local/lib/python3.8/site-packages/django/urls/resolvers.py", line 715, in url_patterns
    patterns = getattr(self.urlconf_module, "urlpatterns", self.urlconf_module)
  File "/home/ramachandra/.local/lib/python3.8/site-packages/django/utils/functional.py", line 57, in __get__
    res = instance.__dict__[self.name] = self.func(instance)
  File "/home/ramachandra/.local/lib/python3.8/site-packages/django/urls/resolvers.py", line 708, in urlconf_module
    return import_module(self.urlconf_name)
  File "/usr/lib/python3.8/importlib/__init__.py", line 127, in import_module
    return _bootstrap._gcd_import(name[level:], package, level)
  File "<frozen importlib._bootstrap>", line 1014, in _gcd_import
  File "<frozen importlib._bootstrap>", line 991, in _find_and_load
  File "<frozen importlib._bootstrap>", line 975, in _find_and_load_unlocked
  File "<frozen importlib._bootstrap>", line 671, in _load_unlocked
  File "<frozen importlib._bootstrap_external>", line 848, in exec_module
  File "<frozen importlib._bootstrap>", line 219, in _call_with_frames_removed
  File "/home/ramachandra/movies/movies/urls.py", line 21, in <module>
    path('app1/',include('app1.urls')),
  File "/home/ramachandra/.local/lib/python3.8/site-packages/django/urls/conf.py", line 38, in include
    urlconf_module = import_module(urlconf_module)
  File "/usr/lib/python3.8/importlib/__init__.py", line 127, in import_module
    return _bootstrap._gcd_import(name[level:], package, level)
  File "<frozen importlib._bootstrap>", line 1014, in _gcd_import
  File "<frozen importlib._bootstrap>", line 991, in _find_and_load
  File "<frozen importlib._bootstrap>", line 975, in _find_and_load_unlocked
  File "<frozen importlib._bootstrap>", line 671, in _load_unlocked
  File "<frozen importlib._bootstrap_external>", line 848, in exec_module
  File "<frozen importlib._bootstrap>", line 219, in _call_with_frames_removed
  File "/home/ramachandra/movies/app1/urls.py", line 3, in <module>
    from .views import upload_file,search_items,land,login_view,logout_view,home,movie_detail,profile
  File "/home/ramachandra/movies/app1/views.py", line 59
    return render(request=request,""{"user":user})
                                    ^
SyntaxError: invalid syntax
/home/ramachandra/movies/app1/views.py changed, reloading.
Watching for file changes with StatReloader
Performing system checks...

Exception in thread django-main-thread:
Traceback (most recent call last):
  File "/usr/lib/python3.8/threading.py", line 932, in _bootstrap_inner
    self.run()
  File "/usr/lib/python3.8/threading.py", line 870, in run
    self._target(*self._args, **self._kwargs)
  File "/home/ramachandra/.local/lib/python3.8/site-packages/django/utils/autoreload.py", line 64, in wrapper
    fn(*args, **kwargs)
  File "/home/ramachandra/.local/lib/python3.8/site-packages/django/core/management/commands/runserver.py", line 133, in inner_run
    self.check(display_num_errors=True)
  File "/home/ramachandra/.local/lib/python3.8/site-packages/django/core/management/base.py", line 485, in check
    all_issues = checks.run_checks(
  File "/home/ramachandra/.local/lib/python3.8/site-packages/django/core/checks/registry.py", line 88, in run_checks
    new_errors = check(app_configs=app_configs, databases=databases)
  File "/home/ramachandra/.local/lib/python3.8/site-packages/django/core/checks/urls.py", line 14, in check_url_config
    return check_resolver(resolver)
  File "/home/ramachandra/.local/lib/python3.8/site-packages/django/core/checks/urls.py", line 24, in check_resolver
    return check_method()
  File "/home/ramachandra/.local/lib/python3.8/site-packages/django/urls/resolvers.py", line 494, in check
    for pattern in self.url_patterns:
  File "/home/ramachandra/.local/lib/python3.8/site-packages/django/utils/functional.py", line 57, in __get__
    res = instance.__dict__[self.name] = self.func(instance)
  File "/home/ramachandra/.local/lib/python3.8/site-packages/django/urls/resolvers.py", line 715, in url_patterns
    patterns = getattr(self.urlconf_module, "urlpatterns", self.urlconf_module)
  File "/home/ramachandra/.local/lib/python3.8/site-packages/django/utils/functional.py", line 57, in __get__
    res = instance.__dict__[self.name] = self.func(instance)
  File "/home/ramachandra/.local/lib/python3.8/site-packages/django/urls/resolvers.py", line 708, in urlconf_module
    return import_module(self.urlconf_name)
  File "/usr/lib/python3.8/importlib/__init__.py", line 127, in import_module
    return _bootstrap._gcd_import(name[level:], package, level)
  File "<frozen importlib._bootstrap>", line 1014, in _gcd_import
  File "<frozen importlib._bootstrap>", line 991, in _find_and_load
  File "<frozen importlib._bootstrap>", line 975, in _find_and_load_unlocked
  File "<frozen importlib._bootstrap>", line 671, in _load_unlocked
  File "<frozen importlib._bootstrap_external>", line 848, in exec_module
  File "<frozen importlib._bootstrap>", line 219, in _call_with_frames_removed
  File "/home/ramachandra/movies/movies/urls.py", line 21, in <module>
    path('app1/',include('app1.urls')),
  File "/home/ramachandra/.local/lib/python3.8/site-packages/django/urls/conf.py", line 38, in include
    urlconf_module = import_module(urlconf_module)
  File "/usr/lib/python3.8/importlib/__init__.py", line 127, in import_module
    return _bootstrap._gcd_import(name[level:], package, level)
  File "<frozen importlib._bootstrap>", line 1014, in _gcd_import
  File "<frozen importlib._bootstrap>", line 991, in _find_and_load
  File "<frozen importlib._bootstrap>", line 975, in _find_and_load_unlocked
  File "<frozen importlib._bootstrap>", line 671, in _load_unlocked
  File "<frozen importlib._bootstrap_external>", line 848, in exec_module
  File "<frozen importlib._bootstrap>", line 219, in _call_with_frames_removed
  File "/home/ramachandra/movies/app1/urls.py", line 3, in <module>
    from .views import upload_file,search_items,land,login_view,logout_view,home,movie_detail,profile
  File "/home/ramachandra/movies/app1/views.py", line 59
    return render(request=request,"",{"user":user})
                                  ^
SyntaxError: positional argument follows keyword argument
/home/ramachandra/movies/app1/views.py changed, reloading.
Watching for file changes with StatReloader
Performing system checks...

Exception in thread django-main-thread:
Traceback (most recent call last):
  File "/usr/lib/python3.8/threading.py", line 932, in _bootstrap_inner
    self.run()
  File "/usr/lib/python3.8/threading.py", line 870, in run
    self._target(*self._args, **self._kwargs)
  File "/home/ramachandra/.local/lib/python3.8/site-packages/django/utils/autoreload.py", line 64, in wrapper
    fn(*args, **kwargs)
  File "/home/ramachandra/.local/lib/python3.8/site-packages/django/core/management/commands/runserver.py", line 133, in inner_run
    self.check(display_num_errors=True)
  File "/home/ramachandra/.local/lib/python3.8/site-packages/django/core/management/base.py", line 485, in check
    all_issues = checks.run_checks(
  File "/home/ramachandra/.local/lib/python3.8/site-packages/django/core/checks/registry.py", line 88, in run_checks
    new_errors = check(app_configs=app_configs, databases=databases)
  File "/home/ramachandra/.local/lib/python3.8/site-packages/django/core/checks/urls.py", line 14, in check_url_config
    return check_resolver(resolver)
  File "/home/ramachandra/.local/lib/python3.8/site-packages/django/core/checks/urls.py", line 24, in check_resolver
    return check_method()
  File "/home/ramachandra/.local/lib/python3.8/site-packages/django/urls/resolvers.py", line 494, in check
    for pattern in self.url_patterns:
  File "/home/ramachandra/.local/lib/python3.8/site-packages/django/utils/functional.py", line 57, in __get__
    res = instance.__dict__[self.name] = self.func(instance)
  File "/home/ramachandra/.local/lib/python3.8/site-packages/django/urls/resolvers.py", line 715, in url_patterns
    patterns = getattr(self.urlconf_module, "urlpatterns", self.urlconf_module)
  File "/home/ramachandra/.local/lib/python3.8/site-packages/django/utils/functional.py", line 57, in __get__
    res = instance.__dict__[self.name] = self.func(instance)
  File "/home/ramachandra/.local/lib/python3.8/site-packages/django/urls/resolvers.py", line 708, in urlconf_module
    return import_module(self.urlconf_name)
  File "/usr/lib/python3.8/importlib/__init__.py", line 127, in import_module
    return _bootstrap._gcd_import(name[level:], package, level)
  File "<frozen importlib._bootstrap>", line 1014, in _gcd_import
  File "<frozen importlib._bootstrap>", line 991, in _find_and_load
  File "<frozen importlib._bootstrap>", line 975, in _find_and_load_unlocked
  File "<frozen importlib._bootstrap>", line 671, in _load_unlocked
  File "<frozen importlib._bootstrap_external>", line 848, in exec_module
  File "<frozen importlib._bootstrap>", line 219, in _call_with_frames_removed
  File "/home/ramachandra/movies/movies/urls.py", line 21, in <module>
    path('app1/',include('app1.urls')),
  File "/home/ramachandra/.local/lib/python3.8/site-packages/django/urls/conf.py", line 38, in include
    urlconf_module = import_module(urlconf_module)
  File "/usr/lib/python3.8/importlib/__init__.py", line 127, in import_module
    return _bootstrap._gcd_import(name[level:], package, level)
  File "<frozen importlib._bootstrap>", line 1014, in _gcd_import
  File "<frozen importlib._bootstrap>", line 991, in _find_and_load
  File "<frozen importlib._bootstrap>", line 975, in _find_and_load_unlocked
  File "<frozen importlib._bootstrap>", line 671, in _load_unlocked
  File "<frozen importlib._bootstrap_external>", line 848, in exec_module
  File "<frozen importlib._bootstrap>", line 219, in _call_with_frames_removed
  File "/home/ramachandra/movies/app1/urls.py", line 3, in <module>
    from .views import upload_file,search_items,land,login_view,logout_view,home,movie_detail,profile
  File "/home/ramachandra/movies/app1/views.py", line 59
    return render(request=request,"app1/",{"user":user})
                                  ^
SyntaxError: positional argument follows keyword argument
/home/ramachandra/movies/app1/views.py changed, reloading.
Watching for file changes with StatReloader
Performing system checks...

Exception in thread django-main-thread:
Traceback (most recent call last):
  File "/usr/lib/python3.8/threading.py", line 932, in _bootstrap_inner
    self.run()
  File "/usr/lib/python3.8/threading.py", line 870, in run
    self._target(*self._args, **self._kwargs)
  File "/home/ramachandra/.local/lib/python3.8/site-packages/django/utils/autoreload.py", line 64, in wrapper
    fn(*args, **kwargs)
  File "/home/ramachandra/.local/lib/python3.8/site-packages/django/core/management/commands/runserver.py", line 133, in inner_run
    self.check(display_num_errors=True)
  File "/home/ramachandra/.local/lib/python3.8/site-packages/django/core/management/base.py", line 485, in check
    all_issues = checks.run_checks(
  File "/home/ramachandra/.local/lib/python3.8/site-packages/django/core/checks/registry.py", line 88, in run_checks
    new_errors = check(app_configs=app_configs, databases=databases)
  File "/home/ramachandra/.local/lib/python3.8/site-packages/django/core/checks/urls.py", line 14, in check_url_config
    return check_resolver(resolver)
  File "/home/ramachandra/.local/lib/python3.8/site-packages/django/core/checks/urls.py", line 24, in check_resolver
    return check_method()
  File "/home/ramachandra/.local/lib/python3.8/site-packages/django/urls/resolvers.py", line 494, in check
    for pattern in self.url_patterns:
  File "/home/ramachandra/.local/lib/python3.8/site-packages/django/utils/functional.py", line 57, in __get__
    res = instance.__dict__[self.name] = self.func(instance)
  File "/home/ramachandra/.local/lib/python3.8/site-packages/django/urls/resolvers.py", line 715, in url_patterns
    patterns = getattr(self.urlconf_module, "urlpatterns", self.urlconf_module)
  File "/home/ramachandra/.local/lib/python3.8/site-packages/django/utils/functional.py", line 57, in __get__
    res = instance.__dict__[self.name] = self.func(instance)
  File "/home/ramachandra/.local/lib/python3.8/site-packages/django/urls/resolvers.py", line 708, in urlconf_module
    return import_module(self.urlconf_name)
  File "/usr/lib/python3.8/importlib/__init__.py", line 127, in import_module
    return _bootstrap._gcd_import(name[level:], package, level)
  File "<frozen importlib._bootstrap>", line 1014, in _gcd_import
  File "<frozen importlib._bootstrap>", line 991, in _find_and_load
  File "<frozen importlib._bootstrap>", line 975, in _find_and_load_unlocked
  File "<frozen importlib._bootstrap>", line 671, in _load_unlocked
  File "<frozen importlib._bootstrap_external>", line 848, in exec_module
  File "<frozen importlib._bootstrap>", line 219, in _call_with_frames_removed
  File "/home/ramachandra/movies/movies/urls.py", line 21, in <module>
    path('app1/',include('app1.urls')),
  File "/home/ramachandra/.local/lib/python3.8/site-packages/django/urls/conf.py", line 38, in include
    urlconf_module = import_module(urlconf_module)
  File "/usr/lib/python3.8/importlib/__init__.py", line 127, in import_module
    return _bootstrap._gcd_import(name[level:], package, level)
  File "<frozen importlib._bootstrap>", line 1014, in _gcd_import
  File "<frozen importlib._bootstrap>", line 991, in _find_and_load
  File "<frozen importlib._bootstrap>", line 975, in _find_and_load_unlocked
  File "<frozen importlib._bootstrap>", line 671, in _load_unlocked
  File "<frozen importlib._bootstrap_external>", line 848, in exec_module
  File "<frozen importlib._bootstrap>", line 219, in _call_with_frames_removed
  File "/home/ramachandra/movies/app1/urls.py", line 3, in <module>
    from .views import upload_file,search_items,land,login_view,logout_view,home,movie_detail,profile
  File "/home/ramachandra/movies/app1/views.py", line 59
    return render(request=request,"app1/profile.html",{"user":user})
                                  ^
SyntaxError: positional argument follows keyword argument
/home/ramachandra/movies/app1/views.py changed, reloading.
Watching for file changes with StatReloader
Performing system checks...

System check identified no issues (0 silenced).
May 19, 2024 - 07:46:18
Django version 4.2.13, using settings 'movies.settings'
Starting development server at http://0.0.0.0:3000/
Quit the server with CONTROL-C.

/home/ramachandra/movies/app1/views.py changed, reloading.
Watching for file changes with StatReloader
Performing system checks...

System check identified no issues (0 silenced).
May 19, 2024 - 07:46:20
Django version 4.2.13, using settings 'movies.settings'
Starting development server at http://0.0.0.0:3000/
Quit the server with CONTROL-C.

/home/ramachandra/movies/app1/views.py changed, reloading.
Watching for file changes with StatReloader
Performing system checks...

System check identified no issues (0 silenced).
May 19, 2024 - 07:46:26
Django version 4.2.13, using settings 'movies.settings'
Starting development server at http://0.0.0.0:3000/
Quit the server with CONTROL-C.

[19/May/2024 07:46:47] "GET /app1/home HTTP/1.1" 200 17877
[19/May/2024 07:46:49] "GET /app1/profile HTTP/1.1" 200 239
[19/May/2024 07:46:58] "GET /app1/profile HTTP/1.1" 200 256
[19/May/2024 07:48:35] "GET /app1/home HTTP/1.1" 200 18882
[19/May/2024 07:51:55] code 400, message Bad request version ('\x02â9\x15¢ç\x15Èb\xad\x97MHÂÔ®\x95üç@d¦á0#\x00°\x8d\x8b^\x07Þ¡<.\x17\x86\x04\x8d')
[19/May/2024 07:51:55] You're accessing the development server over HTTPS, but it only supports HTTP.
[19/May/2024 07:51:55] code 400, message Bad request version ('\x16§¨\x83')
[19/May/2024 07:51:55] You're accessing the development server over HTTPS, but it only supports HTTP.
[19/May/2024 07:51:55] "GET /app1/ HTTP/1.1" 200 26936
[19/May/2024 07:51:57] "GET /app1/ HTTP/1.1" 200 26595
Not Found: /favicon.ico
[19/May/2024 07:51:57] "GET /favicon.ico HTTP/1.1" 404 2219
[19/May/2024 07:51:57] code 400, message Bad request version ("qr\x81\x9cÓ'\x00")
[19/May/2024 07:51:57] You're accessing the development server over HTTPS, but it only supports HTTP.
[19/May/2024 07:51:57] code 400, message Bad request version ('À\x13À')
[19/May/2024 07:51:57] You're accessing the development server over HTTPS, but it only supports HTTP.
[19/May/2024 07:51:57] code 400, message Bad request version ('ÚÚ\x13\x01\x13\x02\x13\x03À+À/À,À0Ì©Ì¨À\x13À\x14\x00\x9c\x00\x9d\x00/\x005\x01\x00\x01\x93')
[19/May/2024 07:51:57] You're accessing the development server over HTTPS, but it only supports HTTP.
[19/May/2024 07:52:10] "GET /app1/ajax/search/?query=A HTTP/1.1" 200 11874
[19/May/2024 07:52:11] "GET /app1/ajax/search/?query=Ak HTTP/1.1" 200 11944
Not Found: /app1/nan
[19/May/2024 07:52:11] "GET /app1/nan HTTP/1.1" 404 3526
[19/May/2024 07:52:17] "GET /app1/movie_detail/242 HTTP/1.1" 301 0
[19/May/2024 07:52:17] code 400, message Bad request version ('w\x00')
[19/May/2024 07:52:17] You're accessing the development server over HTTPS, but it only supports HTTP.
[19/May/2024 07:52:17] "GET /app1/movie_detail/242/ HTTP/1.1" 302 0
[19/May/2024 07:52:17] code 400, message Bad request version ('\x00\x12\x00\x10\x04\x03\x08\x04\x04\x01\x05\x03\x08\x05\x05\x01\x08\x06\x06\x01Di\x00\x05\x00\x03\x02h2\x003\x00+\x00)')
[19/May/2024 07:52:17] You're accessing the development server over HTTPS, but it only supports HTTP.
[19/May/2024 07:52:17] "GET /app1/login HTTP/1.1" 200 4205
[19/May/2024 07:52:35] "POST /app1/login HTTP/1.1" 302 0
[19/May/2024 07:52:35] "GET /app1/home HTTP/1.1" 200 17494
[19/May/2024 07:52:56] "GET /app1/profile HTTP/1.1" 200 256
[19/May/2024 07:53:00] "GET /app1/out HTTP/1.1" 302 0
[19/May/2024 07:53:00] "GET /app1/login HTTP/1.1" 200 4205
Forbidden (CSRF token missing.): /app1/login
[19/May/2024 08:01:16] "POST /app1/login HTTP/1.1" 403 2506
Not Found: /favicon.ico
[19/May/2024 08:01:17] "GET /favicon.ico HTTP/1.1" 404 2219
[19/May/2024 08:01:21] "GET /app1/login HTTP/1.1" 200 4205
[19/May/2024 08:01:31] "GET /app1/movie_detail/1666/ HTTP/1.1" 302 0
[19/May/2024 08:01:31] "GET /app1/login HTTP/1.1" 200 4205
[19/May/2024 08:02:01] "GET /app1/movie_detail/1768/ HTTP/1.1" 302 0
[19/May/2024 08:02:01] "GET /app1/login HTTP/1.1" 200 4205
[19/May/2024 08:02:05] "GET /app1/movie_detail/1064/ HTTP/1.1" 302 0
[19/May/2024 08:02:05] "GET /app1/login HTTP/1.1" 200 4205
Internal Server Error: /app1/login
Traceback (most recent call last):
  File "/home/ramachandra/.local/lib/python3.8/site-packages/django/core/handlers/exception.py", line 55, in inner
    response = get_response(request)
  File "/home/ramachandra/.local/lib/python3.8/site-packages/django/core/handlers/base.py", line 197, in _get_response
    response = wrapped_callback(request, *callback_args, **callback_kwargs)
  File "/home/ramachandra/movies/app1/views.py", line 47, in login_view
    login(request, user)
  File "/home/ramachandra/.local/lib/python3.8/site-packages/django/contrib/auth/__init__.py", line 138, in login
    request.session[SESSION_KEY] = user._meta.pk.value_to_string(user)
  File "/home/ramachandra/.local/lib/python3.8/site-packages/django/utils/functional.py", line 268, in inner
    return func(_wrapped, *args)
AttributeError: 'AnonymousUser' object has no attribute '_meta'
[19/May/2024 08:02:25] "POST /app1/login HTTP/1.1" 500 71994
[19/May/2024 08:16:05] "GET /app1/home HTTP/1.1" 200 18553
[19/May/2024 08:16:08] "GET /app1/login HTTP/1.1" 200 4205
[19/May/2024 08:16:14] "POST /app1/login HTTP/1.1" 302 0
[19/May/2024 08:16:14] "GET /app1/home HTTP/1.1" 200 18146
[19/May/2024 08:21:07] "POST /app1/login HTTP/1.1" 200 4596
[19/May/2024 08:21:29] "POST /app1/login HTTP/1.1" 200 4470
[19/May/2024 08:21:43] "POST /app1/login HTTP/1.1" 200 4459
Internal Server Error: /app1/login
Traceback (most recent call last):
  File "/home/ramachandra/.local/lib/python3.8/site-packages/django/core/handlers/exception.py", line 55, in inner
    response = get_response(request)
  File "/home/ramachandra/.local/lib/python3.8/site-packages/django/core/handlers/base.py", line 197, in _get_response
    response = wrapped_callback(request, *callback_args, **callback_kwargs)
  File "/home/ramachandra/movies/app1/views.py", line 47, in login_view
    login(request, user)
  File "/home/ramachandra/.local/lib/python3.8/site-packages/django/contrib/auth/__init__.py", line 138, in login
    request.session[SESSION_KEY] = user._meta.pk.value_to_string(user)
  File "/home/ramachandra/.local/lib/python3.8/site-packages/django/utils/functional.py", line 268, in inner
    return func(_wrapped, *args)
AttributeError: 'AnonymousUser' object has no attribute '_meta'
[19/May/2024 08:22:04] "POST /app1/login HTTP/1.1" 500 71989
[19/May/2024 08:22:34] "GET /app1/ HTTP/1.1" 200 26670
[19/May/2024 08:22:37] "GET /app1/login HTTP/1.1" 200 4205
Internal Server Error: /app1/login
Traceback (most recent call last):
  File "/home/ramachandra/.local/lib/python3.8/site-packages/django/core/handlers/exception.py", line 55, in inner
    response = get_response(request)
  File "/home/ramachandra/.local/lib/python3.8/site-packages/django/core/handlers/base.py", line 197, in _get_response
    response = wrapped_callback(request, *callback_args, **callback_kwargs)
  File "/home/ramachandra/movies/app1/views.py", line 47, in login_view
    login(request, user)
  File "/home/ramachandra/.local/lib/python3.8/site-packages/django/contrib/auth/__init__.py", line 138, in login
    request.session[SESSION_KEY] = user._meta.pk.value_to_string(user)
  File "/home/ramachandra/.local/lib/python3.8/site-packages/django/utils/functional.py", line 268, in inner
    return func(_wrapped, *args)
AttributeError: 'AnonymousUser' object has no attribute '_meta'
[19/May/2024 08:22:53] "POST /app1/login HTTP/1.1" 500 71986
[19/May/2024 08:25:02] "GET /app1/movie_detail/5140/ HTTP/1.1" 302 0
[19/May/2024 08:25:02] "GET /app1/login HTTP/1.1" 200 4205
[19/May/2024 08:25:12] "GET /app1/movie_detail/1666/ HTTP/1.1" 302 0
[19/May/2024 08:25:12] "GET /app1/login HTTP/1.1" 200 4205
[19/May/2024 08:25:42] "POST /app1/login HTTP/1.1" 302 0
[19/May/2024 08:25:43] "GET /app1/home HTTP/1.1" 200 17701
2021-October-30
[19/May/2024 08:25:48] "GET /app1/movie_detail/1666/ HTTP/1.1" 200 4442
1986-May-16
[19/May/2024 08:26:11] "GET /app1/movie_detail/1681/ HTTP/1.1" 200 4365
2011-September-27
[19/May/2024 08:26:19] "GET /app1/movie_detail/837/ HTTP/1.1" 200 4073
2020-August-14
[19/May/2024 08:26:32] "GET /app1/movie_detail/4298/ HTTP/1.1" 200 4027
[19/May/2024 08:26:41] "GET /app1/ajax/search/?query=E HTTP/1.1" 200 11597
[19/May/2024 08:27:13] "GET /app1/ HTTP/1.1" 200 27767
[19/May/2024 08:27:40] "GET /app1/ajax/search/?query=G HTTP/1.1" 200 10978
[19/May/2024 08:27:47] "GET /app1/ajax/search/?query=Q HTTP/1.1" 200 13362
[19/May/2024 08:28:10] "GET /app1/ajax/search/?query=S HTTP/1.1" 200 12121
[19/May/2024 08:28:10] "GET /app1/ajax/search/?query=Su HTTP/1.1" 200 12946
[19/May/2024 08:28:10] "GET /app1/ajax/search/?query=Sup HTTP/1.1" 200 14230
[19/May/2024 08:28:10] "GET /app1/ajax/search/?query=Supe HTTP/1.1" 200 14071
[19/May/2024 08:28:11] "GET /app1/ajax/search/?query=Super HTTP/1.1" 200 14071
[19/May/2024 08:28:57,210] - Broken pipe from ('152.58.239.144', 60592)
1992-May-22
[19/May/2024 08:29:04] "GET /app1/movie_detail/2742/ HTTP/1.1" 200 4249
[19/May/2024 08:29:36] "GET /app1/login HTTP/1.1" 200 4205
[19/May/2024 08:29:39] "GET /app1/login HTTP/1.1" 200 4205
[19/May/2024 08:29:47] "GET /app1/login HTTP/1.1" 200 4205
2021-August-23
[19/May/2024 08:29:51] "GET /app1/movie_detail/3367/ HTTP/1.1" 200 4045
[19/May/2024 08:30:03] "GET /app1/movie_detail/214 HTTP/1.1" 301 0
2016-March-23
[19/May/2024 08:30:03] "GET /app1/movie_detail/214/ HTTP/1.1" 200 4274
2016-March-23
[19/May/2024 08:30:07] "GET /app1/movie_detail/214/ HTTP/1.1" 200 4274
2001-June-07
[19/May/2024 08:32:43] "GET /app1/movie_detail/4043/ HTTP/1.1" 200 4199
2001-June-07
[19/May/2024 08:32:43] "GET /app1/movie_detail/4043/ HTTP/1.1" 200 4199
[19/May/2024 08:36:01] "GET /app1/ajax/search/?query=Super HTTP/1.1" 200 14071
[19/May/2024 08:36:02] "GET /app1/ajax/search/?query=Super HTTP/1.1" 200 14071
[19/May/2024 08:36:02] "GET /app1/ajax/search/?query=Super%20smash HTTP/1.1" 200 2
[19/May/2024 08:36:02] "GET /app1/ajax/search/?query=Super HTTP/1.1" 200 14071
[19/May/2024 08:36:02] "GET /app1/ajax/search/?query=Super HTTP/1.1" 200 14071
[19/May/2024 08:36:03] "GET /app1/ajax/search/?query=Supe HTTP/1.1" 200 14071
[19/May/2024 08:36:03] "GET /app1/ajax/search/?query=Sup HTTP/1.1" 200 14230
[19/May/2024 08:36:03] "GET /app1/ajax/search/?query=Su HTTP/1.1" 200 12946
[19/May/2024 08:36:03] "GET /app1/ajax/search/?query=S HTTP/1.1" 200 12121
2020-February-21
[19/May/2024 08:38:19] "GET /app1/movie_detail/1767/ HTTP/1.1" 200 4707
[19/May/2024 08:42:02] "GET /app1/ HTTP/1.1" 200 26796
[19/May/2024 08:42:06] "GET /app1/ HTTP/1.1" 200 26208
[19/May/2024 08:42:12] "GET /app1/ HTTP/1.1" 200 27248
[19/May/2024 08:42:16] "GET /app1/ HTTP/1.1" 200 25799
[19/May/2024 08:42:18] "GET /app1/ HTTP/1.1" 200 27345
[19/May/2024 08:42:21] "GET /app1/ HTTP/1.1" 200 25887
[19/May/2024 08:42:36] "GET /app1/login HTTP/1.1" 200 4205
2020-April-24
[19/May/2024 08:42:50] "GET /app1/movie_detail/1331/ HTTP/1.1" 200 4043
2020-April-24
[19/May/2024 08:43:06] "GET /app1/movie_detail/1331/ HTTP/1.1" 200 4043
2020-April-24
[19/May/2024 08:43:26] "GET /app1/movie_detail/1331/ HTTP/1.1" 200 4043
2020-April-24
[19/May/2024 08:43:51] "GET /app1/movie_detail/1331/ HTTP/1.1" 200 4043
[19/May/2024 08:44:47] "GET /app1/ HTTP/1.1" 200 26331
[19/May/2024 08:46:39] "GET /app1/ HTTP/1.1" 200 26152
Forbidden (CSRF token missing.): /app1/login
[19/May/2024 09:50:05] "POST /app1/login HTTP/1.1" 403 2506
Not Found: /favicon.ico
[19/May/2024 09:50:05] "GET /favicon.ico HTTP/1.1" 404 2219
[19/May/2024 10:27:51] "GET /app1/ HTTP/1.1" 200 27300
[19/May/2024 11:25:53] code 400, message Bad request version ("¯nãY»bhlÿ(=':©\x82ÙoÈ¢×\x93\x98´ï\x80å¹\x90\x00(À")
[19/May/2024 11:25:53] You're accessing the development server over HTTPS, but it only supports HTTP.
/home/ramachandra/movies/app1/views.py changed, reloading.
Watching for file changes with StatReloader
Performing system checks...

System check identified no issues (0 silenced).
May 19, 2024 - 11:30:07
Django version 4.2.13, using settings 'movies.settings'
Starting development server at http://0.0.0.0:3000/
Quit the server with CONTROL-C.

/home/ramachandra/movies/app1/views.py changed, reloading.
Watching for file changes with StatReloader
Performing system checks...

System check identified no issues (0 silenced).
May 19, 2024 - 11:30:11
Django version 4.2.13, using settings 'movies.settings'
Starting development server at http://0.0.0.0:3000/
Quit the server with CONTROL-C.

/home/ramachandra/movies/app1/views.py changed, reloading.
Watching for file changes with StatReloader
Performing system checks...

System check identified no issues (0 silenced).
May 19, 2024 - 11:30:27
Django version 4.2.13, using settings 'movies.settings'
Starting development server at http://0.0.0.0:3000/
Quit the server with CONTROL-C.

[19/May/2024 14:35:40] "GET /app1/ HTTP/1.1" 200 27335
[19/May/2024 14:35:48] "GET /app1/login HTTP/1.1" 200 4205
Not Found: /favicon.ico
[19/May/2024 14:35:53] "GET /favicon.ico HTTP/1.1" 404 2219
[19/May/2024 14:35:54] "GET /app1/login HTTP/1.1" 200 4205
Not Found: /favicon.ico
[19/May/2024 14:36:02] "GET /favicon.ico HTTP/1.1" 404 2219
[19/May/2024 14:36:07] "GET /app1/login HTTP/1.1" 200 4205
[19/May/2024 14:36:33] "POST /app1/login HTTP/1.1" 302 0
[19/May/2024 14:36:34] "GET /app1/home HTTP/1.1" 200 18747
[19/May/2024 14:37:24] "GET /app1/profile HTTP/1.1" 200 256
[19/May/2024 14:37:32] "GET /app1/out HTTP/1.1" 302 0
[19/May/2024 14:37:33] "GET /app1/login HTTP/1.1" 200 4205
